Workbook

Sheet 27,06
A1: 1-30.05 | B1: Снекпром | C1: 45747 | D1: 45751 | E1: 45765 | F1: 30 мая
A3: Сальдо | B3: =SUM(B6:B101) -> -31198832 | C3: -24683594 | D3: -24387270 | E3: -24137498
A5: покупатели | D5: =D3-C3 -> 296324.32 | E5: =E3-D3 -> 249771.66 | F5: =B3-E3 -> -7061333.8
A6: ИП Супрунов | B6: ='[1]ИП Супрунов'!$R$25 -> 0
A7: ИП Лысенко | B7: ='[1]ИП Лысенко'!$R$57 -> -61576.2
A8: Белторгфуд | B8: =[1]БелторгФ!$L$24 -> 0
A9: Золотой Снек | B9: ='[1]Золотой Снек'!$V$101 -> 2634456
A10: Компас класс | B10: ='[1]Компас класс'!$R$28 -> 0
A11: ТМК-Сервис | B11: ='[2]ТМК-Сервис'!$Q$23 -> 0
A12: Рыбацкое дело | B12: ='[2]Рыбацкое дело'!$R$28 -> 0
A13: СНГ | B13: =[1]СНГ!$R$28 -> 0
A14: Универсам Бегемаг | B14: ='[2]Универсам Бег'!$O$55 -> 0
A15: Яндекс.Лавка | B15: =[3]Яндекс.Л!$O$80 -> 318532.5
A16: Экобиотехнология (отработ. пальмовое масло) | B16: =[3]Экобиотехн!$H$8 -> 0
A17: Элемент Трейд (Монетка) | B17: ='[1]ЭлТр Монетка'!$P$73 -> 6135984
C18: =SUM(B6:B18) -> 9027396.3 | E18: итого май по 25: | F18: =D5+E5+F5+G5 -> -6515237.8 | G18: =B3-C3 -> -6515237.8
A19: займы
A20: Нерудснаб займы р/с | B20: ='[4]Нерудснаб рс'!$D$40 -> -9905000
A21: Нерудснаб займы касса | B21: ='[4]Нерудснаб касса'!$D$84 -> -5959301.7
A22: Нерудснаб прочее касса | B22: =-[5]Нерудснаб!$H$21 -> -36549.99
A23: Нерудснаб прочее р/с | B23: =-[6]Нерудснаб!$I$21 -> -255549.6
A24: Нерудснаб оборудование | B24: =-[5]Нерудснаб!$G$21 -> -14094906
A25: АБЗстрой займ р/с | B25: =[7]АБЗ!$D$40 -> -2000000
A26: ГСН займ р/с | B26: =[7]ГСН!$D$40 -> -8600000
A27: ИП Головлин А.А. оборудование | B27: =-'[5]ИП Головлин'!$J$21 -> -4123500
A28: ИП Головлин прочее р/с | B28: =-'[6]ИП Головлин'!$I$21 -> -9840
A29: Головлин А.А. | B29: =-'[5]ИП Головлин'!$H$21 -> -103275
A30: Учредитель №2 (взносы) | B30: ='[7]Учр.№2 взносы'!$D$40 -> -7990
A31: Учредитель №1 (Нерудснаб) | B31: =[8]Учр.№1!$D$40 -> -80000
A32: Учредитель №2 (ИП Савин) | B32: =[8]Учр.№2!$D$40 -> -60000
A33: Учредитель №3 (Матвиенко) | B33: ='[8]Учр.№3 М'!$D$40 -> -20000
A34: Матвиенко Зп | B34: 1021800
A35: Учредитель №3 (Захаров) | B35: ='[8]Учр.№3 З'!$D$40 -> -20000
A36: Захаров Зп | B36: ='[7]Захаров зп'!$D$40 -> 899247.08
A37: Учредитель №3 (Саманков) | B37: ='[8]Учр.№3 С'!$D$40 -> -20000
A38: Учредитель №3 (Саманков) | B38: 800000 | C38: =SUM(B20:B38) -> -42574865
A39: поставщики комплектующих
A40: Аурум Фуд | B40: ='[9]Аурум Фуд'!$I$21 -> 0
A41: Золотой Снек (тарелки, гофрокороба) | B41: =-337862 -> -337862
A42: Интернет Решения | B42: ='[9]Интернет-Решения'!$I$21 -> 9.094947e-13
...
