Workbook

Sheet склад
A1: Арахис | E1: Крахмал кукурузный ГОСТ | I1: Крахмал модифицированный Е1422 | K1: мука кукурузная | M1: Крахмал модифицированный Е1414 | Q1: Мука пшеничная
A2: Агроимпекс сплит | B2: АгроТр целый | C2: АгроТр сплит | E2: Ресурс Групп | F2: Доминант | G2: НьюБио | I2: Доминант | J2: Ресурс Групп | K2: Ресурс Групп | M2: Доминант | N2: Ресурс Групп | Q2: Русские мельницы
A3: =Агроимпекс!V2 -> 0 | B3: =АгроТрейд!T2 -> -75 | C3: =АгроТрейд!U2 -> 0 | D3: =A3+B3+C3 -> -75 | E3: =РесурсГр!W2 -> 50 | F3: =Доминант!W2 -> 3150 | G3: =НьюБио!V2 -> 0 | H3: =E3+F3+G3 -> 3200 | I3: =Доминант!X2 -> 1650 | J3: =РесурсГр!AA2 -> 75 | K3: =РесурсГр!AC2 -> 0 | L3: =I3+J3+K3 -> 1725 | M3: =Доминант!Y2 -> 1350 | N3: =РесурсГр!AB2 -> 0 | P3: =M3+N3+O3 -> 1350 | Q3: ='Русские мельницы'!N2 -> 0 | R3: ='Русские мельницы'!O2 -> 2650 | T3: =Q3+R3+S3 -> 2650
A4: 186 | B4: 152.5 | C4: 207.996 | E4: 47 | F4: 47 | G4: 165 | I4: 183 | J4: 183 | K4: 37 | M4: 183 | N4: 183 | Q4: 26 | R4: 27
A5: =A3*A4 -> 0 | B5: =B3*B4 -> -11437.5 | C5: =C3*C4 -> 0 | D5: =A5+B5+C5 -> -11437.5 | E5: =E3*E4 -> 2350 | F5: =F3*F4 -> 148050 | G5: =G3*G4 -> 0 | H5: =E5+F5+G5 -> 150400 | I5: =I3*I4 -> 301950 | J5: =J3*J4 -> 13725 | K5: =K3*K4 -> 0 | L5: =I5+J5+K5 -> 315675 | M5: =M3*M4 -> 247050 | N5: =N3*N4 -> 0 | P5: =M5+N5+O5 -> 247050 | Q5: =Q3*Q4 -> 0 | R5: =R3*R4 -> 71550 | T5: =Q5+R5+S5 -> 71550
A7: Соль | B7: Антиокислит | E7: Масло пальмовое | G7: масло подсолнечное 5л | I7: Глутамат натрия | J7: Глюкоза | K7: Пекарский порошок В | M7: Патока крахм-карамельная | N7: Мальтодекстрин | O7: Патока крахм-карамельная
A8: Виктан | B8: Велторг | E8: Люкс Ойл | F8: отработка | G8: ИП Ким | I8: СоюзСнаб | J8: СоюзСнаб | K8: СоюзСнаб | M8: Скип | N8: Орион | O8: КрахмалПрод
A9: ='ТД Виктан'!L2 -> 1440 | B9: =Велторг!V2 -> 39.74 | D9: =A9+B9+C9 -> 1479.74 | E9: =ЛюксОйл!O2 -> 720 | F9: ='отработ масло'!M2 -> 1075 | G9: ='ИП Ким'!V2 -> 210 | H9: =E9+F9+G9 -> 2005 | I9: ='Союзснаб ПдК'!AE2 -> 50 | J9: ='Союзснаб ПдК'!AC2 -> 0 | K9: ='Союзснаб ПдК'!AD2 -> 0 | L9: =I9+J9+K9 -> 50 | M9: =Скип!P2 -> -256 | N9: =Орион!R2 -> 25 | O9: =КрахмалПрод!L2 -> 3424 | P9: =M9+N9+O9 -> 3193
A10: 24 | B10: 2196.6 | E10: 234 | F10: 55 | G10: 623 | I10: 194.15 | J10: 129 | K10: 168.11 | M10: 57 | N10: 84 | O10: 59
A11: =A9*A10 -> 34560 | B11: =B9*B10 -> 87292.884 | D11: =A11+B11+C11 -> 121852.88 | E11: =E9*E10 -> 168480 | F11: =F9*F10 -> 59125 | G11: =G9*G10 -> 130830 | H11: =E11+F11+G11 -> 358435 | I11: =I9*I10 -> 9707.5 | J11: =J9*J10 -> 0 | K11: =K9*K10 -> 0 | L11: =I11+J11+K11 -> 9707.5 | M11: =M9*M10 -> -14592 | N11: =N9*N10 -> 2100 | O11: =O9*O10 -> 202016 | P11: =M11+N11+O11 -> 189524
A13: Красители | F13: ВАДы | M13: Глутамат натрия | N13: сахар | O13: диоксид титана
A14: солнечный закат | B14: тартразин | C14: зеленое яблоко | D14: понсо | F14: барбекю | G14: сыр с халапеньо | H14: васаби | I14: сметана и зелень | J14: сметана/ лук 117403 | K14: сметана и зелень/3 | M14: Орион | N14: ИП Ким | O14: Эко Ресурс
A15: ВМ Ингред | B15: ВМ Ингред | C15: ВМ Ингред | D15: ВМ Ингред | F15: ВМ Ингред | G15: ВМ Ингред | H15: Омега-Фуд | I15: Омега-Фуд | J15: Омега-Фуд | K15: Омега-Фуд
A16: ='ВМ Ингредиент'!AD2 -> 0 | B16: ='ВМ Ингредиент'!AE2 -> 0 | C16: ='ВМ Ингредиент'!AF2 -> 2 | D16: ='ВМ Ингредиент'!AG2 -> 2 | E16: =A16+B16+C16+D16 -> 4 | F16: ='ВМ Ингредиент'!AB2 -> 0 | G16: ='ВМ Ингредиент'!AC2 -> 0 | H16: ='Омега Фуд Техн'!V2 -> 0 | I16: ='Омега Фуд Техн'!U2 -> 93 | J16: ='Омега Фуд Техн'!X2 -> 310 | K16: ='Омега Фуд Техн'!W2 -> 0 | L16: =F16+G16+H16+I16+J16+K16 -> 403 | M16: =Орион!Q2 -> 0 | N16: ='ИП Ким'!U2 -> 750 | O16: ='Эко Ресурс'!M2 -> 150 | P16: =M16+N16+O16 -> 900
A17: 1465.2 | B17: 1200 | C17: 2070 | D17: 1758 | F17: 312 | G17: 470.4 | H17: 832.48158 | I17: 743.2872 | J17: 559.2 | K17: 676.42 | M17: 183 | N17: 60 | O17: 498
A18: =A16*A17 -> 0 | B18: =B16*B17 -> 0 | C18: =C16*C17 -> 4140 | D18: =D16*D17 -> 3516 | E18: =A18+B18+C18+D18 -> 7656 | F18: =F16*F17 -> 0 | G18: =G16*G17 -> 0 | H18: =H16*H17 -> 0 | I18: =I16*I17 -> 69125.71 | J18: =J16*J17 -> 173352 | K18: =K16*K17 -> 0 | L18: =F18+G18+H18+I18+J18+K18 -> 242477.71 | M18: =M16*M17 -> 0 | N18: =N16*N17 -> 45000 | O18: =O16*O17 -> 74700 | P18: =M18+N18+O18 -> 119700
A20: Остаток сырья, на сумму | D20: =D5+H5+L5+P5+T5+D11+H11+L11+P11+E18+L18+P18+L25+T25+M32+G39+-44861 -> 2330205.5 | F20: ВАДы | N20: ВАДы
F21: шашлык | G21: Пд Васаби 409 | H21: васаби 402 | I21: Пд сладкий Чили | J21: Пд холодец с хреном | K21: Пд имбирь | N21: бекон 180 | O21: салями | P21: красная икра 011 | Q21: сыр сливочный | R21: сыр
A22: потери: | D22: =Агроимпекс!T61 -> 0 | F22: СоюзСнаб | G22: СоюзСнаб | H22: СоюзСнаб | I22: СоюзСнаб | J22: СоюзСнаб | K22: ч/л | N22: СоюзСнаб | O22: СоюзСнаб | P22: СоюзСнаб | Q22: ВМ Ингред | R22: СоюзСнаб
F23: =СоюзСнаб!AO2 -> -20 | G23: =СоюзСнаб!AQ2 -> 130 | H23: =СоюзСнаб!AP2 -> 75 | I23: =СоюзСнаб!AR2 -> 105 | J23: =СоюзСнаб!AS2 -> -10 | K23: =чл!V2 -> 0 | L23: =F23+G23+H23+I23+J23+K23 -> 280 | N23: =СоюзСнаб!AV2 -> 0 | O23: =СоюзСнаб!AT2 -> 10 | P23: =СоюзСнаб!AU2 -> 65 | Q23: ='ВМ Ингредиент'!AA2 -> 100 | R23: =СоюзСнаб!AW2 -> 155 | S23: =чл!AD2 -> 0 | T23: =N23+O23+P23+Q23+R23+S23 -> 330
A24: остаток сырья, в единицах | D24: =D3+H3+L3+P3+T3+D9+H9+L9+P9+E16+L16+P16+L23+T23+M30+G37+0-290 -> 17662.74 | F24: 607 | G24: 427 | H24: 427 | I24: 514 | J24: 519 | K24: 450 | N24: 502.85 | O24: 504 | P24: 557 | Q24: 384 | R24: 398 | S24: 450
F25: =F23*F24 -> -12140 | G25: =G23*G24 -> 55510 | H25: =H23*H24 -> 32025 | I25: =I23*I24 -> 53970 | J25: =J23*J24 -> -5190 | K25: =K23*K24 -> 0 | L25: =F25+G25+H25+I25+J25+K25 -> 124175 | N25: =N23*N24 -> 0 | O25: =O23*O24 -> 5040 | P25: =P23*P24 -> 36205 | Q25: =Q23*Q24 -> 38400 | R25: =R23*R24 -> 61690 | S25: =S23*S24 -> 0 | T25: =N25+O25+P25+Q25+R25+S25 -> 141335
C27: ВАДы
C28: Пд грибы-сметана 272 | D28: Пд грибы-сметана 274 | E28: Пд холодец с хреном 551 | F28: барбекю-шашлык 541 | G28: креветка 053 | H28: мексиканский соус 206 | I28: ПдК Солнечнй закат | J28: ПдК тартразин | K28: ПдК Зеленое яблоко2 | L28: ПдК Зеленое яблоко
C29: СоюзСнаб
C30: =СоюзСнаб!BA2 -> 10 | D30: =СоюзСнаб!BB2 -> 45 | E30: =СоюзСнаб!BC2 -> 85 | F30: =СоюзСнаб!AX2 -> 220 | G30: =СоюзСнаб!AY2 -> 70 | H30: =СоюзСнаб!AZ2 -> 15 | I30: ='Союзснаб ПдК'!Z2 -> 3 | J30: ='Союзснаб ПдК'!AA2 -> 0 | K30: ='Союзснаб ПдК'!AF2 -> 3 | L30: ='Союзснаб ПдК'!Y2 -> 0 | M30: =C30+D30+E30+F30+G30+H30+I30+J30+K30+L30 -> 451
C31: 688.59 | D31: 522.19 | E31: 532.12 | F31: 629.27 | G31: 524 | H31: 689.75 | I31: 1891.98 | J31: 1780.53 | K31: 1924.17 | L31: 2233.99
C32: =C30*C31 -> 6885.9 | D32: =D30*D31 -> 23498.55 | E32: =E30*E31 -> 45230.2 | F32: =F30*F31 -> 138439.4 | G32: =G30*G31 -> 36680 | H32: =H30*H31 -> 10346.25 | I32: =I30*I31 -> 5675.94 | J32: =J30*J31 -> 0 | ... L32: =L30*L31 -> 0 | M32: =C32+D32+E32+F32+G32+H32+I32+J32+K32+L32 -> 272528.75
C34: Красители
C35: солнечный закат | D35: тартразин2 | E35: зеленое яблоко | F35: понсо2
C36: ВМ Ингред | D36: ВМ Ингред | E36: ВМ Ингред | F36: ВМ Ингред
C37: ='ВМ Ингредиент'!AF23 -> 0 | D37: ='ВМ Ингредиент'!AI2 -> 1 | E37: ='ВМ Ингредиент'!AH23 -> 0 | F37: ='ВМ Ингредиент'!AH2 -> 6 | G37: =C37+D37+E37+F37 -> 7
D38: 1585.2 | F38: 2142
C39: =C37*C38 -> 0 | D39: =D37*D38 -> 1585.2 | E39: =E37*E38 -> 0 | F39: =F37*F38 -> 12852 | G39: =C39+D39+E39+F39 -> 14437.2
K41: =38400+14437+7656 -> 60493

Sheet Агроимпекс
A1: дата поставки | B1: арахис, кг | C1: арахис целый, кг | D1: арахис сплит, кг | G1: цена | H1: на сумму | J1: дата выдачи на пр-во | K1: в чей подотчет | L1: арахис, кг | M1: арахис целый, кг | N1: арахис сплит, кг | Q1: цена | R1: на сумму | T1: арахис, кг | U1: арахис целый, кг | V1: арахис сплит, кг
A2: 2025 год | J2: 2025 год | T2: =0+B86-L86 -> 0 | U2: =0+C86-M86 -> 0 | V2: =0+D86-N86 -> 0
H3: =B3*G3+C3*G3+D3*G3+E3*G3+F3*G3 -> 0 | T3: 190 | V3: 186
A4: 45722 | B4: 10000 | G4: 198 | H4: =B4*G4+C4*G4+D4*G4+E4*G4+F4*G4 -> 1980000 | J4: 45723 | K4: Захаров | L4: 2800 | Q4: 198 | R4: =L4*Q4 -> 554400 | T4: =T2*T3 -> 0 | U4: =U2*U3 -> 0 | V4: =V2*V3 -> 0
A5: 45728 | B5: 500 | G5: 198 | H5: =B5*G5+C5*G5+D5*G5+E5*G5+F5*G5 -> 99000 | J5: 45726 | K5: Захаров | L5: 4700 | Q5: 198 | R5: =L5*Q5 -> 930600
H6: =B6*G6+C6*G6+D6*G6+E6*G6+F6*G6 -> 0 | J6: 45727 | K6: Захаров | L6: 2000 | Q6: 198 | R6: =L6*Q6 -> 396000
H7: =B7*G7+C7*G7+D7*G7+E7*G7+F7*G7 -> 0 | J7: 45729 | K7: Захаров | L7: 1000 | Q7: 198 | R7: =L7*Q7 -> 198000
A8: 45742 | B8: 5000 | G8: 190 | H8: =B8*G8+C8*G8+D8*G8+E8*G8+F8*G8 -> 950000 | J8: 45742 | K8: Захаров | L8: 2500 | Q8: 190 | R8: =L8*Q8 -> 475000
H9: =B9*G9+C9*G9+D9*G9+E9*G9+F9*G9 -> 0 | J9: 45743 | K9: Захаров | L9: 2500 | Q9: 190 | R9: =L9*Q9 -> 475000
A10: 45757 | D10: 5000 | G10: 186 | H10: =B10*G10+C10*G10+D10*G10+E10*G10+F10*G10 -> 930000 | J10: 45757 | K10: Захаров | N10: 5000 | Q10: 186 | R10: =L10*Q10+M10*Q10+N10*Q10+O10*Q10+P10*Q10 -> 930000
A11: 08-09 мая | B11: 5000 | G11: 173 | H11: =B11*G11+C11*G11+D11*G11+E11*G11+F11*G11 -> 865000 | J11: 08-09 мая | K11: Захаров | L11: 5000 | Q11: 173 | R11: =L11*Q11 -> 865000
H12: =B12*G12+C12*G12+D12*G12+E12*G12+F12*G12 -> 0 | R12: =L12*Q12 -> 0
H13: =B13*G13+C13*G13+D13*G13+E13*G13+F13*G13 -> 0 | R13: =L13*Q13 -> 0
H14: =B14*G14+C14*G14+D14*G14+E14*G14+F14*G14 -> 0 | R14: =L14*Q14 -> 0
H15: =B15*G15+C15*G15+D15*G15+E15*G15+F15*G15 -> 0 | R15: =L15*Q15 -> 0
H16: =B16*G16+C16*G16+D16*G16+E16*G16+F16*G16 -> 0 | R16: =L16*Q16 -> 0
H17: =B17*G17+C17*G17+D17*G17+E17*G17+F17*G17 -> 0 | R17: =L17*Q17 -> 0
H18: =B18*G18+C18*G18+D18*G18+E18*G18+F18*G18 -> 0 | R18: =L18*Q18 -> 0
H19: =B19*G19+C19*G19+D19*G19+E19*G19+F19*G19 -> 0 | R19: =L19*Q19 -> 0
H20: =B20*G20+C20*G20+D20*G20+E20*G20+F20*G20 -> 0 | R20: =L20*Q20 -> 0
H21: =B21*G21+C21*G21+D21*G21+E21*G21+F21*G21 -> 0 | R21: =L21*Q21 -> 0
H22: =B22*G22+C22*G22+D22*G22+E22*G22+F22*G22 -> 0 | R22: =L22*Q22 -> 0
H23: =B23*G23+C23*G23+D23*G23+E23*G23+F23*G23 -> 0 | R23: =L23*Q23 -> 0
... H42: =B42*G42+C42*G42+D42*G42+E42*G42+F42*G42 -> 0 | R42: =L42*Q42 -> 0
H43: =B43*G43+C43*G43+D43*G43+E43*G43+F43*G43 -> 0 | R43: =L43*Q43+M43*Q43+N43*Q43+O43*Q43+P43*Q43 -> 0
H44: =B44*G44+C44*G44+D44*G44+E44*G44+F44*G44 -> 0 | R44: =L44*Q44+M44*Q44+N44*Q44+O44*Q44+P44*Q44 -> 0
H45: =B45*G45+C45*G45+D45*G45+E45*G45+F45*G45 -> 0 | R45: =L45*Q45+M45*Q45+N45*Q45+O45*Q45+P45*Q45 -> 0
H46: =B46*G46+C46*G46+D46*G46+E46*G46+F46*G46 -> 0 | R46: =L46*Q46+M46*Q46+N46*Q46+O46*Q46+P46*Q46 -> 0
H47: =B47*G47+C47*G47+D47*G47+E47*G47+F47*G47 -> 0 | R47: =L47*Q47+M47*Q47+N47*Q47+O47*Q47+P47*Q47 -> 0
H48: =B48*G48+C48*G48+D48*G48+E48*G48+F48*G48 -> 0 | R48: =L48*Q48+M48*Q48+N48*Q48+O48*Q48+P48*Q48 -> 0
H49: =B49*G49+C49*G49+D49*G49+E49*G49+F49*G49 -> 0 | R49: =L49*Q49+M49*Q49+N49*Q49+O49*Q49+P49*Q49 -> 0
H50: =B50*G50+C50*G50+D50*G50+E50*G50+F50*G50 -> 0 | R50: =L50*Q50+M50*Q50+N50*Q50+O50*Q50+P50*Q50 -> 0
H51: =B51*G51+C51*G51+D51*G51+E51*G51+F51*G51 -> 0 | R51: =L51*Q51+M51*Q51+N51*Q51+O51*Q51+P51*Q51 -> 0
H52: =B52*G52+C52*G52+D52*G52+E52*G52+F52*G52 -> 0 | R52: =L52*Q52+M52*Q52+N52*Q52+O52*Q52+P52*Q52 -> 0
H53: =B53*G53+C53*G53+D53*G53+E53*G53+F53*G53 -> 0 | R53: =L53*Q53+M53*Q53+N53*Q53+O53*Q53+P53*Q53 -> 0
H54: =B54*G54+C54*G54+D54*G54+E54*G54+F54*G54 -> 0 | R54: =L54*Q54+M54*Q54+N54*Q54+O54*Q54+P54*Q54 -> 0
... H85: =B85*G85+C85*G85+D85*G85+E85*G85+F85*G85 -> 0 | R85: =L85*Q85+M85*Q85+N85*Q85+O85*Q85+P85*Q85 -> 0
B86: =SUM(B3:B85) -> 20500 | C86: =SUM(C3:C85) -> 0 | D86: =SUM(D3:D85) -> 5000 | E86: =SUM(E3:E85) -> 0 | F86: =SUM(F3:F85) -> 0 | L86: =SUM(L3:L85) -> 20500 | M86: =SUM(M3:M85) -> 0 | N86: =SUM(N3:N85) -> 5000 | O86: =SUM(O3:O85) -> 0 | P86: =SUM(P3:P85) -> 0

Sheet ОПТТОРГ
A1: дата поставки | B1: арахис, кг | C1: арахис целый, кг | D1: арахис сплит, кг | G1: цена | H1: на сумму | J1: дата выдачи на пр-во | K1: арахис, кг | L1: арахис целый, кг | M1: арахис сплит, кг | P1: цена | Q1: на сумму | S1: арахис, кг | T1: арахис целый, кг | U1: арахис сплит, кг
A2: 2025 год | J2: 2025 год | S2: =0+B86-K86 -> 9000 | T2: =0+C86-L86 -> 0 | U2: =0+D86-M86 -> 0
H3: =B3*G3+C3*G3+D3*G3+E3*G3+F3*G3 -> 0 | S3: 143
A4: 16 мая | B4: 10000 | G4: 143 | H4: =B4*G4+C4*G4+D4*G4+E4*G4+F4*G4 -> 1430000 | J4: 21 мая | K4: 1000 | P4: 143 | Q4: =K4*P4 -> 143000 | S4: =S2*S3 -> 1287000 | T4: =T2*T3 -> 0 | U4: =U2*U3 -> 0
H5: =B5*G5+C5*G5+D5*G5+E5*G5+F5*G5 -> 0
H6: =B6*G6+C6*G6+D6*G6+E6*G6+F6*G6 -> 0
H7: =B7*G7+C7*G7+D7*G7+E7*G7+F7*G7 -> 0
H8: =B8*G8+C8*G8+D8*G8+E8*G8+F8*G8 -> 0
H9: =B9*G9+C9*G9+D9*G9+E9*G9+F9*G9 -> 0
H10: =B10*G10+C10*G10+D10*G10+E10*G10+F10*G10 -> 0
H11: =B11*G11+C11*G11+D11*G11+E11*G11+F11*G11 -> 0
H12: =B12*G12+C12*G12+D12*G12+E12*G12+F12*G12 -> 0
H13: =B13*G13+C13*G13+D13*G13+E13*G13+F13*G13 -> 0 | Q13: =K13*P13 -> 0
H14: =B14*G14+C14*G14+D14*G14+E14*G14+F14*G14 -> 0 | Q14: =K14*P14 -> 0
H15: =B15*G15+C15*G15+D15*G15+E15*G15+F15*G15 -> 0 | Q15: =K15*P15 -> 0
H16: =B16*G16+C16*G16+D16*G16+E16*G16+F16*G16 -> 0 | Q16: =K16*P16 -> 0
H17: =B17*G17+C17*G17+D17*G17+E17*G17+F17*G17 -> 0 | Q17: =K17*P17 -> 0
H18: =B18*G18+C18*G18+D18*G18+E18*G18+F18*G18 -> 0 | Q18: =K18*P18 -> 0
H19: =B19*G19+C19*G19+D19*G19+E19*G19+F19*G19 -> 0 | Q19: =K19*P19 -> 0
H20: =B20*G20+C20*G20+D20*G20+E20*G20+F20*G20 -> 0 | Q20: =K20*P20 -> 0
H21: =B21*G21+C21*G21+D21*G21+E21*G21+F21*G21 -> 0 | Q21: =K21*P21 -> 0
H22: =B22*G22+C22*G22+D22*G22+E22*G22+F22*G22 -> 0 | Q22: =K22*P22 -> 0
H23: =B23*G23+C23*G23+D23*G23+E23*G23+F23*G23 -> 0 | Q23: =K23*P23 -> 0
H24: =B24*G24+C24*G24+D24*G24+E24*G24+F24*G24 -> 0 | Q24: =K24*P24 -> 0
... H42: =B42*G42+C42*G42+D42*G42+E42*G42+F42*G42 -> 0 | Q42: =K42*P42 -> 0
H43: =B43*G43+C43*G43+D43*G43+E43*G43+F43*G43 -> 0 | Q43: =K43*P43+L43*P43+M43*P43+N43*P43+O43*P43 -> 0
H44: =B44*G44+C44*G44+D44*G44+E44*G44+F44*G44 -> 0 | Q44: =K44*P44+L44*P44+M44*P44+N44*P44+O44*P44 -> 0
H45: =B45*G45+C45*G45+D45*G45+E45*G45+F45*G45 -> 0 | Q45: =K45*P45+L45*P45+M45*P45+N45*P45+O45*P45 -> 0
H46: =B46*G46+C46*G46+D46*G46+E46*G46+F46*G46 -> 0 | Q46: =K46*P46+L46*P46+M46*P46+N46*P46+O46*P46 -> 0
H47: =B47*G47+C47*G47+D47*G47+E47*G47+F47*G47 -> 0 | Q47: =K47*P47+L47*P47+M47*P47+N47*P47+O47*P47 -> 0
H48: =B48*G48+C48*G48+D48*G48+E48*G48+F48*G48 -> 0 | Q48: =K48*P48+L48*P48+M48*P48+N48*P48+O48*P48 -> 0
H49: =B49*G49+C49*G49+D49*G49+E49*G49+F49*G49 -> 0 | Q49: =K49*P49+L49*P49+M49*P49+N49*P49+O49*P49 -> 0
H50: =B50*G50+C50*G50+D50*G50+E50*G50+F50*G50 -> 0 | Q50: =K50*P50+L50*P50+M50*P50+N50*P50+O50*P50 -> 0
H51: =B51*G51+C51*G51+D51*G51+E51*G51+F51*G51 -> 0 | Q51: =K51*P51+L51*P51+M51*P51+N51*P51+O51*P51 -> 0
H52: =B52*G52+C52*G52+D52*G52+E52*G52+F52*G52 -> 0 | Q52: =K52*P52+L52*P52+M52*P52+N52*P52+O52*P52 -> 0
H53: =B53*G53+C53*G53+D53*G53+E53*G53+F53*G53 -> 0 | Q53: =K53*P53+L53*P53+M53*P53+N53*P53+O53*P53 -> 0
H54: =B54*G54+C54*G54+D54*G54+E54*G54+F54*G54 -> 0 | Q54: =K54*P54+L54*P54+M54*P54+N54*P54+O54*P54 -> 0
... H85: =B85*G85+C85*G85+D85*G85+E85*G85+F85*G85 -> 0 | Q85: =K85*P85+L85*P85+M85*P85+N85*P85+O85*P85 -> 0
B86: =SUM(B3:B85) -> 10000 | C86: =SUM(C3:C85) -> 0 | D86: =SUM(D3:D85) -> 0 | E86: =SUM(E3:E85) -> 0 | F86: =SUM(F3:F85) -> 0 | K86: =SUM(K3:K85) -> 1000 | L86: =SUM(L3:L85) -> 0 | M86: =SUM(M3:M85) -> 0 | N86: =SUM(N3:N85) -> 0 | O86: =SUM(O3:O85) -> 0

Sheet АгроТрейд
A1: дата поставки | B1: арахис, кг | C1: арахис целый, кг | D1: арахис сплит, кг | G1: цена | H1: на сумму | J1: дата выдачи на пр-во | K1: арахис, кг | L1: арахис сырой (индия)целый, кг | M1: арахис сплит, кг | P1: цена | Q1: на сумму | S1: арахис, кг | T1: арахис целый, кг | U1: арахис сплит, кг
A2: 2024 год | J2: 2024 год | S2: =0+B118-K118 -> 0 | T2: =0+C118-L118 -> -75 | U2: =0+D118-M118 -> 0
A3: 45508 | B3: 9920 | G3: 157.716 | H3: =B3*G3 -> 1564542.7 | S3: 171.996 | T3: 152.5 | U3: 207.796
H4: =B4*G4 -> 0 | J4: 45512 | K4: 30 | P4: 157.716 | Q4: =K4*P4 -> 4731.48 | S4: =S2*S3 -> 0 | T4: =T2*T3 -> -11437.5 | U4: =U2*U3 -> 0
H5: =B5*G5 -> 0 | J5: 45535 | K5: 35 | P5: 157.716 | Q5: =K5*P5 -> 5520.06
H6: =B6*G6 -> 0 | J6: 45545 | K6: 3 | P6: 157.716 | Q6: =K6*P6 -> 473.148
H7: =B7*G7 -> 0 | J7: 45551 | K7: 5 | P7: 157.716 | Q7: =K7*P7 -> 788.58
H8: =B8*G8 -> 0 | J8: 45558 | K8: 36 | P8: 157.716 | Q8: =K8*P8 -> 5677.776
H9: =B9*G9 -> 0 | J9: 45560 | K9: 36 | P9: 157.716 | Q9: =K9*P9 -> 5677.776
H10: =B10*G10 -> 0 | J10: 45561 | K10: 17 | P10: 157.716 | Q10: =K10*P10 -> 2681.172
H11: =B11*G11 -> 0 | J11: 45566 | K11: 1 | P11: 157.716 | Q11: =K11*P11 -> 157.716
H12: =B12*G12 -> 0 | J12: 45567 | K12: 75 | P12: 157.716 | Q12: =K12*P12 -> 11828.7
H13: =B13*G13 -> 0 | J13: 45568 | K13: 150 | P13: 157.716 | Q13: =K13*P13 -> 23657.4
H14: =B14*G14 -> 0 | J14: 45569 | K14: 107 | P14: 157.716 | Q14: =K14*P14 -> 16875.612
H15: =B15*G15 -> 0 | J15: 45572 | K15: 375 | P15: 157.716 | Q15: =K15*P15 -> 59143.5
H16: =B16*G16 -> 0 | J16: 45580 | K16: 100 | P16: 157.716 | Q16: =K16*P16 -> 15771.6
... H41: =B41*G41 -> 0 | J41: 46015 | K41: 250 | P41: 157.716 | Q41: =K41*P41 -> 39429
A42: 2025 год | H42: =B42*G42 -> 0 | J42: 2025 год | Q42: =K42*P42 -> 0
H43: =B43*G43+C43*G43+D43*G43+E43*G43+F43*G43 -> 0 | J43: 45666 | K43: 550 | P43: 157.716 | Q43: =K43*P43+L43*P43+M43*P43+N43*P43+O43*P43 -> 86743.8
H44: =B44*G44+C44*G44+D44*G44+E44*G44+F44*G44 -> 0 | J44: 45667 | K44: 175 | P44: 157.716 | Q44: =K44*P44+L44*P44+M44*P44+N44*P44+O44*P44 -> 27600.3
H45: =B45*G45+C45*G45+D45*G45+E45*G45+F45*G45 -> 0 | J45: 45671 | K45: 75 | P45: 157.716 | Q45: =K45*P45+L45*P45+M45*P45+N45*P45+O45*P45 -> 11828.7
H46: =B46*G46+C46*G46+D46*G46+E46*G46+F46*G46 -> 0 | J46: 45672 | K46: 300 | P46: 157.716 | Q46: =K46*P46+L46*P46+M46*P46+N46*P46+O46*P46 -> 47314.8
H47: =B47*G47+C47*G47+D47*G47+E47*G47+F47*G47 -> 0 | J47: 45673 | K47: 675 | P47: 157.716 | Q47: =K47*P47+L47*P47+M47*P47+N47*P47+O47*P47 -> 106458.3
H48: =B48*G48+C48*G48+D48*G48+E48*G48+F48*G48 -> 0 | J48: 45674 | K48: 25 | P48: 157.716 | Q48: =K48*P48+L48*P48+M48*P48+N48*P48+O48*P48 -> 3942.9
H49: =B49*G49+C49*G49+D49*G49+E49*G49+F49*G49 -> 0 | J49: 45678 | K49: 25 | P49: 157.716 | Q49: =K49*P49+L49*P49+M49*P49+N49*P49+O49*P49 -> 3942.9
A50: 45680 | C50: 9196 | G50: 171.996 | H50: =B50*G50+C50*G50+D50*G50+E50*G50+F50*G50 -> 1581675.2 | J50: 45680 | K50: 150 | P50: 157.716 | Q50: =K50*P50+L50*P50+M50*P50+N50*P50+O50*P50 -> 23657.4
D51: 50 | G51: 208 | H51: =B51*G51+C51*G51+D51*G51+E51*G51+F51*G51 -> 10400 | J51: 45681 | K51: 100 | P51: 157.716 | Q51: =K51*P51+L51*P51+M51*P51+N51*P51+O51*P51 -> 15771.6
H52: =B52*G52+C52*G52+D52*G52+E52*G52+F52*G52 -> 0 | J52: 45684 | K52: 350 | P52: 157.716 | Q52: =K52*P52+L52*P52+M52*P52+N52*P52+O52*P52 -> 55200.6
H53: =B53*G53+C53*G53+D53*G53+E53*G53+F53*G53 -> 0 | J53: 45685 | K53: 275 | P53: 157.716 | Q53: =K53*P53+L53*P53+M53*P53+N53*P53+O53*P53 -> 43371.9
H54: =B54*G54+C54*G54+D54*G54+E54*G54+F54*G54 -> 0 | J54: 45686 | K54: 200 | P54: 157.716 | Q54: =K54*P54+L54*P54+M54*P54+N54*P54+O54*P54 -> 31543.2
H55: =B55*G55+C55*G55+D55*G55+E55*G55+F55*G55 -> 0 | L55: 150 | P55: 171.996 | Q55: =K55*P55+L55*P55+M55*P55+N55*P55+O55*P55 -> 25799.4
H56: =B56*G56+C56*G56+D56*G56+E56*G56+F56*G56 -> 0 | J56: 45687 | L56: 300 | P56: 171.996 | Q56: =K56*P56+L56*P56+M56*P56+N56*P56+O56*P56 -> 51598.8
H57: =B57*G57+C57*G57+D57*G57+E57*G57+F57*G57 -> 0 | J57: 45688 | L57: 150 | P57: 171.996 | Q57: =K57*P57+L57*P57+M57*P57+N57*P57+O57*P57 -> 25799.4
H58: =B58*G58+C58*G58+D58*G58+E58*G58+F58*G58 -> 0 | L58: 375 | P58: 171.996 | Q58: =K58*P58+L58*P58+M58*P58+N58*P58+O58*P58 -> 64498.5
H59: =B59*G59+C59*G59+D59*G59+E59*G59+F59*G59 -> 0 | J59: 45692 | L59: 375 | P59: 171.996 | Q59: =K59*P59+L59*P59+M59*P59+N59*P59+O59*P59 -> 64498.5
H60: =B60*G60+C60*G60+D60*G60+E60*G60+F60*G60 -> 0 | J60: 45693 | L60: 225 | P60: 171.996 | Q60: =K60*P60+L60*P60+M60*P60+N60*P60+O60*P60 -> 38699.1
H61: =B61*G61+C61*G61+D61*G61+E61*G61+F61*G61 -> 0 | J61: 45694 | L61: 350 | P61: 171.996 | Q61: =K61*P61+L61*P61+M61*P61+N61*P61+O61*P61 -> 60198.6
H62: =B62*G62+C62*G62+D62*G62+E62*G62+F62*G62 -> 0 | J62: 45698 | L62: 525 | P62: 171.996 | Q62: =K62*P62+L62*P62+M62*P62+N62*P62+O62*P62 -> 90297.9
H63: =B63*G63+C63*G63+D63*G63+E63*G63+F63*G63 -> 0 | J63: 45699 | L63: 500 | P63: 171.996 | Q63: =K63*P63+L63*P63+M63*P63+N63*P63+O63*P63 -> 85998
H64: =B64*G64+C64*G64+D64*G64+E64*G64+F64*G64 -> 0 | J64: 45700 | L64: 525 | P64: 171.996 | Q64: =K64*P64+L64*P64+M64*P64+N64*P64+O64*P64 -> 90297.9
...

Sheet Академия-Т
A1: дата поставки | B1: Гуммиарабик Инст ВА | C1: мука, кг | D1: цена | E1: на сумму | G1: дата выдачи на пр-во | H1: в чей подотчет | I1: Гуммиарабик Инст ВА | J1: мука, кг | K1: цена | L1: на сумму | O1: Гуммиарабик Инст ВА | P1: мука, кг
A2: 2024 год | G2: 2024 год | O2: =0+B53-I53 -> 0 | P2: =0+C53-J53 -> 0
A3: 45643 | B3: 25 | D3: 851.495 | E3: =B3*D3+C3*D3 -> 21287.375 | O3: 851.495 | P3: 27
E4: =B4*D4+C4*D4 -> 0 | G4: 45726 | H4: Захаров | I4: 25 | K4: 851.5 | L4: =I4*K4+J4*K4 -> 21287.5 | O4: =O2*O3 -> 0 | P4: =P2*P3 -> 0
E5: =B5*D5+C5*D5 -> 0 | L5: =I5*K5+J5*K5 -> 0
E6: =B6*D6+C6*D6 -> 0 | L6: =I6*K6+J6*K6 -> 0
E7: =B7*D7+C7*D7 -> 0 | L7: =I7*K7+J7*K7 -> 0
E8: =B8*D8+C8*D8 -> 0 | L8: =I8*K8+J8*K8 -> 0
E9: =B9*D9+C9*D9 -> 0 | L9: =I9*K9+J9*K9 -> 0
E10: =B10*D10+C10*D10 -> 0 | L10: =I10*K10+J10*K10 -> 0
E11: =B11*D11+C11*D11 -> 0 | L11: =I11*K11+J11*K11 -> 0
E12: =B12*D12+C12*D12 -> 0 | L12: =I12*K12+J12*K12 -> 0
E13: =B13*D13+C13*D13 -> 0 | L13: =I13*K13+J13*K13 -> 0
E14: =B14*D14+C14*D14 -> 0 | L14: =I14*K14+J14*K14 -> 0
E15: =B15*D15+C15*D15 -> 0 | L15: =I15*K15+J15*K15 -> 0
E16: =B16*D16+C16*D16 -> 0 | L16: =I16*K16+J16*K16 -> 0
... E52: =B52*D52+C52*D52 -> 0 | L52: =I52*K52+J52*K52 -> 0
B53: =SUM(B3:B52) -> 25 | C53: =SUM(C3:C52) -> 0 | I53: =SUM(I3:I52) -> 25 | J53: =SUM(J3:J52) -> 0

Sheet ВМ Ингредиент
A1: дата поставки | B1: Аромат сыр сливоч | C1: Аромат барбекю | D1: Аромат сыр с халапеньо | E1: Краситель желтый закат | F1: Краситель тартразин | G1: Краситель зеленое яблоко | H1: Краситель понсо | I1: Краситель понсо2 | J1: Краситель тартразин2 | K1: цена | L1: на сумму | N1: дата выдачи на пр-во | O1: Аромат сыр сливоч | P1: Аромат барбекю | Q1: Аромат сыр с халапеньо | R1: Краситель желтый закат | S1: Краситель тартразин | T1: Краситель зеленое яблоко | U1: Краситель понсо | V1: Краситель понсо2 | W1: Краситель тартразин2 | X1: цена | Y1: на сумму | AA1: Аромат сыр сливоч | AB1: Аромат барбекю | AC1: Аромат сыр с халапеньо | AD1: Краситель желтый закат | AE1: Краситель тартразин | AF1: Краситель зеленое яблоко | AG1: Краситель понсо | AH1: Краситель понсо2 | AI1: Краситель тартразин2
A2: 2024 год | N2: 2024 год | AA2: =0+B114-O114 -> 100 | AB2: =0+C114-P114 -> 0 | AC2: =0+D114-Q114 -> 0 | AD2: =0+E114-R114 -> 0 | AE2: =0+F114-S114 -> 0 | AF2: =0+G114-T114 -> 2 | AG2: =H114-U114 -> 2 | AH2: =0+I114-V114 -> 6 | AI2: =0+J114-W114 -> 1
A3: 45524 | C3: 125 | K3: 312 | L3: =B3*K3+C3*K3+D3*K3+E3*K3+F3*K3+G3*K3+H3*K3+I3*K3+J3*K3 -> 39000 | P3: 0.12 | X3: 312 | Y3: =O3*X3+P3*X3+Q3*X3+R3*X3+S3*X3+T3*X3+U3*X3+V3*X3+W3*X3 -> 37.44 | AA3: 384 | AB3: 312 | AC3: 470.4 | AD3: 1465.2 | AE3: 1200 | AF3: 2070 | AG3: 1758 | AH3: 2142 | AI3: 1585.2
D4: 125 | K4: 470.4 | L4: =B4*K4+C4*K4+D4*K4+E4*K4+F4*K4+G4*K4+H4*K4+I4*K4+J4*K4 -> 58800 | Q4: 0.12 | X4: 470.4 | Y4: =O4*X4+P4*X4+Q4*X4+R4*X4+S4*X4+T4*X4+U4*X4+V4*X4+W4*X4 -> 56.448 | AA4: =AA2*AA3 -> 38400 | AB4: =AB2*AB3 -> 0 | AC4: =AC2*AC3 -> 0 | AD4: =AD2*AD3 -> 0 | AE4: =AE2*AE3 -> 0 | AF4: =AF2*AF3 -> 4140 | AG4: =AG2*AG3 -> 3516 | AH4: =AH2*AH3 -> 12852 | AI4: =AI2*AI3 -> 1585.2
E5: 3 | K5: 1200 | L5: =B5*K5+C5*K5+D5*K5+E5*K5+F5*K5+G5*K5+H5*K5+I5*K5+J5*K5 -> 3600 | N5: 45535 | P5: 0.06 | X5: 312 | Y5: =O5*X5+P5*X5+Q5*X5+R5*X5+S5*X5+T5*X5+U5*X5+V5*X5+W5*X5 -> 18.72
F6: 3 | K6: 1200 | L6: =B6*K6+C6*K6+D6*K6+E6*K6+F6*K6+G6*K6+H6*K6+I6*K6+J6*K6 -> 3600 | Q6: 0.06 | X6: 470.4 | Y6: =O6*X6+P6*X6+Q6*X6+R6*X6+S6*X6+T6*X6+U6*X6+V6*X6+W6*X6 -> 28.224
G7: 3 | K7: 1596 | L7: =B7*K7+C7*K7+D7*K7+E7*K7+F7*K7+G7*K7+H7*K7+I7*K7+J7*K7 -> 4788 | N7: 45545 | P7: 0.6 | X7: 312 | Y7: =O7*X7+P7*X7+Q7*X7+R7*X7+S7*X7+T7*X7+U7*X7+V7*X7+W7*X7 -> 187.2
L8: =B8*K8+C8*K8+D8*K8+E8*K8+F8*K8+G8*K8+H8*K8+I8*K8+J8*K8 -> 0 | Q8: 0.6 | X8: 470.4 | Y8: =O8*X8+P8*X8+Q8*X8+R8*X8+S8*X8+T8*X8+U8*X8+V8*X8+W8*X8 -> 282.24
L9: =B9*K9+C9*K9+D9*K9+E9*K9+F9*K9+G9*K9+H9*K9+I9*K9+J9*K9 -> 0 | N9: 45551 | P9: 0.5 | X9: 312 | Y9: =O9*X9+P9*X9+Q9*X9+R9*X9+S9*X9+T9*X9+U9*X9+V9*X9+W9*X9 -> 156
L10: =B10*K10+C10*K10+D10*K10+E10*K10+F10*K10+G10*K10+H10*K10+I10*K10+J10*K10 -> 0 | Q10: 0.5 | X10: 470.4 | Y10: =O10*X10+P10*X10+Q10*X10+R10*X10+S10*X10+T10*X10+U10*X10+V10*X10+W10*X10 -> 235.2
L11: =B11*K11+C11*K11+D11*K11+E11*K11+F11*K11+G11*K11+H11*K11+I11*K11+J11*K11 -> 0 | N11: 45558 | X11: 1200 | Y11: =O11*X11+P11*X11+Q11*X11+R11*X11+S11*X11+T11*X11+U11*X11+V11*X11+W11*X11 -> 0 | Z11: 0.045
L12: =B12*K12+C12*K12+D12*K12+E12*K12+F12*K12+G12*K12+H12*K12+I12*K12+J12*K12 -> 0 | P12: 0.5 | X12: 312 | Y12: =O12*X12+P12*X12+Q12*X12+R12*X12+S12*X12+T12*X12+U12*X12+V12*X12+W12*X12 -> 156
L13: =B13*K13+C13*K13+D13*K13+E13*K13+F13*K13+G13*K13+H13*K13+I13*K13+J13*K13 -> 0 | N13: 45560 | S13: 0.06 | X13: 1200 | Y13: =O13*X13+P13*X13+Q13*X13+R13*X13+S13*X13+T13*X13+U13*X13+V13*X13+W13*X13 -> 72
L14: =B14*K14+C14*K14+D14*K14+E14*K14+F14*K14+G14*K14+H14*K14+I14*K14+J14*K14 -> 0 | P14: 1 | X14: 312 | Y14: =O14*X14+P14*X14+Q14*X14+R14*X14+S14*X14+T14*X14+U14*X14+V14*X14+W14*X14 -> 312
L15: =B15*K15+C15*K15+D15*K15+E15*K15+F15*K15+G15*K15+H15*K15+I15*K15+J15*K15 -> 0 | Q15: 1 | X15: 470.4 | Y15: =O15*X15+P15*X15+Q15*X15+R15*X15+S15*X15+T15*X15+U15*X15+V15*X15+W15*X15 -> 470.4
L16: =B16*K16+C16*K16+D16*K16+E16*K16+F16*K16+G16*K16+H16*K16+I16*K16+J16*K16 -> 0 | R16: 0.06 | X16: 1200 | Y16: =O16*X16+P16*X16+Q16*X16+R16*X16+S16*X16+T16*X16+U16*X16+V16*X16+W16*X16 -> 72
L17: =B17*K17+C17*K17+D17*K17+E17*K17+F17*K17+G17*K17+H17*K17+I17*K17+J17*K17 -> 0 | N17: 45567 | S17: 0.09 | X17: 1200 | Y17: =O17*X17+P17*X17+Q17*X17+R17*X17+S17*X17+T17*X17+U17*X17+V17*X17+W17*X17 -> 108
L18: =B18*K18+C18*K18+D18*K18+E18*K18+F18*K18+G18*K18+H18*K18+I18*K18+J18*K18 -> 0 | N18: 45568 | S18: 0.15 | X18: 1200 | Y18: =O18*X18+P18*X18+Q18*X18+R18*X18+S18*X18+T18*X18+U18*X18+V18*X18+W18*X18 -> 180
L19: =B19*K19+C19*K19+D19*K19+E19*K19+F19*K19+G19*K19+H19*K19+I19*K19+J19*K19 -> 0 | Q19: 9 | X19: 470 | Y19: =O19*X19+P19*X19+Q19*X19+R19*X19+S19*X19+T19*X19+U19*X19+V19*X19+W19*X19 -> 4230
L20: =B20*K20+C20*K20+D20*K20+E20*K20+F20*K20+G20*K20+H20*K20+I20*K20+J20*K20 -> 0 | N20: 45603 | T20: 0.47 | X20: 1596 | Y20: =O20*X20+P20*X20+Q20*X20+R20*X20+S20*X20+T20*X20+U20*X20+V20*X20+W20*X20 -> 750.12
L21: =B21*K21+C21*K21+D21*K21+E21*K21+F21*K21+G21*K21+H21*K21+I21*K21+J21*K21 -> 0 | N21: 45576 | T21: 0.53 | X21: 1596 | Y21: =O21*X21+P21*X21+Q21*X21+R21*X21+S21*X21+T21*X21+U21*X21+V21*X21+W21*X21 -> 845.88
L22: =B22*K22+C22*K22+D22*K22+E22*K22+F22*K22+G22*K22+H22*K22+I22*K22+J22*K22 -> 0 | R22: 0.9 | X22: 1200 | Y22: =O22*X22+P22*X22+Q22*X22+R22*X22+S22*X22+T22*X22+U22*X22+V22*X22+W22*X22 -> 1080
L23: =B23*K23+C23*K23+D23*K23+E23*K23+F23*K23+G23*K23+H23*K23+I23*K23+J23*K23 -> 0 | S23: 0.7 | X23: 1200 | Y23: =O23*X23+P23*X23+Q23*X23+R23*X23+S23*X23+T23*X23+U23*X23+V23*X23+W23*X23 -> 840
L24: =B24*K24+C24*K24+D24*K24+E24*K24+F24*K24+G24*K24+H24*K24+I24*K24+J24*K24 -> 0 | Q24: 38.72 | X24: 470.4 | Y24: =O24*X24+P24*X24+Q24*X24+R24*X24+S24*X24+T24*X24+U24*X24+V24*X24+W24*X24 -> 18213.888
L25: =B25*K25+C25*K25+D25*K25+E25*K25+F25*K25+G25*K25+H25*K25+I25*K25+J25*K25 -> 0 | N25: 45583 | R25: 0 | S25: 0 | X25: 1200 | Y25: =O25*X25+P25*X25+Q25*X25+R25*X25+S25*X25+T25*X25+U25*X25+V25*X25+W25*X25 -> 0
L26: =B26*K26+C26*K26+D26*K26+E26*K26+F26*K26+G26*K26+H26*K26+I26*K26+J26*K26 -> 0 | P26: 17 | X26: 312 | Y26: =O26*X26+P26*X26+Q26*X26+R26*X26+S26*X26+T26*X26+U26*X26+V26*X26+W26*X26 -> 5304
L27: =B27*K27+C27*K27+D27*K27+E27*K27+F27*K27+G27*K27+H27*K27+I27*K27+J27*K27 -> 0 | Q27: 17 | X27: 470.4 | Y27: =O27*X27+P27*X27+Q27*X27+R27*X27+S27*X27+T27*X27+U27*X27+V27*X27+W27*X27 -> 7996.8
L28: =B28*K28+C28*K28+D28*K28+E28*K28+F28*K28+G28*K28+H28*K28+I28*K28+J28*K28 -> 0 | N28: 45584 | P28: 1 | X28: 312 | Y28: =O28*X28+P28*X28+Q28*X28+R28*X28+S28*X28+T28*X28+U28*X28+V28*X28+W28*X28 -> 312
L29: =B29*K29+C29*K29+D29*K29+E29*K29+F29*K29+G29*K29+H29*K29+I29*K29+J29*K29 -> 0 | R29: 0 | X29: 1200 | Y29: =O29*X29+P29*X29+Q29*X29+R29*X29+S29*X29+T29*X29+U29*X29+V29*X29+W29*X29 -> 0
L30: =B30*K30+C30*K30+D30*K30+E30*K30+F30*K30+G30*K30+H30*K30+I30*K30+J30*K30 -> 0 | N30: 45586 | R30: 0 | X30: 1200 | Y30: =O30*X30+P30*X30+Q30*X30+R30*X30+S30*X30+T30*X30+U30*X30+V30*X30+W30*X30 -> 0
L31: =B31*K31+C31*K31+D31*K31+E31*K31+F31*K31+G31*K31+H31*K31+I31*K31+J31*K31 -> 0 | N31: 45587 | R31: 0.04 | X31: 1200 | Y31: =O31*X31+P31*X31+Q31*X31+R31*X31+S31*X31+T31*X31+U31*X31+V31*X31+W31*X31 -> 48
L32: =B32*K32+C32*K32+D32*K32+E32*K32+F32*K32+G32*K32+H32*K32+I32*K32+J32*K32 -> 0 | N32: 45589 | R32: 0 | S32: 0 | X32: 1200 | Y32: =O32*X32+P32*X32+Q32*X32+R32*X32+S32*X32+T32*X32+U32*X32+V32*X32+W32*X32 -> 0
L33: =B33*K33+C33*K33+D33*K33+E33*K33+F33*K33+G33*K33+H33*K33+I33*K33+J33*K33 -> 0 | N33: 45594 | P33: 29.22 | X33: 312 | Y33: =O33*X33+P33*X33+Q33*X33+R33*X33+S33*X33+T33*X33+U33*X33+V33*X33+W33*X33 -> 9116.64
A34: 45602 | B34: 25 | K34: 350.4 | L34: =B34*K34+C34*K34+D34*K34+E34*K34+F34*K34+G34*K34+H34*K34+I34*K34+J34*K34 -> 8760 | Q34: 8 | X34: 470.4 | Y34: =O34*X34+P34*X34+Q34*X34+R34*X34+S34*X34+T34*X34+U34*X34+V34*X34+W34*X34 -> 3763.2
H35: 3 | K35: 1758 | L35: =B35*K35+C35*K35+D35*K35+E35*K35+F35*K35+G35*K35+H35*K35+I35*K35+J35*K35 -> 5274 | N35: 45602 | O35: 25 | X35: 350.4 | Y35: =O35*X35+P35*X35+Q35*X35+R35*X35+S35*X35+T35*X35+U35*X35+V35*X35+W35*X35 -> 8760
L36: =B36*K36+C36*K36+D36*K36+E36*K36+F36*K36+G36*K36+H36*K36+I36*K36+J36*K36 -> 0 | U36: 1 | X36: 1758 | Y36: =O36*X36+P36*X36+Q36*X36+R36*X36+S36*X36+T36*X36+U36*X36+V36*X36+W36*X36 -> 1758
L37: =B37*K37+C37*K37+D37*K37+E37*K37+F37*K37+G37*K37+H37*K37+I37*K37+J37*K37 -> 0 | N37: 45618 | R37: 1 | X37: 1200 | Y37: =O37*X37+P37*X37+Q37*X37+R37*X37+S37*X37+T37*X37+U37*X37+V37*X37+W37*X37 -> 1200
L38: =B38*K38+C38*K38+D38*K38+E38*K38+F38*K38+G38*K38+H38*K38+I38*K38+J38*K38 -> 0 | N38: 45631 | S38: 1 | X38: 1200 | Y38: =O38*X38+P38*X38+Q38*X38+R38*X38+S38*X38+T38*X38+U38*X38+V38*X38+W38*X38 -> 1200
L39: =B39*K39+C39*K39+D39*K39+E39*K39+F39*K39+G39*K39+H39*K39+I39*K39+J39*K39 -> 0 | N39: 45638 | T39: 1 | X39: 1596 | Y39: =O39*X39+P39*X39+Q39*X39+R39*X39+S39*X39+T39*X39+U39*X39+V39*X39+W39*X39 -> 1596
L40: =B40*K40+C40*K40+D40*K40+E40*K40+F40*K40+G40*K40+H40*K40+I40*K40+J40*K40 -> 0 | N40: 45645 | R40: 1 | X40: 1200 | Y40: =O40*X40+P40*X40+Q40*X40+R40*X40+S40*X40+T40*X40+U40*X40+V40*X40+W40*X40 -> 1200
...

Sheet Велторг
A1: дата поставки | B1: Антиокислитель Вел-Микс 043 | C1: Ароматизатор сыр с халапеньо | D1: Краситель желтый закат | E1: Краситель тартразин | F1: Краситель зеленое яблоко | G1: Краситель белый титановый | H1: цена | I1: на сумму | K1: дата выдачи на пр-во | L1: в чей подотчет | M1: Антиокислитель Вел-Микс 043 | N1: Ароматизатор сыр с халапеньо | O1: Краситель желтый закат | P1: Краситель тартразин | Q1: Краситель зеленое яблоко | R1: Краситель белый титановый | S1: цена | T1: на сумму | V1: Антиокислитель Вел-Микс 043 | W1: Ароматизатор сыр с халапеньо | X1: Краситель желтый закат | Y1: Краситель тартразин | Z1: Краситель зеленое яблоко | AA1: Краситель белый титановый
A2: 2025 год | K2: 2025 год | V2: =0+B20-M20 -> 39.74 | W2: =0+C20-N20 -> 0 | X2: =0+D20-O20 -> 0 | Y2: =0+E20-P20 -> 0 | Z2: =0+F20-Q20 -> 0 | AA2: =0+G20-R20 -> 0
A3: 45755 | B3: 40 | H3: 2196.6 | I3: =B3*H3+C3*H3+D3*H3+E3*H3+F3*H3+G3*H3 -> 87864 | K3: 45755 | L3: Захаров | M3: 0.26 | S3: 2196.6 | T3: =M3*S3+N3*S3+O3*S3+P3*S3+Q3*S3+R3*S3 -> 571.116 | V3: 2196.6
I4: =B4*H4+C4*H4+D4*H4+E4*H4+F4*H4+G4*H4 -> 0 | L4: Захаров | T4: =M4*S4+N4*S4+O4*S4+P4*S4+Q4*S4+R4*S4 -> 0 | V4: =V2*V3 -> 87292.884 | W4: =W2*W3 -> 0 | X4: =X2*X3 -> 0 | Y4: =Y2*Y3 -> 0 | Z4: =Z2*Z3 -> 0 | AA4: =AA2*AA3 -> 0
I5: =B5*H5+C5*H5+D5*H5+E5*H5+F5*H5+G5*H5 -> 0 | L5: Захаров | T5: =M5*S5+N5*S5+O5*S5+P5*S5+Q5*S5+R5*S5 -> 0
I6: =B6*H6+C6*H6+D6*H6+E6*H6+F6*H6+G6*H6 -> 0 | L6: Захаров | T6: =M6*S6+N6*S6+O6*S6+P6*S6+Q6*S6+R6*S6 -> 0
I7: =B7*H7+C7*H7+D7*H7+E7*H7+F7*H7+G7*H7 -> 0 | L7: Захаров | T7: =M7*S7+N7*S7+O7*S7+P7*S7+Q7*S7+R7*S7 -> 0
I8: =B8*H8+C8*H8+D8*H8+E8*H8+F8*H8+G8*H8 -> 0 | L8: Захаров | T8: =M8*S8+N8*S8+O8*S8+P8*S8+Q8*S8+R8*S8 -> 0
I9: =B9*H9+C9*H9+D9*H9+E9*H9+F9*H9+G9*H9 -> 0 | L9: Захаров | T9: =M9*S9+N9*S9+O9*S9+P9*S9+Q9*S9+R9*S9 -> 0
I10: =B10*H10+C10*H10+D10*H10+E10*H10+F10*H10+G10*H10 -> 0 | L10: Захаров | T10: =M10*S10+N10*S10+O10*S10+P10*S10+Q10*S10+R10*S10 -> 0
I11: =B11*H11+C11*H11+D11*H11+E11*H11+F11*H11+G11*H11 -> 0 | L11: Захаров | T11: =M11*S11+N11*S11+O11*S11+P11*S11+Q11*S11+R11*S11 -> 0
I12: =B12*H12+C12*H12+D12*H12+E12*H12+F12*H12+G12*H12 -> 0 | L12: Захаров | T12: =M12*S12+N12*S12+O12*S12+P12*S12+Q12*S12+R12*S12 -> 0
I13: =B13*H13+C13*H13+D13*H13+E13*H13+F13*H13+G13*H13 -> 0 | L13: Захаров | T13: =M13*S13+N13*S13+O13*S13+P13*S13+Q13*S13+R13*S13 -> 0
I14: =B14*H14+C14*H14+D14*H14+E14*H14+F14*H14+G14*H14 -> 0 | T14: =M14*S14+N14*S14+O14*S14+P14*S14+Q14*S14+R14*S14 -> 0
I15: =B15*H15+C15*H15+D15*H15+E15*H15+F15*H15+G15*H15 -> 0 | T15: =M15*S15+N15*S15+O15*S15+P15*S15+Q15*S15+R15*S15 -> 0
I16: =B16*H16+C16*H16+D16*H16+E16*H16+F16*H16+G16*H16 -> 0 | T16: =M16*S16+N16*S16+O16*S16+P16*S16+Q16*S16+R16*S16 -> 0
I17: =B17*H17+C17*H17+D17*H17+E17*H17+F17*H17+G17*H17 -> 0 | T17: =M17*S17+N17*S17+O17*S17+P17*S17+Q17*S17+R17*S17 -> 0
I18: =B18*H18+C18*H18+D18*H18+E18*H18+F18*H18+G18*H18 -> 0 | T18: =M18*S18+N18*S18+O18*S18+P18*S18+Q18*S18+R18*S18 -> 0
I19: =B19*H19+C19*H19+D19*H19+E19*H19+F19*H19+G19*H19 -> 0 | T19: =M19*S19+N19*S19+O19*S19+P19*S19+Q19*S19+R19*S19 -> 0
B20: =SUM(B3:B19) -> 40 | C20: =SUM(C3:C19) -> 0 | D20: =SUM(D3:D19) -> 0 | E20: =SUM(E3:E19) -> 0 | F20: =SUM(F3:F19) -> 0 | G20: =SUM(G3:G19) -> 0 | H20: =SUM(H3:H19) -> 2196.6 | I20: =SUM(I3:I19) -> 87864 | M20: =SUM(M3:M19) -> 0.26 | N20: =SUM(N3:N19) -> 0 | O20: =SUM(O3:O19) -> 0 | P20: =SUM(P3:P19) -> 0 | Q20: =SUM(Q3:Q19) -> 0 | R20: =SUM(R3:R19) -> 0

Sheet Вито-Хаус
A1: дата поставки | B1: Ароматизатор барбекю | C1: Ароматизатор сыр с халапеньо | D1: Краситель желтый закат | E1: Краситель тартразин | F1: Краситель зеленое яблоко | G1: Краситель белый титановый | H1: цена | I1: на сумму | K1: дата выдачи на пр-во | L1: в чей подотчет | M1: Ароматизатор барбекю | N1: Ароматизатор сыр с халапеньо | O1: Краситель желтый закат | P1: Краситель тартразин | Q1: Краситель зеленое яблоко | R1: Краситель белый титановый | S1: цена | T1: на сумму | V1: Ароматизатор барбекю | W1: Ароматизатор сыр с халапеньо | X1: Краситель желтый закат | Y1: Краситель тартразин | Z1: Краситель зеленое яблоко | AA1: Краситель белый титановый
A2: 2024 год | K2: 2024 год | V2: =0+B20-M20 -> 0 | W2: =0+C20-N20 -> 0 | X2: =0+D20-O20 -> 0 | Y2: =0+E20-P20 -> 0 | Z2: =0+F20-Q20 -> 0 | AA2: =0+G20-R20 -> 0
A3: 45531 | G3: 25 | H3: 406 | I3: =B3*H3+C3*H3+D3*H3+E3*H3+F3*H3+G3*H3 -> 10150 | K3: 45535 | L3: Захаров | R3: 0.4 | S3: 406 | T3: =M3*S3+N3*S3+O3*S3+P3*S3+Q3*S3+R3*S3 -> 162.4 | V3: 312 | W3: 470.4 | X3: 1200 | Y3: 1200 | Z3: 1596 | AA3: 406
I4: =B4*H4+C4*H4+D4*H4+E4*H4+F4*H4+G4*H4 -> 0 | K4: 45545 | L4: Захаров | R4: 1.2 | S4: 406 | T4: =M4*S4+N4*S4+O4*S4+P4*S4+Q4*S4+R4*S4 -> 487.2 | V4: =V2*V3 -> 0 | W4: =W2*W3 -> 0 | X4: =X2*X3 -> 0 | Y4: =Y2*Y3 -> 0 | Z4: =Z2*Z3 -> 0 | AA4: =AA2*AA3 -> 0
I5: =B5*H5+C5*H5+D5*H5+E5*H5+F5*H5+G5*H5 -> 0 | K5: 45551 | L5: Захаров | R5: 0.5 | S5: 406 | T5: =M5*S5+N5*S5+O5*S5+P5*S5+Q5*S5+R5*S5 -> 203
I6: =B6*H6+C6*H6+D6*H6+E6*H6+F6*H6+G6*H6 -> 0 | K6: 45558 | L6: Захаров | R6: 0.4 | S6: 406 | T6: =M6*S6+N6*S6+O6*S6+P6*S6+Q6*S6+R6*S6 -> 162.4
I7: =B7*H7+C7*H7+D7*H7+E7*H7+F7*H7+G7*H7 -> 0 | K7: 45560 | L7: Захаров | R7: 0.3 | S7: 406 | T7: =M7*S7+N7*S7+O7*S7+P7*S7+Q7*S7+R7*S7 -> 121.8
I8: =B8*H8+C8*H8+D8*H8+E8*H8+F8*H8+G8*H8 -> 0 | K8: 45561 | L8: Захаров | R8: 0.1 | S8: 406 | T8: =M8*S8+N8*S8+O8*S8+P8*S8+Q8*S8+R8*S8 -> 40.6
I9: =B9*H9+C9*H9+D9*H9+E9*H9+F9*H9+G9*H9 -> 0 | K9: 45567 | L9: Захаров | R9: 0.35 | S9: 406 | T9: =M9*S9+N9*S9+O9*S9+P9*S9+Q9*S9+R9*S9 -> 142.1
I10: =B10*H10+C10*H10+D10*H10+E10*H10+F10*H10+G10*H10 -> 0 | K10: 45568 | L10: Захаров | R10: 0.6 | S10: 406 | T10: =M10*S10+N10*S10+O10*S10+P10*S10+Q10*S10+R10*S10 -> 243.6
I11: =B11*H11+C11*H11+D11*H11+E11*H11+F11*H11+G11*H11 -> 0 | K11: 45572 | L11: Захаров | R11: 1.8 | S11: 406 | T11: =M11*S11+N11*S11+O11*S11+P11*S11+Q11*S11+R11*S11 -> 730.8
I12: =B12*H12+C12*H12+D12*H12+E12*H12+F12*H12+G12*H12 -> 0 | K12: 45576 | L12: Захаров | R12: 19.35 | S12: 406 | T12: =M12*S12+N12*S12+O12*S12+P12*S12+Q12*S12+R12*S12 -> 7856.1
I13: =B13*H13+C13*H13+D13*H13+E13*H13+F13*H13+G13*H13 -> 0 | L13: Захаров | T13: =M13*S13+N13*S13+O13*S13+P13*S13+Q13*S13+R13*S13 -> 0
I14: =B14*H14+C14*H14+D14*H14+E14*H14+F14*H14+G14*H14 -> 0 | T14: =M14*S14+N14*S14+O14*S14+P14*S14+Q14*S14+R14*S14 -> 0
I15: =B15*H15+C15*H15+D15*H15+E15*H15+F15*H15+G15*H15 -> 0 | T15: =M15*S15+N15*S15+O15*S15+P15*S15+Q15*S15+R15*S15 -> 0
I16: =B16*H16+C16*H16+D16*H16+E16*H16+F16*H16+G16*H16 -> 0 | T16: =M16*S16+N16*S16+O16*S16+P16*S16+Q16*S16+R16*S16 -> 0
I17: =B17*H17+C17*H17+D17*H17+E17*H17+F17*H17+G17*H17 -> 0 | T17: =M17*S17+N17*S17+O17*S17+P17*S17+Q17*S17+R17*S17 -> 0
I18: =B18*H18+C18*H18+D18*H18+E18*H18+F18*H18+G18*H18 -> 0 | T18: =M18*S18+N18*S18+O18*S18+P18*S18+Q18*S18+R18*S18 -> 0
I19: =B19*H19+C19*H19+D19*H19+E19*H19+F19*H19+G19*H19 -> 0 | T19: =M19*S19+N19*S19+O19*S19+P19*S19+Q19*S19+R19*S19 -> 0
B20: =SUM(B3:B19) -> 0 | C20: =SUM(C3:C19) -> 0 | D20: =SUM(D3:D19) -> 0 | E20: =SUM(E3:E19) -> 0 | F20: =SUM(F3:F19) -> 0 | G20: =SUM(G3:G19) -> 25 | H20: =SUM(H3:H19) -> 406 | I20: =SUM(I3:I19) -> 10150 | M20: =SUM(M3:M19) -> 0 | N20: =SUM(N3:N19) -> 0 | O20: =SUM(O3:O19) -> 0 | P20: =SUM(P3:P19) -> 0 | Q20: =SUM(Q3:Q19) -> 0 | R20: =SUM(R3:R19) -> 25

Sheet Доминант
A1: дата поставки | B1: крахмал кукурузный ГОСТ | D1: крахмал кукурузный Е1422 | F1: крахмал кукурузный Е1414 | H1: мука кукурузная | I1: цена | J1: на сумму | L1: дата выдачи на пр-во | M1: крахмал кукурузный ГОСТ | O1: крахмал кукурузный Е1422 | Q1: крахмал кукурузный Е1414 | R1: крахмал кукурузный Е1414, 183р. | S1: мука кукурузная | T1: цена | U1: на сумму | W1: крахмал кукурузный ГОСТ | X1: крахмал кукурузный Е1422 | Y1: крахмал кукурузный Е1414 | AC1: мука кукурузная
A2: 2025 год | L2: 2025 год | W2: =0+B199-M199 -> 3150 | X2: =0+D199-O199 -> 1650 | Y2: =0+F199-Q199 -> 1350 | Z2: =0+C199-N199 -> 0 | AA2: =0+E199-P199 -> 0 | AB2: =0+G199-R199 -> 0 | AC2: =0+H199-S199 -> 0
A3: 45763 | B3: 2500 | I3: 47 | J3: =B3*I3+C3*I3+D3*I3+E3*I3+F3*I3+G3*I3+H3*I3 -> 117500 | L3: 45768 | Q3: 150 | T3: 183 | U3: =M3*T3+N3*T3+O3*T3+P3*T3+Q3*T3+R3*T3+S3*T3 -> 27450 | W3: 47 | X3: 183 | Y3: 183 | Z3: 48 | AA3: 183 | AB3: 183 | AC3: 37
D4: 1000 | F4: 1500 | I4: 183 | J4: =B4*I4+C4*I4+D4*I4+E4*I4+F4*I4+G4*I4+H4*I4 -> 457500 | U4: =M4*T4+N4*T4+O4*T4+P4*T4+Q4*T4+R4*T4+S4*T4 -> 0 | W4: =W2*W3 -> 148050 | X4: =X2*X3 -> 301950 | Y4: =Y2*Y3 -> 247050 | Z4: =Z2*Z3 -> 0 | AA4: =AA2*AA3 -> 0 | AB4: =AB2*AB3 -> 0 | AC4: =AC2*AC3 -> 0
F5: 25 | I5: 183 | J5: =B5*I5+C5*I5+D5*I5+E5*I5+F5*I5+G5*I5+H5*I5 -> 4575 | L5: 45771 | Q5: 150 | T5: 183 | U5: =M5*T5+N5*T5+O5*T5+P5*T5+Q5*T5+R5*T5+S5*T5 -> 27450
J6: =B6*I6+C6*I6+D6*I6+E6*I6+F6*I6+G6*I6+H6*I6 -> 0 | L6: 45775 | Q6: 400 | T6: 183 | U6: =M6*T6+N6*T6+O6*T6+P6*T6+Q6*T6+R6*T6+S6*T6 -> 73200
J7: =B7*I7+C7*I7+D7*I7+E7*I7+F7*I7+G7*I7+H7*I7 -> 0 | M7: 275 | T7: 47 | U7: =M7*T7+N7*T7+O7*T7+P7*T7+Q7*T7+R7*T7+S7*T7 -> 12925
J8: =B8*I8+C8*I8+D8*I8+E8*I8+F8*I8+G8*I8+H8*I8 -> 0 | L8: 45776 | Q8: 125 | T8: 183 | U8: =M8*T8+N8*T8+O8*T8+P8*T8+Q8*T8+R8*T8+S8*T8 -> 22875
J9: =B9*I9+C9*I9+D9*I9+E9*I9+F9*I9+G9*I9+H9*I9 -> 0 | M9: 125 | T9: 47 | U9: =M9*T9+N9*T9+O9*T9+P9*T9+Q9*T9+R9*T9+S9*T9 -> 5875
A10: 45777 | D10: 1000 | F10: 2000 | I10: 183 | J10: =B10*I10+C10*I10+D10*I10+E10*I10+F10*I10+G10*I10+H10*I10 -> 549000 | L10: 45777 | Q10: 125 | T10: 183 | U10: =M10*T10+N10*T10+O10*T10+P10*T10+Q10*T10+R10*T10+S10*T10 -> 22875
B11: 2000 | I11: 47 | J11: =B11*I11+C11*I11+D11*I11+E11*I11+F11*I11+G11*I11+H11*I11 -> 94000 | M11: 125 | T11: 47 | U11: =M11*T11+N11*T11+O11*T11+P11*T11+Q11*T11+R11*T11+S11*T11 -> 5875
L12: 01-04 мая | Q12: 275 | T12: 183 | U12: =M12*T12+N12*T12+O12*T12+P12*T12+Q12*T12+R12*T12+S12*T12 -> 50325
J13: =B13*I13+C13*I13+D13*I13+E13*I13+F13*I13+G13*I13+H13*I13 -> 0 | M13: 250 | T13: 47 | U13: =M13*T13+N13*T13+O13*T13+P13*T13+Q13*T13+R13*T13+S13*T13 -> 11750
J14: =B14*I14+C14*I14+D14*I14+E14*I14+F14*I14+G14*I14+H14*I14 -> 0 | O14: 75 | T14: 183 | U14: =M14*T14+N14*T14+O14*T14+P14*T14+Q14*T14+R14*T14+S14*T14 -> 13725
J15: =B15*I15+C15*I15+D15*I15+E15*I15+F15*I15+G15*I15+H15*I15 -> 0 | L15: 06 мая | Q15: 200 | T15: 183 | U15: =M15*T15+N15*T15+O15*T15+P15*T15+Q15*T15+R15*T15+S15*T15 -> 36600
J16: =B16*I16+C16*I16+D16*I16+E16*I16+F16*I16+G16*I16+H16*I16 -> 0 | M16: 200 | T16: 47 | U16: =M16*T16+N16*T16+O16*T16+P16*T16+Q16*T16+R16*T16+S16*T16 -> 9400
J17: =B17*I17+C17*I17+D17*I17+E17*I17+F17*I17+G17*I17+H17*I17 -> 0 | O17: 100 | T17: 183 | U17: =M17*T17+N17*T17+O17*T17+P17*T17+Q17*T17+R17*T17+S17*T17 -> 18300
J18: =B18*I18+C18*I18+D18*I18+E18*I18+F18*I18+G18*I18+H18*I18 -> 0 | L18: 07 мая | Q18: 125 | T18: 183 | U18: =M18*T18+N18*T18+O18*T18+P18*T18+Q18*T18+R18*T18+S18*T18 -> 22875
J19: =B19*I19+C19*I19+D19*I19+E19*I19+F19*I19+G19*I19+H19*I19 -> 0 | M19: 125 | T19: 47 | U19: =M19*T19+N19*T19+O19*T19+P19*T19+Q19*T19+R19*T19+S19*T19 -> 5875
J20: =B20*I20+C20*I20+D20*I20+E20*I20+F20*I20+G20*I20+H20*I20 -> 0 | L20: 10-11 мая | Q20: 125 | T20: 183 | U20: =M20*T20+N20*T20+O20*T20+P20*T20+Q20*T20+R20*T20+S20*T20 -> 22875
J21: =B21*I21+C21*I21+D21*I21+E21*I21+F21*I21+G21*I21+H21*I21 -> 0 | L21: 12 мая | Q21: 125 | T21: 47 | U21: =M21*T21+N21*T21+O21*T21+P21*T21+Q21*T21+R21*T21+S21*T21 -> 5875
J22: =B22*I22+C22*I22+D22*I22+E22*I22+F22*I22+G22*I22+H22*I22 -> 0 | O22: 125 | T22: 183 | U22: =M22*T22+N22*T22+O22*T22+P22*T22+Q22*T22+R22*T22+S22*T22 -> 22875
J23: =B23*I23+C23*I23+D23*I23+E23*I23+F23*I23+G23*I23+H23*I23 -> 0 | L23: 13 мая | Q23: 125 | T23: 183 | U23: =M23*T23+N23*T23+O23*T23+P23*T23+Q23*T23+R23*T23+S23*T23 -> 22875
J24: =B24*I24+C24*I24+D24*I24+E24*I24+F24*I24+G24*I24+H24*I24 -> 0 | L24: 14 мая | Q24: 125 | T24: 183 | U24: =M24*T24+N24*T24+O24*T24+P24*T24+Q24*T24+R24*T24+S24*T24 -> 22875
J25: =B25*I25+C25*I25+D25*I25+E25*I25+F25*I25+G25*I25+H25*I25 -> 0 | M25: 125 | T25: 47 | U25: =M25*T25+N25*T25+O25*T25+P25*T25+Q25*T25+R25*T25+S25*T25 -> 5875
J26: =B26*I26+C26*I26+D26*I26+E26*I26+F26*I26+G26*I26+H26*I26 -> 0 | L26: 22 мая | Q26: 125 | T26: 183 | U26: =M26*T26+N26*T26+O26*T26+P26*T26+Q26*T26+R26*T26+S26*T26 -> 22875
J27: =B27*I27+C27*I27+D27*I27+E27*I27+F27*I27+G27*I27+H27*I27 -> 0 | M27: 125 | T27: 47 | U27: =M27*T27+N27*T27+O27*T27+P27*T27+Q27*T27+R27*T27+S27*T27 -> 5875
J28: =B28*I28+C28*I28+D28*I28+E28*I28+F28*I28+G28*I28+H28*I28 -> 0 | O28: 50 | T28: 183 | U28: =M28*T28+N28*T28+O28*T28+P28*T28+Q28*T28+R28*T28+S28*T28 -> 9150
J29: =B29*I29+C29*I29+D29*I29+E29*I29+F29*I29+G29*I29+H29*I29 -> 0 | U29: =M29*T29+N29*T29+O29*T29+P29*T29+Q29*T29+R29*T29+S29*T29 -> 0
J30: =B30*I30+C30*I30+D30*I30+E30*I30+F30*I30+G30*I30+H30*I30 -> 0 | U30: =M30*T30+N30*T30+O30*T30+P30*T30+Q30*T30+R30*T30+S30*T30 -> 0
J31: =B31*I31+C31*I31+D31*I31+E31*I31+F31*I31+G31*I31+H31*I31 -> 0 | U31: =M31*T31+N31*T31+O31*T31+P31*T31+Q31*T31+R31*T31+S31*T31 -> 0
J32: =B32*I32+C32*I32+D32*I32+E32*I32+F32*I32+G32*I32+H32*I32 -> 0 | U32: =M32*T32+N32*T32+O32*T32+P32*T32+Q32*T32+R32*T32+S32*T32 -> 0
J33: =B33*I33+C33*I33+D33*I33+E33*I33+F33*I33+G33*I33+H33*I33 -> 0 | U33: =M33*T33+N33*T33+O33*T33+P33*T33+Q33*T33+R33*T33+S33*T33 -> 0
J34: =B34*I34+C34*I34+D34*I34+E34*I34+F34*I34+G34*I34+H34*I34 -> 0 | U34: =M34*T34+N34*T34+O34*T34+P34*T34+Q34*T34+R34*T34+S34*T34 -> 0
J35: =B35*I35+C35*I35+D35*I35+E35*I35+F35*I35+G35*I35+H35*I35 -> 0 | U35: =M35*T35+N35*T35+O35*T35+P35*T35+Q35*T35+R35*T35+S35*T35 -> 0
J36: =B36*I36+C36*I36+D36*I36+E36*I36+F36*I36+G36*I36+H36*I36 -> 0 | U36: =M36*T36+N36*T36+O36*T36+P36*T36+Q36*T36+R36*T36+S36*T36 -> 0
J37: =B37*I37+C37*I37+D37*I37+E37*I37+F37*I37+G37*I37+H37*I37 -> 0 | U37: =M37*T37+N37*T37+O37*T37+P37*T37+Q37*T37+R37*T37+S37*T37 -> 0
J38: =B38*I38+C38*I38+D38*I38+E38*I38+F38*I38+G38*I38+H38*I38 -> 0 | U38: =M38*T38+N38*T38+O38*T38+P38*T38+Q38*T38+R38*T38+S38*T38 -> 0
J39: =B39*I39+C39*I39+D39*I39+E39*I39+F39*I39+G39*I39+H39*I39 -> 0 | U39: =M39*T39+N39*T39+O39*T39+P39*T39+Q39*T39+R39*T39+S39*T39 -> 0
J40: =B40*I40+C40*I40+D40*I40+E40*I40+F40*I40+G40*I40+H40*I40 -> 0 | U40: =M40*T40+N40*T40+O40*T40+P40*T40+Q40*T40+R40*T40+S40*T40 -> 0
...

Sheet КрахмалПрод
A1: дата поставки | B1: патока крахм, кг | C1: цена | D1: на сумму | F1: дата выдачи на пр-во | G1: патока крахм, кг | H1: цена | I1: на сумму | L1: патока крахм, кг | M1: патока крахм, кг
A2: 2025 год | F2: 2025 год | L2: =0+B95-G95 -> 3424 | M2: =0+C95-H95 -> 0
A3: 45772 | B3: 1680 | C3: 59 | D3: =B3*C3 -> 99120 | F3: 45777 | G3: 128 | H3: 59 | I3: =G3*H3 -> 7552 | L3: 57 | M3: 59
A4: 10-11 мая | B4: 128 | C4: 59 | D4: =B4*C4 -> 7552 | F4: 07 мая | G4: 256 | H4: 57 | I4: =G4*H4 -> 14592 | L4: =L2*L3 -> 195168 | M4: =M2*M3 -> 0
A5: 20 мая | B5: 2240 | C5: 59 | D5: =B5*C5 -> 132160 | F5: 13 мая | G5: 128 | H5: 59 | I5: =G5*H5 -> 7552
B6: 144 | C6: 60 | D6: =B6*C6 -> 8640 | F6: 17 мая | G6: 128 | H6: 59 | I6: =G6*H6 -> 7552
D7: =B7*C7 -> 0 | F7: 23 мая | G7: 128 | H7: 60 | I7: =G7*H7 -> 7680
D8: =B8*C8 -> 0 | I8: =G8*H8 -> 0
D9: =B9*C9 -> 0 | I9: =G9*H9 -> 0
D10: =B10*C10 -> 0 | I10: =G10*H10 -> 0
D11: =B11*C11 -> 0 | I11: =G11*H11 -> 0
D12: =B12*C12 -> 0 | I12: =G12*H12 -> 0
D13: =B13*C13 -> 0 | I13: =G13*H13 -> 0
D14: =B14*C14 -> 0 | I14: =G14*H14 -> 0
D15: =B15*C15 -> 0 | I15: =G15*H15 -> 0
D16: =B16*C16 -> 0 | I16: =G16*H16 -> 0
D17: =B17*C17 -> 0 | I17: =G17*H17 -> 0
D18: =B18*C18 -> 0 | I18: =G18*H18 -> 0
D19: =B19*C19 -> 0 | I19: =G19*H19 -> 0
... D93: =B93*C93 -> 0 | I93: =G93*H93 -> 0
D94: =B94*C94 -> 0
B95: =SUM(B3:B94) -> 4192 | G95: =SUM(G3:G94) -> 768

Sheet РесурсГр
A1: дата поставки | B1: крахмал кукурузный ГОСТ | C1: крахмал кукурузный ГОСТ, 48р. | D1: крахмал кукурузный Е1422 | E1: крахмал кукурузный Е1422, 183р. | F1: крахмал кукурузный Е1414 | G1: крахмал кукурузный Е1414, 183р. | H1: мука кукурузная | I1: цена | J1: на сумму | L1: дата выдачи на пр-во | M1: крахмал кукурузный ГОСТ | N1: крахмал кукурузный ГОСТ, 48р. | O1: крахмал кукурузный Е1422 | P1: крахмал кукурузный Е1422, 183р. | Q1: крахмал кукурузный Е1414 | R1: крахмал кукурузный Е1414, 183р. | S1: мука кукурузная | T1: цена | U1: на сумму | W1: крахмал кукурузный ГОСТ | X1: крахмал кукурузный Е1422 | Y1: крахмал кукурузный Е1414 | Z1: крахмал кукурузный ГОСТ, 48р. | AA1: крахмал кукурузный Е1422, 183р. | AB1: крахмал кукурузный Е1414, 183р. | AC1: мука кукурузная
A2: 2024 год | L2: 2024 год | W2: =0+B221-M221 -> 50 | X2: =0+D221-O221 -> 0 | Y2: =0+F221-Q221 -> 0 | Z2: =0+C221-N221 -> 0 | AA2: =0+E221-P221 -> 75 | AB2: =0+G221-R221 -> 0 | AC2: =0+H221-S221 -> 0
A3: 45510 | B3: 2000 | I3: 49 | J3: =B3*I3+C3*I3+D3*I3+E3*I3+F3*I3+G3*I3+H3*I3 -> 98000 | M3: 5 | T3: 49 | U3: =M3*T3+N3*T3+O3*T3+P3*T3+Q3*T3+R3*T3+S3*T3 -> 245 | W3: 47 | X3: 185 | Y3: 185 | Z3: 48 | AA3: 183 | AB3: 183 | AC3: 37
D4: 2000 | I4: 185 | J4: =B4*I4+C4*I4+D4*I4+E4*I4+F4*I4+G4*I4+H4*I4 -> 370000 | O4: 9 | Q4: 2.3 | T4: 185 | U4: =M4*T4+N4*T4+O4*T4+P4*T4+Q4*T4+R4*T4+S4*T4 -> 2090.5 | W4: =W2*W3 -> 2350 | X4: =X2*X3 -> 0 | Y4: =Y2*Y3 -> 0 | Z4: =Z2*Z3 -> 0 | AA4: =AA2*AA3 -> 13725 | AB4: =AB2*AB3 -> 0 | AC4: =AC2*AC3 -> 0
F5: 1200 | I5: 185 | J5: =B5*I5+C5*I5+D5*I5+E5*I5+F5*I5+G5*I5+H5*I5 -> 222000 | L5: 45535 | M5: 12 | T5: 49 | U5: =M5*T5+N5*T5+O5*T5+P5*T5+Q5*T5+R5*T5+S5*T5 -> 588
J6: =B6*I6+C6*I6+D6*I6+E6*I6+F6*I6+G6*I6+H6*I6 -> 0 | O6: 9 | Q6: 7 | T6: 185 | U6: =M6*T6+N6*T6+O6*T6+P6*T6+Q6*T6+R6*T6+S6*T6 -> 2960
J7: =B7*I7+C7*I7+D7*I7+E7*I7+F7*I7+G7*I7+H7*I7 -> 0 | L7: 45545 | M7: 1 | T7: 49 | U7: =M7*T7+N7*T7+O7*T7+P7*T7+Q7*T7+R7*T7+S7*T7 -> 49
J8: =B8*I8+C8*I8+D8*I8+E8*I8+F8*I8+G8*I8+H8*I8 -> 0 | O8: 2 | Q8: 2 | T8: 185 | U8: =M8*T8+N8*T8+O8*T8+P8*T8+Q8*T8+R8*T8+S8*T8 -> 740
J9: =B9*I9+C9*I9+D9*I9+E9*I9+F9*I9+G9*I9+H9*I9 -> 0 | L9: 45551 | M9: 5 | T9: 49 | U9: =M9*T9+N9*T9+O9*T9+P9*T9+Q9*T9+R9*T9+S9*T9 -> 245
J10: =B10*I10+C10*I10+D10*I10+E10*I10+F10*I10+G10*I10+H10*I10 -> 0 | O10: 3 | Q10: 3 | T10: 185 | U10: =M10*T10+N10*T10+O10*T10+P10*T10+Q10*T10+R10*T10+S10*T10 -> 1110
J11: =B11*I11+C11*I11+D11*I11+E11*I11+F11*I11+G11*I11+H11*I11 -> 0 | L11: 45558 | M11: 12.2 | T11: 49 | U11: =M11*T11+N11*T11+O11*T11+P11*T11+Q11*T11+R11*T11+S11*T11 -> 597.8
J12: =B12*I12+C12*I12+D12*I12+E12*I12+F12*I12+G12*I12+H12*I12 -> 0 | O12: 3.6 | Q12: 4.6 | T12: 185 | U12: =M12*T12+N12*T12+O12*T12+P12*T12+Q12*T12+R12*T12+S12*T12 -> 1517
J13: =B13*I13+C13*I13+D13*I13+E13*I13+F13*I13+G13*I13+H13*I13 -> 0 | L13: 45561 | M13: 10.6 | T13: 49 | U13: =M13*T13+N13*T13+O13*T13+P13*T13+Q13*T13+R13*T13+S13*T13 -> 519.4
J14: =B14*I14+C14*I14+D14*I14+E14*I14+F14*I14+G14*I14+H14*I14 -> 0 | O14: 3.6 | Q14: 6.2 | T14: 185 | U14: =M14*T14+N14*T14+O14*T14+P14*T14+Q14*T14+R14*T14+S14*T14 -> 1813
J15: =B15*I15+C15*I15+D15*I15+E15*I15+F15*I15+G15*I15+H15*I15 -> 0 | L15: 45566 | M15: 1 | T15: 49 | U15: =M15*T15+N15*T15+O15*T15+P15*T15+Q15*T15+R15*T15+S15*T15 -> 49
J16: =B16*I16+C16*I16+D16*I16+E16*I16+F16*I16+G16*I16+H16*I16 -> 0 | O16: 1 | Q16: 1 | T16: 185 | U16: =M16*T16+N16*T16+O16*T16+P16*T16+Q16*T16+R16*T16+S16*T16 -> 370
J17: =B17*I17+C17*I17+D17*I17+E17*I17+F17*I17+G17*I17+H17*I17 -> 0 | L17: 45567 | M17: 14.6 | T17: 49 | U17: =M17*T17+N17*T17+O17*T17+P17*T17+Q17*T17+R17*T17+S17*T17 -> 715.4
J18: =B18*I18+C18*I18+D18*I18+E18*I18+F18*I18+G18*I18+H18*I18 -> 0 | O18: 8 | Q18: 4 | T18: 185 | U18: =M18*T18+N18*T18+O18*T18+P18*T18+Q18*T18+R18*T18+S18*T18 -> 2220
J19: =B19*I19+C19*I19+D19*I19+E19*I19+F19*I19+G19*I19+H19*I19 -> 0 | L19: 45568 | M19: 33 | T19: 49 | U19: =M19*T19+N19*T19+O19*T19+P19*T19+Q19*T19+R19*T19+S19*T19 -> 1617
J20: =B20*I20+C20*I20+D20*I20+E20*I20+F20*I20+G20*I20+H20*I20 -> 0 | O20: 10.8 | Q20: 25.8 | T20: 185 | U20: =M20*T20+N20*T20+O20*T20+P20*T20+Q20*T20+R20*T20+S20*T20 -> 6771
J21: =B21*I21+C21*I21+D21*I21+E21*I21+F21*I21+G21*I21+H21*I21 -> 0 | L21: 45569 | M21: 55.6 | T21: 49 | U21: =M21*T21+N21*T21+O21*T21+P21*T21+Q21*T21+R21*T21+S21*T21 -> 2724.4
J22: =B22*I22+C22*I22+D22*I22+E22*I22+F22*I22+G22*I22+H22*I22 -> 0 | O22: 0 | Q22: 69.1 | T22: 185 | U22: =M22*T22+N22*T22+O22*T22+P22*T22+Q22*T22+R22*T22+S22*T22 -> 12783.5
J23: =B23*I23+C23*I23+D23*I23+E23*I23+F23*I23+G23*I23+H23*I23 -> 0 | L23: 45572 | M23: 52.5 | T23: 49 | U23: =M23*T23+N23*T23+O23*T23+P23*T23+Q23*T23+R23*T23+S23*T23 -> 2572.5
J24: =B24*I24+C24*I24+D24*I24+E24*I24+F24*I24+G24*I24+H24*I24 -> 0 | O24: 15 | Q24: 36 | T24: 185 | U24: =M24*T24+N24*T24+O24*T24+P24*T24+Q24*T24+R24*T24+S24*T24 -> 9435
J25: =B25*I25+C25*I25+D25*I25+E25*I25+F25*I25+G25*I25+H25*I25 -> 0 | L25: 45576 | M25: 22.5 | U25: =M25*T25+N25*T25+O25*T25+P25*T25+Q25*T25+R25*T25+S25*T25 -> 0
J26: =B26*I26+C26*I26+D26*I26+E26*I26+F26*I26+G26*I26+H26*I26 -> 0 | O26: 10 | T26: 185 | U26: =M26*T26+N26*T26+O26*T26+P26*T26+Q26*T26+R26*T26+S26*T26 -> 1850
J27: =B27*I27+C27*I27+D27*I27+E27*I27+F27*I27+G27*I27+H27*I27 -> 0 | L27: 45580 | M27: 24.8 | T27: 49 | U27: =M27*T27+N27*T27+O27*T27+P27*T27+Q27*T27+R27*T27+S27*T27 -> 1215.2
J28: =B28*I28+C28*I28+D28*I28+E28*I28+F28*I28+G28*I28+H28*I28 -> 0 | O28: 11.2 | Q28: 27.2 | T28: 185 | U28: =M28*T28+N28*T28+O28*T28+P28*T28+Q28*T28+R28*T28+S28*T28 -> 7104
J29: =B29*I29+C29*I29+D29*I29+E29*I29+F29*I29+G29*I29+H29*I29 -> 0 | L29: 45581 | M29: 49.6 | T29: 49 | U29: =M29*T29+N29*T29+O29*T29+P29*T29+Q29*T29+R29*T29+S29*T29 -> 2430.4
J30: =B30*I30+C30*I30+D30*I30+E30*I30+F30*I30+G30*I30+H30*I30 -> 0 | O30: 22.4 | Q30: 54.4 | T30: 185 | U30: =M30*T30+N30*T30+O30*T30+P30*T30+Q30*T30+R30*T30+S30*T30 -> 14208
J31: =B31*I31+C31*I31+D31*I31+E31*I31+F31*I31+G31*I31+H31*I31 -> 0 | L31: 45582 | M31: 48 | T31: 49 | U31: =M31*T31+N31*T31+O31*T31+P31*T31+Q31*T31+R31*T31+S31*T31 -> 2352
J32: =B32*I32+C32*I32+D32*I32+E32*I32+F32*I32+G32*I32+H32*I32 -> 0 | O32: 22.4 | Q32: 56 | T32: 185 | U32: =M32*T32+N32*T32+O32*T32+P32*T32+Q32*T32+R32*T32+S32*T32 -> 14504
J33: =B33*I33+C33*I33+D33*I33+E33*I33+F33*I33+G33*I33+H33*I33 -> 0 | L33: 45583 | M33: 11 | T33: 49 | U33: =M33*T33+N33*T33+O33*T33+P33*T33+Q33*T33+R33*T33+S33*T33 -> 539
J34: =B34*I34+C34*I34+D34*I34+E34*I34+F34*I34+G34*I34+H34*I34 -> 0 | O34: 6.1 | Q34: 14.5 | T34: 185 | U34: =M34*T34+N34*T34+O34*T34+P34*T34+Q34*T34+R34*T34+S34*T34 -> 3811
J35: =B35*I35+C35*I35+D35*I35+E35*I35+F35*I35+G35*I35+H35*I35 -> 0 | L35: 45587 | M35: 11 | T35: 49 | U35: =M35*T35+N35*T35+O35*T35+P35*T35+Q35*T35+R35*T35+S35*T35 -> 539
J36: =B36*I36+C36*I36+D36*I36+E36*I36+F36*I36+G36*I36+H36*I36 -> 0 | O36: 6.1 | Q36: 14.5 | T36: 185 | U36: =M36*T36+N36*T36+O36*T36+P36*T36+Q36*T36+R36*T36+S36*T36 -> 3811
J37: =B37*I37+C37*I37+D37*I37+E37*I37+F37*I37+G37*I37+H37*I37 -> 0 | L37: 45589 | M37: 33 | T37: 49 | U37: =M37*T37+N37*T37+O37*T37+P37*T37+Q37*T37+R37*T37+S37*T37 -> 1617
J38: =B38*I38+C38*I38+D38*I38+E38*I38+F38*I38+G38*I38+H38*I38 -> 0 | O38: 18.3 | Q38: 43.5 | T38: 185 | U38: =M38*T38+N38*T38+O38*T38+P38*T38+Q38*T38+R38*T38+S38*T38 -> 11433
J39: =B39*I39+C39*I39+D39*I39+E39*I39+F39*I39+G39*I39+H39*I39 -> 0 | L39: 45594 | M39: 297.6 | T39: 49 | U39: =M39*T39+N39*T39+O39*T39+P39*T39+Q39*T39+R39*T39+S39*T39 -> 14582.4
J40: =B40*I40+C40*I40+D40*I40+E40*I40+F40*I40+G40*I40+H40*I40 -> 0 | O40: 38.5 | Q40: 153.9 | T40: 185 | U40: =M40*T40+N40*T40+O40*T40+P40*T40+Q40*T40+R40*T40+S40*T40 -> 35594
...

Sheet НьюБио
A1: дата поставки | B1: крахмал ГОСТ | H1: цена | I1: на сумму | K1: дата выдачи на пр-во | L1: в чей подотчет | M1: крахмал ГОСТ | S1: цена | T1: на сумму | V1: Ароматизатор барбекю | W1: Ароматизатор сыр с халапеньо | X1: Краситель желтый закат | Y1: Краситель тартразин | Z1: Краситель зеленое яблоко | AA1: Краситель белый титановый
V2: =0+B20-M20 -> 0 | W2: =0+C20-N20 -> 0 | X2: =0+D20-O20 -> 0 | Y2: =0+E20-P20 -> 0 | Z2: =0+F20-Q20 -> 0 | AA2: =0+G20-R20 -> 0
A3: 45714 | B3: 25 | H3: 165 | I3: =B3*H3+C3*H3+D3*H3+E3*H3+F3*H3+G3*H3 -> 4125 | K3: 45726 | L3: Захаров | M3: 25 | S3: 165 | T3: =M3*S3+N3*S3+O3*S3+P3*S3+Q3*S3+R3*S3 -> 4125 | V3: 165 | W3: 470.4 | X3: 1200 | Y3: 1200 | Z3: 1596 | AA3: 406
I4: =B4*H4+C4*H4+D4*H4+E4*H4+F4*H4+G4*H4 -> 0 | T4: =M4*S4+N4*S4+O4*S4+P4*S4+Q4*S4+R4*S4 -> 0 | V4: =V2*V3 -> 0 | W4: =W2*W3 -> 0 | X4: =X2*X3 -> 0 | Y4: =Y2*Y3 -> 0 | Z4: =Z2*Z3 -> 0 | AA4: =AA2*AA3 -> 0
I5: =B5*H5+C5*H5+D5*H5+E5*H5+F5*H5+G5*H5 -> 0 | T5: =M5*S5+N5*S5+O5*S5+P5*S5+Q5*S5+R5*S5 -> 0
I6: =B6*H6+C6*H6+D6*H6+E6*H6+F6*H6+G6*H6 -> 0 | T6: =M6*S6+N6*S6+O6*S6+P6*S6+Q6*S6+R6*S6 -> 0
I7: =B7*H7+C7*H7+D7*H7+E7*H7+F7*H7+G7*H7 -> 0 | T7: =M7*S7+N7*S7+O7*S7+P7*S7+Q7*S7+R7*S7 -> 0
I8: =B8*H8+C8*H8+D8*H8+E8*H8+F8*H8+G8*H8 -> 0 | T8: =M8*S8+N8*S8+O8*S8+P8*S8+Q8*S8+R8*S8 -> 0
I9: =B9*H9+C9*H9+D9*H9+E9*H9+F9*H9+G9*H9 -> 0 | T9: =M9*S9+N9*S9+O9*S9+P9*S9+Q9*S9+R9*S9 -> 0
I10: =B10*H10+C10*H10+D10*H10+E10*H10+F10*H10+G10*H10 -> 0 | T10: =M10*S10+N10*S10+O10*S10+P10*S10+Q10*S10+R10*S10 -> 0
I11: =B11*H11+C11*H11+D11*H11+E11*H11+F11*H11+G11*H11 -> 0 | T11: =M11*S11+N11*S11+O11*S11+P11*S11+Q11*S11+R11*S11 -> 0
I12: =B12*H12+C12*H12+D12*H12+E12*H12+F12*H12+G12*H12 -> 0 | T12: =M12*S12+N12*S12+O12*S12+P12*S12+Q12*S12+R12*S12 -> 0
I13: =B13*H13+C13*H13+D13*H13+E13*H13+F13*H13+G13*H13 -> 0 | T13: =M13*S13+N13*S13+O13*S13+P13*S13+Q13*S13+R13*S13 -> 0
I14: =B14*H14+C14*H14+D14*H14+E14*H14+F14*H14+G14*H14 -> 0 | T14: =M14*S14+N14*S14+O14*S14+P14*S14+Q14*S14+R14*S14 -> 0
I15: =B15*H15+C15*H15+D15*H15+E15*H15+F15*H15+G15*H15 -> 0 | T15: =M15*S15+N15*S15+O15*S15+P15*S15+Q15*S15+R15*S15 -> 0
I16: =B16*H16+C16*H16+D16*H16+E16*H16+F16*H16+G16*H16 -> 0 | T16: =M16*S16+N16*S16+O16*S16+P16*S16+Q16*S16+R16*S16 -> 0
... I19: =B19*H19+C19*H19+D19*H19+E19*H19+F19*H19+G19*H19 -> 0 | T19: =M19*S19+N19*S19+O19*S19+P19*S19+Q19*S19+R19*S19 -> 0
B20: =SUM(B3:B19) -> 25 | C20: =SUM(C3:C19) -> 0 | D20: =SUM(D3:D19) -> 0 | E20: =SUM(E3:E19) -> 0 | F20: =SUM(F3:F19) -> 0 | G20: =SUM(G3:G19) -> 0 | H20: =SUM(H3:H19) -> 165 | I20: =SUM(I3:I19) -> 4125 | M20: =SUM(M3:M19) -> 25 | N20: =SUM(N3:N19) -> 0 | O20: =SUM(O3:O19) -> 0 | P20: =SUM(P3:P19) -> 0 | Q20: =SUM(Q3:Q19) -> 0 | R20: =SUM(R3:R19) -> 0

Sheet Омега Фуд Техн
A1: дата поставки | B1: Пд сметана-зелень | C1: Пд васаби особая | D1: Пд сметана-зелень/3 | E1: Сметана-лук 117403 | G1: Пд сметана-зелень 403 | H1: цена | I1: на сумму | K1: дата выдачи на пр-во | L1: Пд сметана-зелень 446 | M1: Пд васаби особая | N1: Пд сметана-зелень/3 | O1: Сметана-лук 117403 | Q1: Пд сметана-зелень 403 | R1: цена | S1: на сумму | U1: Пд сметана-зелень | V1: Пд васаби особая | W1: Пд сметана-зелень/3 | X1: Сметана-лук 117403 | Z1: Пд сметана-зелень 403
A2: 2024 год | K2: 2024 год | U2: =0+B68-L68 -> 93 | V2: =0+C68-M68 -> 0 | W2: =0+D68-N68 -> 0 | X2: =0+E68-O68 -> 310 | Y2: =0+F68-P68 -> -25 | Z2: =0+G68-Q68 -> 0
A3: 45519 | B3: 120 | H3: 743.2872 | I3: =B3*H3+C3*H3+D3*H3+E3*H3+F3*H3+G3*H3 -> 89194.464 | S3: =L3*R3+M3*R3+N3*R3+O3*R3+P3*R3+Q3*R3 -> 0 | U3: 743.2872 | V3: 832.48158 | W3: 676.42 | X3: 559.19762 | Z3: 642.097
A4: 45520 | C4: 120 | H4: =I4/C4 -> 832.48158 | I4: 99897.79 | K4: 45535 | L4: 0 | R4: 743.2872 | S4: =L4*R4+M4*R4+N4*R4+O4*R4+P4*R4+Q4*R4 -> 0 | U4: =U2*U3 -> 69125.71 | V4: =V2*V3 -> 0 | W4: =W2*W3 -> 0 | X4: =X2*X3 -> 173351.26 | Y4: =Y2*Y3 -> 0 | Z4: =Z2*Z3 -> 0
I5: =B5*H5+C5*H5+D5*H5+E5*H5+F5*H5+G5*H5 -> 0 | M5: 0.06 | R5: 832.48158 | S5: =L5*R5+M5*R5+N5*R5+O5*R5+P5*R5+Q5*R5 -> 49.948895
I6: =B6*H6+C6*H6+D6*H6+E6*H6+F6*H6+G6*H6 -> 0 | K6: 45545 | L6: 0 | R6: 743.2872 | S6: =L6*R6+M6*R6+N6*R6+O6*R6+P6*R6+Q6*R6 -> 0
I7: =B7*H7+C7*H7+D7*H7+E7*H7+F7*H7+G7*H7 -> 0 | M7: 0.6 | R7: 832.48158 | S7: =L7*R7+M7*R7+N7*R7+O7*R7+P7*R7+Q7*R7 -> 499.48895
I8: =B8*H8+C8*H8+D8*H8+E8*H8+F8*H8+G8*H8 -> 0 | K8: 45551 | L8: -3 | R8: 743.2872 | S8: =L8*R8+M8*R8+N8*R8+O8*R8+P8*R8+Q8*R8 -> -2229.8616
I9: =B9*H9+C9*H9+D9*H9+E9*H9+F9*H9+G9*H9 -> 0 | M9: 0.5 | R9: 832.48158 | S9: =L9*R9+M9*R9+N9*R9+O9*R9+P9*R9+Q9*R9 -> 416.24079
I10: =B10*H10+C10*H10+D10*H10+E10*H10+F10*H10+G10*H10 -> 0 | K10: 45561 | M10: 1 | R10: 832.48158 | S10: =L10*R10+M10*R10+N10*R10+O10*R10+P10*R10+Q10*R10 -> 832.48158
A11: 45565 | G11: 12 | H11: 642.097 | I11: =B11*H11+C11*H11+D11*H11+E11*H11+F11*H11+G11*H11 -> 7705.164 | S11: =L11*R11+M11*R11+N11*R11+O11*R11+P11*R11+Q11*R11 -> 0
I12: =B12*H12+C12*H12+D12*H12+E12*H12+F12*H12+G12*H12 -> 0 | K12: 45572 | M12: 22.84 | R12: 832.48158 | S12: =L12*R12+M12*R12+N12*R12+O12*R12+P12*R12+Q12*R12 -> 19013.879
I13: =B13*H13+C13*H13+D13*H13+E13*H13+F13*H13+G13*H13 -> 0 | K13: 45589 | Q13: 1 | R13: 642.1 | S13: =L13*R13+M13*R13+N13*R13+O13*R13+P13*R13+Q13*R13 -> 642.1
I14: =B14*H14+C14*H14+D14*H14+E14*H14+F14*H14+G14*H14 -> 0 | K14: 45594 | M14: 20 | R14: 832.48158 | S14: =L14*R14+M14*R14+N14*R14+O14*R14+P14*R14+Q14*R14 -> 16649.632
A15: 45597 | D15: 97 | H15: 676.42 | I15: =B15*H15+C15*H15+D15*H15+E15*H15+F15*H15+G15*H15 -> 65612.74 | S15: =L15*R15+M15*R15+N15*R15+O15*R15+P15*R15+Q15*R15 -> 0
A16: пересорт | C16: 51 | H16: 832.48158 | I16: =B16*H16+C16*H16+D16*H16+E16*H16+F16*H16+G16*H16 -> 42456.561 | K16: 45601 | M16: 26 | R16: 832.48 | S16: =L16*R16+M16*R16+N16*R16+O16*R16+P16*R16+Q16*R16 -> 21644.48
I17: =B17*H17+C17*H17+D17*H17+E17*H17+F17*H17+G17*H17 -> 0 | N17: 2 | R17: 672.46 | S17: =L17*R17+M17*R17+N17*R17+O17*R17+P17*R17+Q17*R17 -> 1344.92
I18: =B18*H18+C18*H18+D18*H18+E18*H18+F18*H18+G18*H18 -> 0 | K18: 45618 | L18: 6 | R18: 743.29 | S18: =L18*R18+M18*R18+N18*R18+O18*R18+P18*R18+Q18*R18 -> 4459.74
I19: =B19*H19+C19*H19+D19*H19+E19*H19+F19*H19+G19*H19 -> 0 | N19: 25 | R19: 676.42 | S19: =L19*R19+M19*R19+N19*R19+O19*R19+P19*R19+Q19*R19 -> 16910.5
I20: =B20*H20+C20*H20+D20*H20+E20*H20+F20*H20+G20*H20 -> 0 | K20: 45631 | Q20: 1 | R20: 642.1 | S20: =L20*R20+M20*R20+N20*R20+O20*R20+P20*R20+Q20*R20 -> 642.1
