Workbook

Sheet склад
A1: Склад комплектующих
A2: Лотки | B2: тарелка КД-404 Тарелка подорехи прозрачная | C2: Тарелки ТР-209/4 | E2: Гофроящик Кедровый бор (Монетка) | F2: Гофроящик h=1677 (Лента) | G2: ПЛЕНКА без печати ВОРР ширина 430 | I2: Пакет ПНД 60*100 14 мк | J2: Пленка 500 мл 20 мк | K2: Пленка паллет 500 мм 17 мк 2,0 кг вторичная | M2: Пакет ПНД 46+60 30 мк | N2: Пленка паллет | O2: Пакеты вакуумные Biovak 200*300 Рет//ре 65 | Q2: Пленка Арахисовая тарелка ЧИПЛС 4 вкуса 200 г | R2: Пленка Арахисовая тарелка Smakky Asian Mix 200 г | S2: Пленка Арахисовая тарелка Smakky Classic Mix 200г
A3: НИКА | B3: Золотой Снек | C3: Пластик | E3: ТД Л-Пак | F3: ТД Л-Пак | G3: РусУпак | I3: Приопак | J3: Приопак | K3: Приопак | M3: ИП Тришина | N3: Приопак/ТД Л-Пак | O3: ООО "ПТК Аурумфуд" | Q3: УпакАреал | R3: УпакАреал | S3: УпакАреал
A4: =Ника!L2 -> 4607 | B4: ='Золотой Снек'!Q2 -> 0 | C4: =Пластик!P2 -> 47400 | D4: =A4+B4+C4 -> 52007 | E4: ='ТД-Л Пак'!U2 -> 1300 | F4: ='ТД-Л Пак'!V2 -> 932 | G4: =РусУпак!Y2 -> 166 | H4: =E4+F4+G4 -> 2398 | I4: =Приопак!Y2 -> 492 | J4: =Приопак!Z2 -> 0 | K4: =Приопак!AA2 -> 29 | L4: =I4+J4+K4 -> 521 | M4: ='ИП Тришина'!R2 -> 0 | N4: ='ТД-Л Пак'!W2 -> 54 | O4: =АурумФуд!Q2 -> 1400 | P4: =M4+N4+O4 -> 1454 | Q4: =УпакАреал!X2 -> 574.35 | R4: =УпакАреал!Y2 -> 245.41 | S4: =УпакАреал!Z2 -> 261.44 | T4: =Q4+R4+S4 -> 1081.2
A5: 5 | B5: 4.95 | C5: 5.3 | E5: 25.776 | F5: 24.744 | G5: 280 | I5: 4 | J5: 446.12 | K5: 441.6866 | M5: 4.25 | N5: 432.82 | O5: 3.86 | Q5: 715 | R5: 850 | S5: 850
A6: =A4*A5 -> 23035 | B6: =B4*B5 -> 0 | C6: =C4*C5 -> 251220 | D6: =A6+B6+C6 -> 274255 | E6: =E4*E5 -> 33508.8 | F6: =F4*F5 -> 23061.408 | G6: =G4*G5 -> 46480 | H6: =E6+F6+G6 -> 103050.21 | I6: =I4*I5 -> 1968 | J6: =J4*J5 -> 0 | K6: =K4*K5 -> 12808.911 | L6: =I6+J6+K6 -> 14776.911 | M6: =M4*M5 -> 0 | N6: =N4*N5 -> 23372.28 | O6: =O4*O5 -> 5404 | P6: =M6+N6+O6 -> 28776.28 | Q6: =Q4*Q5 -> 410660.25 | R6: =R4*R5 -> 208598.5 | S6: =S4*S5 -> 222224 | T6: =Q6+R6+S6 -> 841482.75
A8: ПЛЕНКА БОПП 40*310 | B8: ПЛЕНКА БОПП 40*420 | C8: ПЛЕНКА без печати ВОРР ширина 310 ЯндексЛ | E8: Мешок полипропиленовый 55*95 см серый | F8: Мешки пищевые белые | G8: Пленка КВАДРО МИКС "Тарелка" БОПП 20 мкм проз.,240*310 мм | I8: Пакет ПНД 45*27*60 14 мк | J8: Пакет ПНД 45*27*60 14 мк | K8: Плёнка для запайки 240 мм | M8: Пакет бумажный 150*240 | N8: Этикетка 57*40 мм Лицо | O8: Этикетка 57*40 мм Оборот
A9: Ф-Граф | B9: Ф-Граф | C9: РусУпак | E9: Приопак | F9: Озон | G9: Ф-Граф | I9: Приопак | J9: Приопак | K9: Приопак | M9: ч/л | N9: Полимаркет | O9: Полимаркет
A10: ='Ф-Граф'!AG2 -> 0 | B10: ='Ф-Граф'!AH2 -> 25.45 | C10: =РусУпак!X2 -> 139.2 | D10: =A10+B10+C10 -> 164.65 | E10: =Приопак!AE2 -> 0 | F10: =Озон!S2 -> 0 | G10: ='Ф-Граф'!AI2 -> 434.12 | H10: =E10+F10+G10 -> 434.12 | I10: =Приопак!AB2 -> 1580 | J10: =Приопак!AC2 -> 0 | K10: =Приопак!AD2 -> 3.65 | L10: =I10+J10+K10 -> 1583.65 | M10: =чл!V2 -> 0 | N10: =Полимаркет!Q2 -> 0 | O10: =Полимаркет!R2 -> 0 | P10: =M10+N10+O10 -> 0
A11: 414 | B11: 414 | C11: 290 | E11: 18 | F11: 20.24 | G11: 625 | I11: 2.9 | J11: 2.86 | K11: 499.4 | M11: 12.59 | N11: 0.54 | O11: 0.54
A12: =A10*A11 -> 0 | B12: =B10*B11 -> 10536.3 | C12: =C10*C11 -> 40368 | D12: =A12+B12+C12 -> 50904.3 | E12: =E10*E11 -> 0 | F12: =F10*F11 -> 0 | G12: =G10*G11 -> 271325 | H12: =E12+F12+G12 -> 271325 | I12: =I10*I11 -> 4582 | J12: =J10*J11 -> 0 | K12: =K10*K11 -> 1822.81 | L12: =I12+J12+K12 -> 6404.81 | M12: =M10*M11 -> 0 | N12: =N10*N11 -> 0 | O12: =O10*O11 -> 0 | P12: =M12+N12+O12 -> 0
A15: Короб "Ласточкин хвост" | B15: гофроящик Н=1648 бп | C15: Гофроящик Н=1703 б/п (для ЯндексЛ) | D15: Гофрокороб 460*340*130-Т24 | F15: Пленки | M15: Пакеты для фасовки | N15: термопленка | O15: этикетки | P15: этикетки
F16: сметана-лук | G16: васаби | H16: барбекю | I16: сыр | J16: арахис | K16: фисташки
A17: СЗ-Гофра | B17: ТД Л-Пак | C17: ТД Л-Пак | D17: Золотой Снек | F17: Ф-Граф | G17: Ф-Граф | H17: Ф-Граф | I17: Ф-Граф | J17: Ф-Граф | K17: Ф-Граф | M17: ИП Тришина | N17: Концепт | O17: ЛейблСтик | P17: ЛейблСтик
A18: ='СЗ-Гофра'!M2 -> 17435 | B18: ='ТД-Л Пак'!S2 -> 4200 | C18: ='ТД-Л Пак'!T2 -> 0 | D18: ='Золотой Снек'!R2 -> 290 | E18: =A18+B18+C18+D18 -> 21925 | F18: ='Ф-Граф'!AA2 -> 210.2 | G18: ='Ф-Граф'!AB2 -> 204.85 | H18: ='Ф-Граф'!AC2 -> 222.25 | I18: ='Ф-Граф'!AD2 -> 222.9 | J18: ='Ф-Граф'!AE2 -> -181.86 | K18: ='Ф-Граф'!AF2 -> 266 | L18: =F18+G18+H18+I18+J18+K18 -> 944.34 | M18: ='ИП Тришина'!Q2 -> 0 | N18: =Концепт!M2 -> 0 | O18: =ЛейблСтик!R2 -> 0 | P18: =ЛейблСтик!S2 -> 0 | Q18: =M18+N18+O18+P18 -> 0
A19: 17.4 | B19: 24.996 | C19: 13.788 | D19: 33 | F19: 605 | G19: 605 | H19: 605 | I19: 605 | J19: 682 | K19: 692 | M19: 3.1 | N19: 145 | O19: 5.83333 | P19: 3.41435
A20: =A18*A19 -> 303369 | B20: =B18*B19 -> 104983.2 | C20: =C18*C19 -> 0 | D20: =D18*D19 -> 9570 | E20: =A20+B20+C20+D20 -> 417922.2 | F20: =F18*F19 -> 127171 | G20: =G18*G19 -> 123934.25 | H20: =H18*H19 -> 134461.25 | I20: =I18*I19 -> 134854.5 | J20: =J18*J19 -> -124028.52 | K20: =K18*K19 -> 184072 | L20: =F20+G20+H20+I20+J20+K20 -> 580464.48 | M20: =M18*M19 -> 0 | N20: =N18*N19 -> 0 | O20: =O18*O19 -> 0 | P20: =P18*P19 -> 0 | Q20: =M20+N20+O20+P20 -> 0
A22: Остаток комплект, на сумму | D22: =D6+H6+L6+P6+T6+D12+H12+L12+P12+E20+L20+Q20+-32526.75 -> 2556835.2
A24: Остаток комплект, в единицах | D24: =D4+H4+L4+P4+T4+E18+L18+Q18+L10+P10+H10+D10+0-4222.35 -> 78290.61

Sheet АурумФуд
A1: дата поставки | B1: Пакеты вакуумные Biovak 200*300 Рет//ре 65 | E1: цена | F1: на сумму | H1: дата выдачи на пр-во | I1: в чей подотчет | J1: Пакеты вакуумные Biovak 200*300 Рет//ре 65 | M1: цена | N1: на сумму | Q1: Пакеты вакуумные Biovak 200*300 Рет//ре 65
A2: 2024 год | H2: 2024 год | Q2: =0+B36-J36 -> 1400 | R2: =0+C36-K36 -> 0 | S2: =0+D36-L36 -> 0
A3: 45635 | B3: 10000 | E3: 3.86 | F3: =B3*E3+C3*E3+D3*E3 -> 38600 | H3: 45636 | I3: Захаров | J3: 126 | M3: 3.86 | N3: =J3*M3+K3*M3+L3*M3 -> 486.36 | Q3: 3.86 | R3: 4.25 | S3: 408.2
F4: =B4*E4+C4*E4+D4*E4 -> 0 | H4: 45637 | I4: Захаров | J4: 777 | M4: 3.86 | N4: =J4*M4+K4*M4+L4*M4 -> 2999.22 | Q4: =Q2*Q3 -> 5404 | R4: =R2*R3 -> 0 | S4: =S2*S3 -> 0
F5: =B5*E5+C5*E5+D5*E5 -> 0 | H5: 45638 | I5: Захаров | J5: 932 | M5: 3.86 | N5: =J5*M5+K5*M5+L5*M5 -> 3597.52
F6: =B6*E6+C6*E6+D6*E6 -> 0 | H6: 45642 | I6: Захаров | J6: 322 | M6: 3.86 | N6: =J6*M6+K6*M6+L6*M6 -> 1242.92
F7: =B7*E7+C7*E7+D7*E7 -> 0 | H7: 45643 | I7: Захаров | J7: 322 | M7: 3.86 | N7: =J7*M7+K7*M7+L7*M7 -> 1242.92
F8: =B8*E8+C8*E8+D8*E8 -> 0 | H8: 45644 | I8: Захаров | J8: 322 | M8: 3.86 | N8: =J8*M8+K8*M8+L8*M8 -> 1242.92
F9: =B9*E9+C9*E9+D9*E9 -> 0 | H9: 45646 | I9: Захаров | J9: 490 | M9: 3.86 | N9: =J9*M9+K9*M9+L9*M9 -> 1891.4
F10: =B10*E10+C10*E10+D10*E10 -> 0 | H10: 45649 | I10: Захаров | J10: 161 | M10: 3.86 | N10: =J10*M10+K10*M10+L10*M10 -> 621.46
F11: =B11*E11+C11*E11+D11*E11 -> 0 | H11: 45651 | I11: Захаров | J11: 1302 | M11: 3.86 | N11: =J11*M11+K11*M11+L11*M11 -> 5025.72
F12: =B12*E12+C12*E12+D12*E12 -> 0 | H12: 45652 | I12: Захаров | J12: 1092 | M12: 3.86 | N12: =J12*M12+K12*M12+L12*M12 -> 4215.12
F13: =B13*E13+C13*E13+D13*E13 -> 0 | H13: 2025 год | N13: =J13*M13+K13*M13+L13*M13 -> 0
F14: =B14*E14+C14*E14+D14*E14 -> 0 | H14: 45666 | I14: Захаров | J14: 266 | M14: 3.86 | N14: =J14*M14+K14*M14+L14*M14 -> 1026.76
F15: =B15*E15+C15*E15+D15*E15 -> 0 | H15: 45667 | I15: Захаров | J15: 259 | M15: 3.86 | N15: =J15*M15+K15*M15+L15*M15 -> 999.74
F16: =B16*E16+C16*E16+D16*E16 -> 0 | H16: 45670 | I16: Захаров | J16: 392 | M16: 3.86 | N16: =J16*M16+K16*M16+L16*M16 -> 1513.12
F17: =B17*E17+C17*E17+D17*E17 -> 0 | H17: 45671 | I17: Захаров | J17: 882 | M17: 3.86 | N17: =J17*M17+K17*M17+L17*M17 -> 3404.52
F18: =B18*E18+C18*E18+D18*E18 -> 0 | H18: 45672 | I18: Захаров | J18: 238 | M18: 3.86 | N18: =J18*M18+K18*M18+L18*M18 -> 918.68
F19: =B19*E19+C19*E19+D19*E19 -> 0 | H19: 45673 | I19: Захаров | J19: 217 | M19: 3.86 | N19: =J19*M19+K19*M19+L19*M19 -> 837.62
F20: =B20*E20+C20*E20+D20*E20 -> 0 | H20: 45674 | I20: Захаров | J20: 1900 | M20: 3.86 | N20: =J20*M20+K20*M20+L20*M20 -> 7334
A21: 45707 | B21: 5000 | E21: 3.86 | F21: =B21*E21+C21*E21+D21*E21 -> 19300 | N21: =J21*M21+K21*M21+L21*M21 -> 0
F22: =B22*E22+C22*E22+D22*E22 -> 0 | H22: март | N22: =J22*M22+K22*M22+L22*M22 -> 0
F23: =B23*E23+C23*E23+D23*E23 -> 0 | H23: 45741 | I23: Захаров | J23: 1800 | M23: 3.86 | N23: =J23*M23+K23*M23+L23*M23 -> 6948
A24: май | F24: =B24*E24+C24*E24+D24*E24 -> 0 | H24: май | N24: =J24*M24+K24*M24+L24*M24 -> 0
F25: =B25*E25+C25*E25+D25*E25 -> 0 | J25: 1800 | M25: 3.86 | N25: =J25*M25+K25*M25+L25*M25 -> 6948
F26: =B26*E26+C26*E26+D26*E26 -> 0 | N26: =J26*M26+K26*M26+L26*M26 -> 0
F27: =B27*E27+C27*E27+D27*E27 -> 0 | N27: =J27*M27+K27*M27+L27*M27 -> 0
F28: =B28*E28+C28*E28+D28*E28 -> 0 | N28: =J28*M28+K28*M28+L28*M28 -> 0
F29: =B29*E29+C29*E29+D29*E29 -> 0 | N29: =J29*M29+K29*M29+L29*M29 -> 0
F30: =B30*E30+C30*E30+D30*E30 -> 0 | N30: =J30*M30+K30*M30+L30*M30 -> 0
F31: =B31*E31+C31*E31+D31*E31 -> 0 | N31: =J31*M31+K31*M31+L31*M31 -> 0
F32: =B32*E32+C32*E32+D32*E32 -> 0 | N32: =J32*M32+K32*M32+L32*M32 -> 0
F33: =B33*E33+C33*E33+D33*E33 -> 0 | N33: =J33*M33+K33*M33+L33*M33 -> 0
F34: =B34*E34+C34*E34+D34*E34 -> 0 | N34: =J34*M34+K34*M34+L34*M34 -> 0
F35: =B35*E35+C35*E35+D35*E35 -> 0 | N35: =J35*M35+K35*M35+L35*M35 -> 0
B36: =SUM(B3:B35) -> 15000 | C36: =SUM(C3:C35) -> 0 | D36: =SUM(D3:D35) -> 0 | J36: =SUM(J3:J35) -> 13600 | K36: =SUM(K3:K35) -> 0 | L36: =SUM(L3:L35) -> 0

Sheet Золотой Снек
A1: дата поставки | B1: тарелка КД-404 Тарелка подорехи прозрачная | C1: Гофрокороб 460*340*130-Т24 | E1: цена | F1: на сумму | H1: дата выдачи на пр-во | I1: в чей подотчет | J1: тарелка КД-404 Тарелка подорехи прозрачная | K1: Гофрокороб 460*340*130-Т24 | M1: цена | N1: на сумму | Q1: тарелка КД-404 Тарелка подорехи прозрачная | R1: Гофрокороб 460*340*130-Т24
A2: 2025 год | H2: 2025 год | Q2: =0+B39-J39 -> 0 | R2: =0+C39-K39 -> 290
A3: 45674 | B3: 59760 | E3: 4.95 | F3: =B3*E3+C3*E3+D3*E3 -> 295812 | H3: 45719 | I3: Захаров | J3: 2070 | M3: 4.95 | N3: =J3*M3+K3*M3+L3*M3 -> 10246.5 | Q3: 4.95 | R3: 33
A4: 45686 | C4: 250 | E4: 36.2 | F4: =B4*E4+C4*E4+D4*E4 -> 9050 | H4: 45720 | I4: Захаров | J4: 2160 | M4: 4.95 | N4: =J4*M4+K4*M4+L4*M4 -> 10692 | Q4: =Q2*Q3 -> 0 | R4: =R2*R3 -> 9570
H5: 45721 | I5: Захаров | J5: 1440 | M5: 4.95 | N5: =J5*M5+K5*M5+L5*M5 -> 7128
H6: 45722 | I6: Захаров | J6: 2200 | M6: 4.95 | N6: =J6*M6+K6*M6+L6*M6 -> 10890
H7: 45723 | I7: Захаров | J7: 2880 | M7: 4.95 | N7: =J7*M7+K7*M7+L7*M7 -> 14256
H8: 45726 | I8: Захаров | J8: 2160 | M8: 4.95 | N8: =J8*M8+K8*M8+L8*M8 -> 10692
H9: 45727 | I9: Захаров | J9: 2880 | M9: 4.95 | N9: =J9*M9+K9*M9+L9*M9 -> 14256
H10: 45728 | I10: Захаров | J10: 3600 | M10: 4.95 | N10: =J10*M10+K10*M10+L10*M10 -> 17820
H11: 45729 | I11: Захаров | J11: 7200 | M11: 4.95 | N11: =J11*M11+K11*M11+L11*M11 -> 35640
H12: 45730 | I12: Захаров | J12: 3600 | M12: 4.95 | N12: =J12*M12+K12*M12+L12*M12 -> 17820
H13: 45733 | I13: Захаров | J13: 1440 | M13: 4.95 | N13: =J13*M13+K13*M13+L13*M13 -> 7128
I14: Захаров | K14: 250 | M14: 36.2 | N14: =J14*M14+K14*M14+L14*M14 -> 9050
H15: 45734 | I15: Захаров | J15: 5760 | M15: 4.95 | N15: =J15*M15+K15*M15+L15*M15 -> 28512
H16: 45735 | I16: Захаров | J16: 720 | M16: 4.95 | N16: =J16*M16+K16*M16+L16*M16 -> 3564
H17: 45736 | I17: Захаров | J17: 5760 | M17: 4.95 | N17: =J17*M17+K17*M17+L17*M17 -> 28512
H18: 45737 | I18: Захаров | J18: 3650 | M18: 4.95 | N18: =J18*M18+K18*M18+L18*M18 -> 18067.5
H19: 45740 | I19: Захаров | J19: 6480 | M19: 4.95 | N19: =J19*M19+K19*M19+L19*M19 -> 32076
H20: 45741 | I20: Захаров | J20: 5760 | M20: 4.95 | N20: =J20*M20+K20*M20+L20*M20 -> 28512
A22: 45757 | C22: 500 | E22: 33 | F22: =B22*E22+C22*E22+D22*E22 -> 16500 | H22: 45757 | I22: Захаров | K22: 250 | M22: 33 | N22: =J22*M22+K22*M22+L22*M22 -> 8250
F23: =B23*E23+C23*E23+D23*E23 -> 0 | H23: 45762 | I23: Захаров | K23: 250 | M23: 33 | N23: =J23*M23+K23*M23+L23*M23 -> 8250
A24: 45763 | C24: 500 | E24: 33 | F24: =B24*E24+C24*E24+D24*E24 -> 16500 | H24: 45763 | I24: Захаров | K24: 100 | M24: 33 | N24: =J24*M24+K24*M24+L24*M24 -> 3300
F25: =B25*E25+C25*E25+D25*E25 -> 0 | H25: 45764 | I25: Захаров | K25: 150 | M25: 33 | N25: =J25*M25+K25*M25+L25*M25 -> 4950
F26: =B26*E26+C26*E26+D26*E26 -> 0 | H26: 45765 | I26: Захаров | K26: 250 | M26: 33 | N26: =J26*M26+K26*M26+L26*M26 -> 8250
A27: май | H27: май
A28: 14 мая | C28: 1500 | E28: 33 | F28: =B28*E28+C28*E28+D28*E28 -> 49500 | H28: 19 мая | I28: Захаров | K28: 550 | M28: 33 | N28: =J28*M28+K28*M28+L28*M28 -> 18150
F29: =B29*E29+C29*E29+D29*E29 -> 0 | H29: 20 мая | I29: Захаров | K29: 660 | M29: 33 | N29: =J29*M29+K29*M29+L29*M29 -> 21780
F30: =B30*E30+C30*E30+D30*E30 -> 0 | I30: Захаров | N30: =J30*M30+K30*M30+L30*M30 -> 0
F31: =B31*E31+C31*E31+D31*E31 -> 0 | I31: Захаров | N31: =J31*M31+K31*M31+L31*M31 -> 0
F32: =B32*E32+C32*E32+D32*E32 -> 0 | I32: Захаров | N32: =J32*M32+K32*M32+L32*M32 -> 0
F33: =B33*E33+C33*E33+D33*E33 -> 0 | I33: Захаров | N33: =J33*M33+K33*M33+L33*M33 -> 0
F34: =B34*E34+C34*E34+D34*E34 -> 0 | I34: Захаров | N34: =J34*M34+K34*M34+L34*M34 -> 0
F35: =B35*E35+C35*E35+D35*E35 -> 0 | I35: Захаров | N35: =J35*M35+K35*M35+L35*M35 -> 0
F36: =B36*E36+C36*E36+D36*E36 -> 0 | I36: Захаров | N36: =J36*M36+K36*M36+L36*M36 -> 0
F37: =B37*E37+C37*E37+D37*E37 -> 0 | I37: Захаров | N37: =J37*M37+K37*M37+L37*M37 -> 0
F38: =B38*E38+C38*E38+D38*E38 -> 0 | N38: =J38*M38+K38*M38+L38*M38 -> 0
B39: =SUM(B3:B38) -> 59760 | C39: =SUM(C3:C38) -> 2750 | D39: =SUM(D3:D38) -> 0 | J39: =SUM(J3:J38) -> 59760 | K39: =SUM(K3:K38) -> 2460 | L39: =SUM(L3:L38) -> 0

Sheet ИП Тришина
A1: дата поставки | B1: пакеты | C1: Пакет ПНД 46+60 30 мк | D1: Пленка паллет 500 мм 17 мк 2,0 кг вторичная | E1: цена | F1: на сумму | H1: дата выдачи на пр-во | I1: в чей подотчет | J1: пакеты | K1: Пакет ПНД 46+60 30 мк | L1: Пленка паллет 500 мм 17 мк 2,0 кг вторичная | M1: цена | N1: на сумму | Q1: пакеты | R1: Пакет ПНД 46+60 30 мк | S1: Пленка паллет 500 мм 17 мк 2,0 кг вторичная
A2: 2024 год | H2: 2024 год | Q2: =0+B20-J20 -> 0 | R2: =0+C20-K20 -> 0 | S2: =0+D20-L20 -> 0
A3: 45573 | B3: 300 | E3: 3.1 | F3: =B3*E3+C3*E3+D3*E3 -> 930 | H3: 45573 | I3: Захаров | J3: 114 | M3: 3.1 | N3: =J3*M3+K3*M3+L3*M3 -> 353.4 | Q3: 3.1 | R3: 4.25 | S3: 408.2
A4: 45583 | B4: 500 | E4: 3.1 | F4: =B4*E4+C4*E4+D4*E4 -> 1550 | H4: 45587 | I4: Захаров | J4: 282 | M4: 3.1 | N4: =J4*M4+K4*M4+L4*M4 -> 874.2 | Q4: =Q2*Q3 -> 0 | R4: =R2*R3 -> 0 | S4: =S2*S3 -> 0
F5: =B5*E5+C5*E5+D5*E5 -> 0 | H5: 45595 | I5: Захаров | J5: 103 | M5: 3.1 | N5: =J5*M5+K5*M5+L5*M5 -> 319.3
F6: =B6*E6+C6*E6+D6*E6 -> 0 | H6: 45596 | I6: Захаров | J6: 17 | M6: 3.1 | N6: =J6*M6+K6*M6+L6*M6 -> 52.7
F7: =B7*E7+C7*E7+D7*E7 -> 0 | H7: 45598 | I7: Захаров | J7: 44 | M7: 3.1 | N7: =J7*M7+K7*M7+L7*M7 -> 136.4
F8: =B8*E8+C8*E8+D8*E8 -> 0 | H8: 45601 | I8: Захаров | J8: 154 | M8: 3.1 | N8: =J8*M8+K8*M8+L8*M8 -> 477.4
F9: =B9*E9+C9*E9+D9*E9 -> 0 | H9: 45602 | I9: Захаров | J9: 86 | M9: 3.1 | N9: =J9*M9+K9*M9+L9*M9 -> 266.6
A10: 45603 | C10: 500 | E10: 4.25 | F10: =B10*E10+C10*E10+D10*E10 -> 2125 | H10: 45603 | I10: Захаров | K10: 151 | M10: 4.25 | N10: =J10*M10+K10*M10+L10*M10 -> 641.75
D11: 2 | E11: 408.2 | F11: =B11*E11+C11*E11+D11*E11 -> 816.4 | I11: Захаров | L11: 1 | M11: 408.2 | N11: =J11*M11+K11*M11+L11*M11 -> 408.2
F12: =B12*E12+C12*E12+D12*E12 -> 0 | H12: 45607 | I12: Захаров | K12: 111 | N12: =J12*M12+K12*M12+L12*M12 -> 0
F13: =B13*E13+C13*E13+D13*E13 -> 0 | L13: 1 | M13: 408.2 | N13: =J13*M13+K13*M13+L13*M13 -> 408.2
F14: =B14*E14+C14*E14+D14*E14 -> 0 | H14: 2025 год | N14: =J14*M14+K14*M14+L14*M14 -> 0
F15: =B15*E15+C15*E15+D15*E15 -> 0 | H15: 45741 | I15: Захаров | K15: 238 | M15: 4.25 | N15: =J15*M15+K15*M15+L15*M15 -> 1011.5
F16: =B16*E16+C16*E16+D16*E16 -> 0 | N16: =J16*M16+K16*M16+L16*M16 -> 0
F17: =B17*E17+C17*E17+D17*E17 -> 0 | N17: =J17*M17+K17*M17+L17*M17 -> 0
F18: =B18*E18+C18*E18+D18*E18 -> 0 | N18: =J18*M18+K18*M18+L18*M18 -> 0
F19: =B19*E19+C19*E19+D19*E19 -> 0 | N19: =J19*M19+K19*M19+L19*M19 -> 0
B20: =SUM(B3:B19) -> 800 | C20: =SUM(C3:C19) -> 500 | D20: =SUM(D3:D19) -> 2 | J20: =SUM(J3:J19) -> 800 | K20: =SUM(K3:K19) -> 500 | L20: =SUM(L3:L19) -> 2

Sheet Концепт
A1: дата поставки | B1: термотрансф пленка | C1: цена | D1: на сумму | F1: дата выдачи на пр-во | G1: в чей подотчет | H1: термотрансф пленка | I1: цена | J1: на сумму | M1: термотрансф пленка
A2: 2024 год | F2: 2024 год | M2: =0+B20-H20 -> 0
A3: 45582 | B3: 5 | C3: 145 | D3: =B3*C3 -> 725 | J3: =H3*I3 -> 0 | M3: 145
F4: 45652 | G4: Захаров | H4: 1 | I4: 725 | J4: =H4*I4 -> 725 | M4: =M2*M3 -> 0
A5: 2025 год | J5: =H5*I5 -> 0
F6: 45685 | G6: Захаров | H6: 4 | I6: 725 | J6: =H6*I6 -> 2900
J7: =H7*I7 -> 0
J8: =H8*I8 -> 0
J9: =H9*I9 -> 0
J10: =H10*I10 -> 0
J11: =H11*I11 -> 0
J12: =H12*I12 -> 0
J13: =H13*I13 -> 0
J14: =H14*I14 -> 0
J15: =H15*I15 -> 0
J16: =H16*I16 -> 0
J17: =H17*I17 -> 0
J18: =H18*I18 -> 0
J19: =H19*I19 -> 0
B20: =SUM(B3:B19) -> 5 | H20: =SUM(H3:H19) -> 5

Sheet ЛейблСтик
A1: дата поставки | C1: этикетка 100*80 | D1: этикетка 58*80 | F1: цена | G1: на сумму | I1: дата выдачи на пр-во | J1: в чей подотчет | K1: этикетка 100*80 | L1: этикетка 58*80 | N1: цена | O1: на сумму | R1: этикетка 100*80 | S1: этикетка 58*80
A2: 2024 год | I2: 2024 год | R2: =0+C20-K20 -> 0 | S2: =0+D20-L20 -> 0
A3: 45582 | B3: 10 | C3: 300 | F3: 5.83333 | G3: =C3*F3+D3*F3+E3*F3 -> 1749.999 | O3: =K3*N3 -> 0 | R3: 5.83333 | S3: 3.41435
B4: 10 | D4: 700 | F4: 3.41435 | G4: =C4*F4+D4*F4+E4*F4 -> 2390.045 | O4: =K4*N4 -> 0 | R4: =R2*R3 -> 0 | S4: =S2*S3 -> 0
I5: 45629 | J5: Захаров | K5: 150 | N5: 5.83 | O5: =K5*N5+L5*N5+M5*N5 -> 874.5
J6: Захаров | L6: 500 | N6: 3.41 | O6: =K6*N6+L6*N6+M6*N6 -> 1705
I7: 45630 | J7: Захаров | L7: 18 | N7: 3.41435 | O7: =K7*N7+L7*N7+M7*N7 -> 61.4583
I8: 2025 год | O8: =K8*N8+L8*N8+M8*N8 -> 0
I9: 45744 | K9: 150 | N9: 5.83 | O9: =K9*N9+L9*N9+M9*N9 -> 874.5
L10: 182 | N10: 3.41 | O10: =K10*N10+L10*N10+M10*N10 -> 620.62
O11: =K11*N11+L11*N11+M11*N11 -> 0
O12: =K12*N12+L12*N12+M12*N12 -> 0
O13: =K13*N13+L13*N13+M13*N13 -> 0
O14: =K14*N14+L14*N14+M14*N14 -> 0
O15: =K15*N15+L15*N15+M15*N15 -> 0
O16: =K16*N16+L16*N16+M16*N16 -> 0
O17: =K17*N17+L17*N17+M17*N17 -> 0
O18: =K18*N18+L18*N18+M18*N18 -> 0
O19: =K19*N19+L19*N19+M19*N19 -> 0
C20: =SUM(C3:C19) -> 300 | D20: =SUM(D3:D19) -> 700 | K20: =SUM(K3:K19) -> 300 | L20: =SUM(L3:L19) -> 700

Sheet ТД-Л Пак
A1: дата поставки | B1: гофроящик Н=1648 бп | C1: Гофроящик Н=1703 б/п (для ЯндексЛ) | D1: Гофроящик Кедровый бор (Монетка) | E1: Гофроящик h=1677 (Лента) | F1: пленка для палет | G1: цена | H1: на сумму | J1: дата выдачи на пр-во | K1: гофроящик Н=1648 бп | L1: Гофроящик Н=1703 б/п (для ЯндексЛ) | M1: Гофроящик Кедровый бор (Монетка) | N1: Гофроящик h=1677 (Лента) | O1: пленка для палет | P1: цена | Q1: на сумму | S1: гофроящик Н=1648 бп | T1: Гофроящик Н=1703 б/п (для ЯндексЛ) | U1: Гофроящик Кедровый бор (Монетка) | V1: Гофроящик h=1677 (Лента) | W1: пленка для палет Приопак
A2: 2024 год | J2: 2024 год | S2: =0+B103-K103 -> 4200 | T2: =0+C103-L103 -> 0 | U2: =0+D103-M103 -> 1300 | V2: =0+E103-N103 -> 932 | W2: =0+F103-O103 -> 54
A3: 45569 | B3: 6000 | G3: 24.996 | H3: =B3*G3+C3*G3+D3*G3+E3*G3+F3*G3 -> 149976 | S3: 24.996 | T3: 13.788 | U3: 25.776 | V3: 24.744 | W3: 432.82
H4: =B4*G4+C4*G4+D4*G4+E4*G4+F4*G4 -> 0 | J4: 45573 | K4: 114 | P4: 25 | Q4: =K4*P4+L4*P4+O4*P4+M4*P4+N4*P4 -> 2850 | S4: =S2*S3 -> 104983.2 | T4: =T2*T3 -> 0 | U4: =U2*U3 -> 33508.8 | V4: =V2*V3 -> 23061.408 | W4: =W2*W3 -> 23372.28
H5: =B5*G5+C5*G5+D5*G5+E5*G5+F5*G5 -> 0 | J5: 45587 | K5: 282 | P5: 25 | Q5: =K5*P5+L5*P5+O5*P5+M5*P5+N5*P5 -> 7050
H6: =B6*G6+C6*G6+D6*G6+E6*G6+F6*G6 -> 0 | J6: 45595 | K6: 103 | P6: 25 | Q6: =K6*P6+L6*P6+O6*P6+M6*P6+N6*P6 -> 2575
H7: =B7*G7+C7*G7+D7*G7+E7*G7+F7*G7 -> 0 | J7: 45596 | K7: 17 | P7: 25 | Q7: =K7*P7+L7*P7+O7*P7+M7*P7+N7*P7 -> 425
H8: =B8*G8+C8*G8+D8*G8+E8*G8+F8*G8 -> 0 | J8: 45598 | K8: 44 | P8: 25 | Q8: =K8*P8+L8*P8+O8*P8+M8*P8+N8*P8 -> 1100
H9: =B9*G9+C9*G9+D9*G9+E9*G9+F9*G9 -> 0 | J9: 45601 | K9: 154 | P9: 25 | Q9: =K9*P9+L9*P9+O9*P9+M9*P9+N9*P9 -> 3850
H10: =B10*G10+C10*G10+D10*G10+E10*G10+F10*G10 -> 0 | J10: 45602 | K10: 154 | P10: 25 | Q10: =K10*P10+L10*P10+O10*P10+M10*P10+N10*P10 -> 3850
H11: =B11*G11+C11*G11+D11*G11+E11*G11+F11*G11 -> 0 | J11: 45603 | K11: 151 | P11: 25 | Q11: =K11*P11+L11*P11+O11*P11+M11*P11+N11*P11 -> 3775
H12: =B12*G12+C12*G12+D12*G12+E12*G12+F12*G12 -> 0 | J12: 45604 | K12: 151 | P12: 25 | Q12: =K12*P12+L12*P12+O12*P12+M12*P12+N12*P12 -> 3775
H13: =B13*G13+C13*G13+D13*G13+E13*G13+F13*G13 -> 0 | J13: 45607 | K13: 111 | P13: 25 | Q13: =K13*P13+L13*P13+O13*P13+M13*P13+N13*P13 -> 2775
H14: =B14*G14+C14*G14+D14*G14+E14*G14+F14*G14 -> 0 | J14: 45610 | K14: 7 | P14: 25 | Q14: =K14*P14+L14*P14+O14*P14+M14*P14+N14*P14 -> 175
H15: =B15*G15+C15*G15+D15*G15+E15*G15+F15*G15 -> 0 | J15: 45621 | K15: 42 | P15: 25 | Q15: =K15*P15+L15*P15+O15*P15+M15*P15+N15*P15 -> 1050
H16: =B16*G16+C16*G16+D16*G16+E16*G16+F16*G16 -> 0 | J16: 45622 | K16: 44 | P16: 25 | Q16: =K16*P16+L16*P16+O16*P16+M16*P16+N16*P16 -> 1100
... H28: =B28*G28+C28*G28+D28*G28+E28*G28+F28*G28 -> 0 | J28: 45652 | K28: 156 | P28: 25 | Q28: =K28*P28+L28*P28+O28*P28+M28*P28+N28*P28 -> 3900
H29: =B29*G29+C29*G29+D29*G29+E29*G29+F29*G29 -> 0 | Q29: =K29*P29+L29*P29+O29*P29+M29*P29+N29*P29 -> 0
H30: =B30*G30+C30*G30+D30*G30+E30*G30+F30*G30 -> 0 | J30: 45666 | K30: 38 | P30: 25 | Q30: =K30*P30+L30*P30+O30*P30+M30*P30+N30*P30 -> 950
H31: =B31*G31+C31*G31+D31*G31+E31*G31+F31*G31 -> 0 | J31: 45667 | K31: 37 | P31: 25 | Q31: =K31*P31+L31*P31+O31*P31+M31*P31+N31*P31 -> 925
H32: =B32*G32+C32*G32+D32*G32+E32*G32+F32*G32 -> 0 | J32: 45670 | K32: 56 | P32: 25 | Q32: =K32*P32+L32*P32+O32*P32+M32*P32+N32*P32 -> 1400
H33: =B33*G33+C33*G33+D33*G33+E33*G33+F33*G33 -> 0 | J33: 45671 | K33: 126 | P33: 25 | Q33: =K33*P33+L33*P33+O33*P33+M33*P33+N33*P33 -> 3150
H34: =B34*G34+C34*G34+D34*G34+E34*G34+F34*G34 -> 0 | J34: 45672 | K34: 34 | P34: 25 | Q34: =K34*P34+L34*P34+O34*P34+M34*P34+N34*P34 -> 850
H35: =B35*G35+C35*G35+D35*G35+E35*G35+F35*G35 -> 0 | J35: 45673 | K35: 31 | P35: 25 | Q35: =K35*P35+L35*P35+O35*P35+M35*P35+N35*P35 -> 775
H36: =B36*G36+C36*G36+D36*G36+E36*G36+F36*G36 -> 0 | J36: 45674 | K36: 110 | P36: 25 | Q36: =K36*P36+L36*P36+O36*P36+M36*P36+N36*P36 -> 2750
H37: =B37*G37+C37*G37+D37*G37+E37*G37+F37*G37 -> 0 | J37: 45680 | K37: 58 | P37: 25 | Q37: =K37*P37+L37*P37+O37*P37+M37*P37+N37*P37 -> 1450
H38: =B38*G38+C38*G38+D38*G38+E38*G38+F38*G38 -> 0 | J38: 45681 | K38: 18 | P38: 25 | Q38: =K38*P38+L38*P38+O38*P38+M38*P38+N38*P38 -> 450
H39: =B39*G39+C39*G39+D39*G39+E39*G39+F39*G39 -> 0 | J39: 45684 | K39: 17 | P39: 25 | Q39: =K39*P39+L39*P39+O39*P39+M39*P39+N39*P39 -> 425
H40: =B40*G40+C40*G40+D40*G40+E40*G40+F40*G40 -> 0 | J40: 45685 | K40: 33 | P40: 25 | Q40: =K40*P40+L40*P40+O40*P40+M40*P40+N40*P40 -> 825
A41: 45686 | C41: 3800 | G41: 13.788 | H41: =B41*G41+C41*G41+D41*G41+E41*G41+F41*G41 -> 52394.4 | J41: 45686 | K41: 58 | P41: 25 | Q41: =K41*P41+L41*P41+O41*P41+M41*P41+N41*P41 -> 1450
H42: =B42*G42+C42*G42+D42*G42+E42*G42+F42*G42 -> 0 | J42: 45687 | L42: 128 | P42: 13.788 | Q42: =K42*P42+L42*P42+O42*P42+M42*P42+N42*P42 -> 1764.864
H43: =B43*G43+C43*G43+D43*G43+E43*G43+F43*G43 -> 0 | J43: 45688 | L43: 374 | P43: 13.788 | Q43: =K43*P43+L43*P43+O43*P43+M43*P43+N43*P43 -> 5156.712
H44: =B44*G44+C44*G44+D44*G44+E44*G44+F44*G44 -> 0 | K44: 2 | P44: 25 | Q44: =K44*P44+L44*P44+O44*P44+M44*P44+N44*P44 -> 50
H45: =B45*G45+C45*G45+D45*G45+E45*G45+F45*G45 -> 0 | J45: 45691 | L45: 200 | P45: 13.788 | Q45: =K45*P45+L45*P45+O45*P45+M45*P45+N45*P45 -> 2757.6
H46: =B46*G46+C46*G46+D46*G46+E46*G46+F46*G46 -> 0 | K46: 2 | P46: 25 | Q46: =K46*P46+L46*P46+O46*P46+M46*P46+N46*P46 -> 50
H47: =B47*G47+C47*G47+D47*G47+E47*G47+F47*G47 -> 0 | J47: 45692 | L47: 575 | P47: 13.788 | Q47: =K47*P47+L47*P47+O47*P47+M47*P47+N47*P47 -> 7928.1
H48: =B48*G48+C48*G48+D48*G48+E48*G48+F48*G48 -> 0 | K48: 44 | P48: 25 | Q48: =K48*P48+L48*P48+O48*P48+M48*P48+N48*P48 -> 1100
H49: =B49*G49+C49*G49+D49*G49+E49*G49+F49*G49 -> 0 | J49: 45693 | L49: 726 | P49: 13.788 | Q49: =K49*P49+L49*P49+O49*P49+M49*P49+N49*P49 -> 10010.088
H50: =B50*G50+C50*G50+D50*G50+E50*G50+F50*G50 -> 0 | J50: 45694 | K50: 71 | P50: 25 | Q50: =K50*P50+L50*P50+O50*P50+M50*P50+N50*P50 -> 1775
H51: =B51*G51+C51*G51+D51*G51+E51*G51+F51*G51 -> 0 | J51: 45695 | L51: 840 | P51: 13.788 | Q51: =K51*P51+L51*P51+O51*P51+M51*P51+N51*P51 -> 11581.92
...

Sheet Ника
A1: дата поставки | B1: лоток 4 секции | C1: цена | D1: на сумму | F1: дата выдачи на пр-во | G1: лоток 4 секции | H1: цена | I1: на сумму | L1: лоток 4 секции
A2: 2024 год | F2: 2024 год | L2: =0+B29-G29 -> 4607
A3: 45526 | B3: 6000 | C3: 5 | D3: =B3*C3 -> 30000 | L3: 5
F4: 45545 | G4: 88 | H4: 5 | I4: =G4*H4 -> 440 | L4: =L2*L3 -> 23035
F5: 45551 | G5: 20 | H5: 5 | I5: =G5*H5 -> 100
F6: 45561 | G6: 120 | H6: 5 | I6: =G6*H6 -> 600
F7: 45610 | G7: 11 | H7: 5 | I7: =G7*H7 -> 55
F8: 45617 | G8: 2 | H8: 5 | I8: =G8*H8 -> 10
F9: 45618 | G9: 3 | H9: 5 | I9: =G9*H9 -> 15
F10: 45624 | G10: 9 | H10: 5 | I10: =G10*H10 -> 45
F11: 45651 | G11: 20 | H11: 5 | I11: =G11*H11 -> 100
F12: 45652 | G12: 120 | H12: 5 | I12: =G12*H12 -> 600
F13: 2025 год | I13: =G13*H13 -> 0
F14: 45775 | G14: 1000 | H14: 5 | I14: =G14*H14 -> 5000
I15: =G15*H15 -> 0
I16: =G16*H16 -> 0
I17: =G17*H17 -> 0
I18: =G18*H18 -> 0
I19: =G19*H19 -> 0
I20: =G20*H20 -> 0
I21: =G21*H21 -> 0
I22: =G22*H22 -> 0
I23: =G23*H23 -> 0
I24: =G24*H24 -> 0
I25: =G25*H25 -> 0
I26: =G26*H26 -> 0
... I28: =G28*H28 -> 0
B29: =SUM(B3:B28) -> 6000 | G29: =SUM(G3:G28) -> 1393

Sheet СЗ-Гофра
A1: дата поставки | B1: короб "Ласточкин хвост" | C1: цена | D1: на сумму | F1: дата выдачи на пр-во | G1: в чей подотчет | H1: короб "Ласточкин хвост" | I1: цена | J1: на сумму | M1: короб "Ласточкин хвост"
A2: 2024 год | F2: 2024 год | M2: =0+B20-H20 -> 17435
A3: 45531 | B3: 17435 | C3: 17.4 | D3: =B3*C3 -> 303369 | M3: 17.4
M4: =M2*M3 -> 303369
B20: =SUM(B3:B19) -> 17435 | H20: =SUM(H3:H19) -> 0

Sheet УпакАреал
A1: дата поставки | B1: Пленка Арахисовая тарелка ЧИПЛС 4 вкуса 200 г | C1: Пленка Арахисовая тарелка Smakky Asian Mix 200 г | D1: Пленка Арахисовая тарелка Smakky Classic Mix 200г | I1: цена | J1: на сумму | L1: дата выдачи на пр-во | M1: Пленка Арахисовая тарелка ЧИПЛС 4 вкуса 200 г | N1: Пленка Арахисовая тарелка Smakky Asian Mix 200 г | O1: Пленка Арахисовая тарелка Smakky Classic Mix 200г | P1: Пленка для упаковки арахиса КВАДРОМИКС "Тарелка" 240*315 | T1: цена | U1: на сумму | X1: Пленка Арахисовая тарелка ЧИПЛС 4 вкуса 200 г | Y1: Пленка Арахисовая тарелка Smakky Asian Mix 200 г | Z1: Пленка Арахисовая тарелка Smakky Classic Mix 200г
A2: 2025 год | L2: 2025 год | X2: =0+B39-M39 -> 574.35 | Y2: =0+C39-N39 -> 245.41 | Z2: =0+D39-O39 -> 261.44 | AA2: =0+E39-P39 -> -63.66 | AB2: =0+F39-Q39 -> 0 | AC2: =0+G39-R39 -> 0 | AD2: =0+H39-S39 -> 0
A3: 45715 | B3: 995.54 | I3: 715 | J3: =B3*I3+C3*I3+D3*I3+E3*I3+F3*I3+G3*I3+H3*I3 -> 711811.1 | U3: =M3*T3+N3*T3+O3*T3+P3*T3+Q3*T3+R3*T3+S3*T3 -> 0 | X3: 715 | Y3: 850 | Z3: 850
C4: 363.24 | I4: 850 | J4: =B4*I4+C4*I4+D4*I4+E4*I4+F4*I4+G4*I4+H4*I4 -> 308754 | U4: =M4*T4+N4*T4+O4*T4+P4*T4+Q4*T4+R4*T4+S4*T4 -> 0 | X4: =X2*X3 -> 410660.25 | Y4: =Y2*Y3 -> 208598.5 | Z4: =Z2*Z3 -> 222224 | AA4: =AA2*AA3 -> 0 | AB4: =AB2*AB3 -> 0 | AC4: =AC2*AC3 -> 0 | AD4: =AD2*AD3 -> 0
D5: 374.12 | I5: 850 | J5: =B5*I5+C5*I5+D5*I5+E5*I5+F5*I5+G5*I5+H5*I5 -> 318002 | U5: =M5*T5+N5*T5+O5*T5+P5*T5+Q5*T5+R5*T5+S5*T5 -> 0
J6: =B6*I6+C6*I6+D6*I6+E6*I6+F6*I6+G6*I6+H6*I6 -> 0 | L6: 45719 | M6: 33.2 | T6: 715 | U6: =M6*T6+N6*T6+O6*T6+P6*T6+Q6*T6+R6*T6+S6*T6 -> 23738
J7: =B7*I7+C7*I7+D7*I7+E7*I7+F7*I7+G7*I7+H7*I7 -> 0 | L7: 45726 | M7: 16.7 | T7: 715 | U7: =M7*T7+N7*T7+O7*T7+P7*T7+Q7*T7+R7*T7+S7*T7 -> 11940.5
J8: =B8*I8+C8*I8+D8*I8+E8*I8+F8*I8+G8*I8+H8*I8 -> 0 | L8: 45727 | M8: 15.34 | T8: 715 | U8: =M8*T8+N8*T8+O8*T8+P8*T8+Q8*T8+R8*T8+S8*T8 -> 10968.1
J9: =B9*I9+C9*I9+D9*I9+E9*I9+F9*I9+G9*I9+H9*I9 -> 0 | L9: 45729 | M9: 15.46 | T9: 715 | U9: =M9*T9+N9*T9+O9*T9+P9*T9+Q9*T9+R9*T9+S9*T9 -> 11053.9
J10: =B10*I10+C10*I10+D10*I10+E10*I10+F10*I10+G10*I10+H10*I10 -> 0 | L10: 45730 | M10: 12.72 | T10: 715 | U10: =M10*T10+N10*T10+O10*T10+P10*T10+Q10*T10+R10*T10+S10*T10 -> 9094.8
J11: =B11*I11+C11*I11+D11*I11+E11*I11+F11*I11+G11*I11+H11*I11 -> 0 | L11: 45733 | M11: 16.66 | T11: 715 | U11: =M11*T11+N11*T11+O11*T11+P11*T11+Q11*T11+R11*T11+S11*T11 -> 11911.9
J12: =B12*I12+C12*I12+D12*I12+E12*I12+F12*I12+G12*I12+H12*I12 -> 0 | L12: 45734 | M12: 12.72 | T12: 715 | U12: =M12*T12+N12*T12+O12*T12+P12*T12+Q12*T12+R12*T12+S12*T12 -> 9094.8
J13: =B13*I13+C13*I13+D13*I13+E13*I13+F13*I13+G13*I13+H13*I13 -> 0 | L13: 45736 | M13: 31.38 | T13: 715 | U13: =M13*T13+N13*T13+O13*T13+P13*T13+Q13*T13+R13*T13+S13*T13 -> 22436.7
J14: =B14*I14+C14*I14+D14*I14+E14*I14+F14*I14+G14*I14+H14*I14 -> 0 | L14: 45737 | M14: 30.7 | T14: 715 | U14: =M14*T14+N14*T14+O14*T14+P14*T14+Q14*T14+R14*T14+S14*T14 -> 21950.5
J15: =B15*I15+C15*I15+D15*I15+E15*I15+F15*I15+G15*I15+H15*I15 -> 0 | L15: 45740 | M15: 45.2 | T15: 715 | U15: =M15*T15+N15*T15+O15*T15+P15*T15+Q15*T15+R15*T15+S15*T15 -> 32318
J16: =B16*I16+C16*I16+D16*I16+E16*I16+F16*I16+G16*I16+H16*I16 -> 0 | L16: 45747 | M16: 32.16 | T16: 715 | U16: =M16*T16+N16*T16+O16*T16+P16*T16+Q16*T16+R16*T16+S16*T16 -> 22994.4
J17: =B17*I17+C17*I17+D17*I17+E17*I17+F17*I17+G17*I17+H17*I17 -> 0 | L17: апрель | U17: =M17*T17+N17*T17+O17*T17+P17*T17+Q17*T17+R17*T17+S17*T17 -> 0
J18: =B18*I18+C18*I18+D18*I18+E18*I18+F18*I18+G18*I18+H18*I18 -> 0 | L18: 45750 | M18: 16.02 | T18: 715 | U18: =M18*T18+N18*T18+O18*T18+P18*T18+Q18*T18+R18*T18+S18*T18 -> 11454.3
J19: =B19*I19+C19*I19+D19*I19+E19*I19+F19*I19+G19*I19+H19*I19 -> 0 | L19: 45751 | M19: 16.28 | T19: 715 | U19: =M19*T19+N19*T19+O19*T19+P19*T19+Q19*T19+R19*T19+S19*T19 -> 11640.2
J20: =B20*I20+C20*I20+D20*I20+E20*I20+F20*I20+G20*I20+H20*I20 -> 0 | L20: 45754 | M20: 16.18 | T20: 715 | U20: =M20*T20+N20*T20+O20*T20+P20*T20+Q20*T20+R20*T20+S20*T20 -> 11568.7
J21: =B21*I21+C21*I21+D21*I21+E21*I21+F21*I21+G21*I21+H21*I21 -> 0 | L21: 45755 | M21: 4.86 | T21: 715 | U21: =M21*T21+N21*T21+O21*T21+P21*T21+Q21*T21+R21*T21+S21*T21 -> 3474.9
J22: =B22*I22+C22*I22+D22*I22+E22*I22+F22*I22+G22*I22+H22*I22 -> 0 | L22: 45756 | M22: 4.86 | T22: 715 | U22: =M22*T22+N22*T22+O22*T22+P22*T22+Q22*T22+R22*T22+S22*T22 -> 3474.9
J23: =B23*I23+C23*I23+D23*I23+E23*I23+F23*I23+G23*I23+H23*I23 -> 0 | L23: 45757 | M23: 16.08 | T23: 715 | U23: =M23*T23+N23*T23+O23*T23+P23*T23+Q23*T23+R23*T23+S23*T23 -> 11497.2
J24: =B24*I24+C24*I24+D24*I24+E24*I24+F24*I24+G24*I24+H24*I24 -> 0 | L24: 45765 | M24: 48.61 | T24: 715 | U24: =M24*T24+N24*T24+O24*T24+P24*T24+Q24*T24+R24*T24+S24*T24 -> 34756.15
J25: =B25*I25+C25*I25+D25*I25+E25*I25+F25*I25+G25*I25+H25*I25 -> 0 | L25: 45769 | M25: 3.66 | T25: 715 | U25: =M25*T25+N25*T25+O25*T25+P25*T25+Q25*T25+R25*T25+S25*T25 -> 2616.9
J26: =B26*I26+C26*I26+D26*I26+E26*I26+F26*I26+G26*I26+H26*I26 -> 0 | L26: 45775 | M26: 16.2 | T26: 715 | U26: =M26*T26+N26*T26+O26*T26+P26*T26+Q26*T26+R26*T26+S26*T26 -> 11583
A27: май | L27: май
J28: =B28*I28+C28*I28+D28*I28+E28*I28+F28*I28+G28*I28+H28*I28 -> 0 | L28: 01-04 мая | N28: 88.6 | T28: 850 | U28: =M28*T28+N28*T28+O28*T28+P28*T28+Q28*T28+R28*T28+S28*T28 -> 75310
J29: =B29*I29+C29*I29+D29*I29+E29*I29+F29*I29+G29*I29+H29*I29 -> 0 | O29: 48.76 | T29: 850 | U29: =M29*T29+N29*T29+O29*T29+P29*T29+Q29*T29+R29*T29+S29*T29 -> 41446
J30: =B30*I30+C30*I30+D30*I30+E30*I30+F30*I30+G30*I30+H30*I30 -> 0 | L30: 14 мая | M30: 16.2 | T30: 715 | U30: =M30*T30+N30*T30+O30*T30+P30*T30+Q30*T30+R30*T30+S30*T30 -> 11583
J31: =B31*I31+C31*I31+D31*I31+E31*I31+F31*I31+G31*I31+H31*I31 -> 0 | N31: 9.24 | T31: 850 | U31: =M31*T31+N31*T31+O31*T31+P31*T31+Q31*T31+R31*T31+S31*T31 -> 7854
J32: =B32*I32+C32*I32+D32*I32+E32*I32+F32*I32+G32*I32+H32*I32 -> 0 | O32: 63.92 | T32: 850 | U32: =M32*T32+N32*T32+O32*T32+P32*T32+Q32*T32+R32*T32+S32*T32 -> 54332
J33: =B33*I33+C33*I33+D33*I33+E33*I33+F33*I33+G33*I33+H33*I33 -> 0 | L33: 15 мая | N33: 10.79 | T33: 850 | U33: =M33*T33+N33*T33+O33*T33+P33*T33+Q33*T33+R33*T33+S33*T33 -> 9171.5
J34: =B34*I34+C34*I34+D34*I34+E34*I34+F34*I34+G34*I34+H34*I34 -> 0 | L34: 16 мая | N34: 9.2 | T34: 850 | U34: =M34*T34+N34*T34+O34*T34+P34*T34+Q34*T34+R34*T34+S34*T34 -> 7820
J35: =B35*I35+C35*I35+D35*I35+E35*I35+F35*I35+G35*I35+H35*I35 -> 0 | L35: 22 мая | P35: 23.68 | T35: 741 | U35: =M35*T35+N35*T35+O35*T35+P35*T35+Q35*T35+R35*T35+S35*T35 -> 17546.88
L36: 24 мая | P36: 39.98 | T36: 741 | U36: =M36*T36+N36*T36+O36*T36+P36*T36+Q36*T36+R36*T36+S36*T36 -> 29625.18
U37: =M37*T37+N37*T37+O37*T37+P37*T37+Q37*T37+R37*T37+S37*T37 -> 0
J38: =B38*I38+C38*I38+D38*I38+E38*I38+F38*I38+G38*I38+H38*I38 -> 0 | U38: =M38*T38+N38*T38+O38*T38+P38*T38+Q38*T38+R38*T38+S38*T38 -> 0
B39: =SUM(B3:B38) -> 995.54 | C39: =SUM(C3:C38) -> 363.24 | D39: =SUM(D3:D38) -> 374.12 | E39: =SUM(E3:E38) -> 0 | F39: =SUM(F3:F38) -> 0 | G39: =SUM(G3:G38) -> 0 | H39: =SUM(H3:H38) -> 0 | M39: =SUM(M3:M38) -> 421.19 | N39: =SUM(N3:N38) -> 117.83 | O39: =SUM(O3:O38) -> 112.68 | P39: =SUM(P3:P38) -> 63.66 | Q39: =SUM(Q3:Q38) -> 0 | R39: =SUM(R3:R38) -> 0 | S39: =SUM(S3:S38) -> 0

Sheet РусУпак
A1: дата поставки | B1: ПЛЕНКА без печати ВОРР ширина 310 ЯндексЛ | C1: ПЛЕНКА без печати ВОРР ширина 430 | I1: цена | J1: на сумму | L1: дата выдачи на пр-во | M1: ПЛЕНКА без печати ВОРР ширина 310 ЯндексЛ | N1: ПЛЕНКА без печати ВОРР ширина 430 | T1: цена | U1: на сумму | X1: Пленка Арахисовая тарелка ЧИПЛС 4 вкуса 200 г | Y1: Пленка Арахисовая тарелка Smakky Asian Mix 200 г | Z1: Пленка Арахисовая тарелка Smakky Classic Mix 200г
A2: 2025 год | L2: 2025 год | X2: =0+B36-M36 -> 139.2 | Y2: =0+C36-N36 -> 166 | Z2: =0+D36-O36 -> 0 | AA2: =0+E36-P36 -> 0 | AB2: =0+F36-Q36 -> 0 | AC2: =0+G36-R36 -> 0 | AD2: =0+H36-S36 -> 0
A3: 45726 | B3: 284.55 | I3: 290 | J3: =B3*I3+C3*I3+D3*I3+E3*I3+F3*I3+G3*I3+H3*I3 -> 82519.5 | L3: 45726 | M3: 15.05 | T3: 290 | U3: =M3*T3+N3*T3+O3*T3+P3*T3+Q3*T3+R3*T3+S3*T3 -> 4364.5 | X3: 290 | Y3: 280
J4: =B4*I4+C4*I4+D4*I4+E4*I4+F4*I4+G4*I4+H4*I4 -> 0 | L4: 45728 | M4: 14.55 | T4: 290 | U4: =M4*T4+N4*T4+O4*T4+P4*T4+Q4*T4+R4*T4+S4*T4 -> 4219.5 | X4: =X2*X3 -> 40368 | Y4: =Y2*Y3 -> 46480 | Z4: =Z2*Z3 -> 0 | AA4: =AA2*AA3 -> 0 | AB4: =AB2*AB3 -> 0 | AC4: =AC2*AC3 -> 0 | AD4: =AD2*AD3 -> 0
J5: =B5*I5+C5*I5+D5*I5+E5*I5+F5*I5+G5*I5+H5*I5 -> 0 | L5: 45729 | M5: 28.6 | T5: 290 | U5: =M5*T5+N5*T5+O5*T5+P5*T5+Q5*T5+R5*T5+S5*T5 -> 8294
J6: =B6*I6+C6*I6+D6*I6+E6*I6+F6*I6+G6*I6+H6*I6 -> 0 | L6: 45730 | M6: 14.55 | T6: 290 | U6: =M6*T6+N6*T6+O6*T6+P6*T6+Q6*T6+R6*T6+S6*T6 -> 4219.5
J7: =B7*I7+C7*I7+D7*I7+E7*I7+F7*I7+G7*I7+H7*I7 -> 0 | L7: 45735 | M7: 29.35 | T7: 290 | U7: =M7*T7+N7*T7+O7*T7+P7*T7+Q7*T7+R7*T7+S7*T7 -> 8511.5
J8: =B8*I8+C8*I8+D8*I8+E8*I8+F8*I8+G8*I8+H8*I8 -> 0 | L8: 45736 | M8: 28.65 | T8: 290 | U8: =M8*T8+N8*T8+O8*T8+P8*T8+Q8*T8+R8*T8+S8*T8 -> 8308.5
J9: =B9*I9+C9*I9+D9*I9+E9*I9+F9*I9+G9*I9+H9*I9 -> 0 | L9: 45737 | M9: 14.6 | T9: 290 | U9: =M9*T9+N9*T9+O9*T9+P9*T9+Q9*T9+R9*T9+S9*T9 -> 4234
A10: 45772 | C10: 180.9 | I10: 280 | J10: =B10*I10+C10*I10+D10*I10+E10*I10+F10*I10+G10*I10+H10*I10 -> 50652 | L10: 45777 | N10: 180.9 | T10: 280 | U10: =M10*T10+N10*T10+O10*T10+P10*T10+Q10*T10+R10*T10+S10*T10 -> 50652
J11: =B11*I11+C11*I11+D11*I11+E11*I11+F11*I11+G11*I11+H11*I11 -> 0 | U11: =M11*T11+N11*T11+O11*T11+P11*T11+Q11*T11+R11*T11+S11*T11 -> 0
A12: 14 мая | C12: 166 | I12: 280 | J12: =B12*I12+C12*I12+D12*I12+E12*I12+F12*I12+G12*I12+H12*I12 -> 46480 | U12: =M12*T12+N12*T12+O12*T12+P12*T12+Q12*T12+R12*T12+S12*T12 -> 0
J13: =B13*I13+C13*I13+D13*I13+E13*I13+F13*I13+G13*I13+H13*I13 -> 0 | U13: =M13*T13+N13*T13+O13*T13+P13*T13+Q13*T13+R13*T13+S13*T13 -> 0
J14: =B14*I14+C14*I14+D14*I14+E14*I14+F14*I14+G14*I14+H14*I14 -> 0 | U14: =M14*T14+N14*T14+O14*T14+P14*T14+Q14*T14+R14*T14+S14*T14 -> 0
J15: =B15*I15+C15*I15+D15*I15+E15*I15+F15*I15+G15*I15+H15*I15 -> 0 | U15: =M15*T15+N15*T15+O15*T15+P15*T15+Q15*T15+R15*T15+S15*T15 -> 0
J16: =B16*I16+C16*I16+D16*I16+E16*I16+F16*I16+G16*I16+H16*I16 -> 0 | U16: =M16*T16+N16*T16+O16*T16+P16*T16+Q16*T16+R16*T16+S16*T16 -> 0
J17: =B17*I17+C17*I17+D17*I17+E17*I17+F17*I17+G17*I17+H17*I17 -> 0 | U17: =M17*T17+N17*T17+O17*T17+P17*T17+Q17*T17+R17*T17+S17*T17 -> 0
J18: =B18*I18+C18*I18+D18*I18+E18*I18+F18*I18+G18*I18+H18*I18 -> 0 | U18: =M18*T18+N18*T18+O18*T18+P18*T18+Q18*T18+R18*T18+S18*T18 -> 0
J19: =B19*I19+C19*I19+D19*I19+E19*I19+F19*I19+G19*I19+H19*I19 -> 0 | U19: =M19*T19+N19*T19+O19*T19+P19*T19+Q19*T19+R19*T19+S19*T19 -> 0
J20: =B20*I20+C20*I20+D20*I20+E20*I20+F20*I20+G20*I20+H20*I20 -> 0 | U20: =M20*T20+N20*T20+O20*T20+P20*T20+Q20*T20+R20*T20+S20*T20 -> 0
J21: =B21*I21+C21*I21+D21*I21+E21*I21+F21*I21+G21*I21+H21*I21 -> 0 | U21: =M21*T21+N21*T21+O21*T21+P21*T21+Q21*T21+R21*T21+S21*T21 -> 0
J22: =B22*I22+C22*I22+D22*I22+E22*I22+F22*I22+G22*I22+H22*I22 -> 0 | U22: =M22*T22+N22*T22+O22*T22+P22*T22+Q22*T22+R22*T22+S22*T22 -> 0
J23: =B23*I23+C23*I23+D23*I23+E23*I23+F23*I23+G23*I23+H23*I23 -> 0 | U23: =M23*T23+N23*T23+O23*T23+P23*T23+Q23*T23+R23*T23+S23*T23 -> 0
J24: =B24*I24+C24*I24+D24*I24+E24*I24+F24*I24+G24*I24+H24*I24 -> 0 | U24: =M24*T24+N24*T24+O24*T24+P24*T24+Q24*T24+R24*T24+S24*T24 -> 0
... J35: =B35*I35+C35*I35+D35*I35+E35*I35+F35*I35+G35*I35+H35*I35 -> 0 | U35: =M35*T35+N35*T35+O35*T35+P35*T35+Q35*T35+R35*T35+S35*T35 -> 0
B36: =SUM(B3:B35) -> 284.55 | C36: =SUM(C3:C35) -> 346.9 | D36: =SUM(D3:D35) -> 0 | E36: =SUM(E3:E35) -> 0 | F36: =SUM(F3:F35) -> 0 | G36: =SUM(G3:G35) -> 0 | H36: =SUM(H3:H35) -> 0 | M36: =SUM(M3:M35) -> 145.35 | N36: =SUM(N3:N35) -> 180.9 | O36: =SUM(O3:O35) -> 0 | P36: =SUM(P3:P35) -> 0 | Q36: =SUM(Q3:Q35) -> 0 | R36: =SUM(R3:R35) -> 0 | S36: =SUM(S3:S35) -> 0

Sheet Пластик
A1: дата поставки | B1: Тарелки ТР-209/4 | E1: цена | F1: на сумму | H1: дата выдачи на пр-во | I1: Тарелки ТР-209/4 | L1: цена | M1: на сумму | P1: Тарелки ТР-209/4
A2: 2025 год | H2: 2025 год | P2: =0+B30-I30 -> 47400 | Q2: =0+C30-J30 -> 0
A3: 45740 | B3: 53760 | E3: 5.3 | F3: =B3*E3+C3*E3+D3*E3 -> 284928 | M3: =I3*L3+J3*L3+K3*L3 -> 0 | P3: 5.3
F4: =B4*E4+C4*E4+D4*E4 -> 0 | H4: 45741 | I4: 840 | L4: 5.3 | M4: =I4*L4+J4*L4+K4*L4 -> 4452 | P4: =P2*P3 -> 251220 | Q4: =Q2*Q3 -> 0
F5: =B5*E5+C5*E5+D5*E5 -> 0 | H5: 45742 | I5: 2520 | L5: 5.3 | M5: =I5*L5+J5*L5+K5*L5 -> 13356
F6: =B6*E6+C6*E6+D6*E6 -> 0 | H6: 45743 | I6: 5040 | L6: 5.3 | M6: =I6*L6+J6*L6+K6*L6 -> 26712
F7: =B7*E7+C7*E7+D7*E7 -> 0 | H7: 45744 | I7: 1680 | L7: 5.3 | M7: =I7*L7+J7*L7+K7*L7 -> 8904
F8: =B8*E8+C8*E8+D8*E8 -> 0 | H8: 45747 | I8: 4200 | L8: 5.3 | M8: =I8*L8+J8*L8+K8*L8 -> 22260
H9: апрель | M9: =I9*L9+J9*L9+K9*L9 -> 0
H10: 45749 | I10: 3360 | L10: 5.3 | M10: =I10*L10+J10*L10+K10*L10 -> 17808
H11: 45750 | I11: 5880 | L11: 5.3 | M11: =I11*L11+J11*L11+K11*L11 -> 31164
H12: 45751 | I12: 4200 | L12: 5.3 | M12: =I12*L12+J12*L12+K12*L12 -> 22260
H13: 45754 | I13: 3360 | L13: 5.3 | M13: =I13*L13+J13*L13+K13*L13 -> 17808
H14: 45755 | I14: 5880 | L14: 5.3 | M14: =I14*L14+J14*L14+K14*L14 -> 31164
H15: 45756 | I15: 3360 | L15: 5.3 | M15: =I15*L15+J15*L15+K15*L15 -> 17808
A16: 45757 | B16: 46200 | E16: 5.3 | F16: =B16*E16+C16*E16+D16*E16 -> 244860 | H16: 45757 | I16: 6720 | L16: 5.3 | M16: =I16*L16+J16*L16+K16*L16 -> 35616
F17: =B17*E17+C17*E17+D17*E17 -> 0 | H17: 11-14.04 | I17: 35760 | L17: 5.3 | M17: =I17*L17+J17*L17+K17*L17 -> 189528
F18: =B18*E18+C18*E18+D18*E18 -> 0 | H18: 45769 | I18: 13440 | L18: 5.3 | M18: =I18*L18+J18*L18+K18*L18 -> 71232
A19: 45772 | B19: 40320 | E19: 5.3 | F19: =B19*E19+C19*E19+D19*E19 -> 213696 | H19: 45772 | I19: 840 | L19: 5.3 | M19: =I19*L19+J19*L19+K19*L19 -> 4452
F20: =B20*E20+C20*E20+D20*E20 -> 0 | H20: 45775 | I20: 7560 | L20: 5.3 | M20: =I20*L20+J20*L20+K20*L20 -> 40068
F21: =B21*E21+C21*E21+D21*E21 -> 0 | H21: 45777 | I21: 10080 | L21: 5.3 | M21: =I21*L21+J21*L21+K21*L21 -> 53424
A22: 62160 | H22: май
A23: 16 мая | B23: 62160 | E23: 5.3 | F23: =B23*E23+C23*E23+D23*E23 -> 329448 | H23: 10-11 мая | I23: 6720 | L23: 5.3 | M23: =I23*L23+J23*L23+K23*L23 -> 35616
F24: =B24*E24+C24*E24+D24*E24 -> 0 | H24: 12 мая | I24: 6720 | L24: 5.3 | M24: =I24*L24+J24*L24+K24*L24 -> 35616
F25: =B25*E25+C25*E25+D25*E25 -> 0 | H25: 14 мая | I25: 13440 | L25: 5.3 | M25: =I25*L25+J25*L25+K25*L25 -> 71232
F26: =B26*E26+C26*E26+D26*E26 -> 0 | H26: 19 мая | I26: 13440 | L26: 5.3 | M26: =I26*L26+J26*L26+K26*L26 -> 71232
F27: =B27*E27+C27*E27+D27*E27 -> 0 | M27: =I27*L27+J27*L27+K27*L27 -> 0
F28: =B28*E28+C28*E28+D28*E28 -> 0 | M28: =I28*L28+J28*L28+K28*L28 -> 0
F29: =B29*E29+C29*E29+D29*E29 -> 0 | M29: =I29*L29+J29*L29+K29*L29 -> 0
B30: =SUM(B3:B29) -> 202440 | C30: =SUM(C3:C29) -> 0 | D30: =SUM(D3:D29) -> 0 | I30: =SUM(I3:I29) -> 155040 | J30: =SUM(J3:J29) -> 0 | K30: =SUM(K3:K29) -> 0

Sheet Приопак
A1: дата поставки | B1: Пакет ПНД 60*100 14 мк | C1: Пленка 500 мл 20 мк | D1: Пленка паллет 500 мм 17 мк 2,0 кг вторичная | E1: Пакет ПНД 45*27*60 14 мк | F1: Пакет ПНД 45*27*60 14 мк | G1: Плёнка для запайки 240 мм | H1: Мешок полипропиленовый 55*95 см серый | I1: цена | J1: на сумму | L1: дата выдачи на пр-во | M1: в чей подотчет | N1: Пакет ПНД 60*100 14 мк | O1: Пленка 500 мл 20 мк | P1: Пленка паллет 500 мм 17 мк 2,0 кг вторичная | Q1: Пакет ПНД 45*27*60 14 мк | R1: Пакет ПНД 45*27*60 14 мк | S1: Плёнка для запайки 240 мм | T1: Мешок полипропиленовый 55*95 см серый | U1: цена | V1: на сумму | Y1: Пакет ПНД 60*100 14 мк | Z1: Пленка 500 мл 20 мк | AA1: Пленка паллет 500 мм 17 мк 2,0 кг вторичная | AB1: Пакет ПНД 45*27*60 14 мк | AC1: Пакет ПНД 45*27*60 14 мк | AD1: Плёнка для запайки 240 мм | AE1: Мешок полипропиленовый 55*95 см серый
A2: 2024 год | L2: 2024 год | Y2: =0+B44-N44 -> 492 | Z2: =0+C44-O44 -> 0 | AA2: =0+D44-P44 -> 29 | AB2: =0+E44-Q44 -> 1580 | AC2: =0+F44-R44 -> 0 | AD2: =0+G44-S44 -> 3.65 | AE2: =0+H44-T44 -> 0
A3: 45603 | B3: 500 | I3: 4 | J3: =B3*I3+C3*I3+D3*I3+E3*I3+F3*I3+G3*I3+H3*I3 -> 2000 | V3: =N3*U3+O3*U3+P3*U3+Q3*U3+R3*U3+S3*U3+T3*U3 -> 0 | Y3: 4 | Z3: 446.12 | AA3: 441.6866 | AB3: 2.9 | AC3: 2.86 | AD3: 499.4 | AE3: 18
C4: 6 | I4: 320 | J4: =B4*I4+C4*I4+D4*I4+E4*I4+F4*I4+G4*I4+H4*I4 -> 1920 | V4: =N4*U4+O4*U4+P4*U4+Q4*U4+R4*U4+S4*U4+T4*U4 -> 0 | Y4: =Y2*Y3 -> 1968 | Z4: =Z2*Z3 -> 0 | AA4: =AA2*AA3 -> 12808.911 | AB4: =AB2*AB3 -> 4582 | AC4: =AC2*AC3 -> 0 | AD4: =AD2*AD3 -> 1822.81 | AE4: =AE2*AE3 -> 0
J5: =B5*I5+C5*I5+D5*I5+E5*I5+F5*I5+G5*I5+H5*I5 -> 0 | L5: 45609 | M5: Захаров | O5: 5 | U5: 320 | V5: =N5*U5+O5*U5+P5*U5+Q5*U5+R5*U5+S5*U5+T5*U5 -> 1600
A6: 45610 | D6: 12 | I6: 441.6866 | J6: =B6*I6+C6*I6+D6*I6+E6*I6+F6*I6+G6*I6+H6*I6 -> 5300.2392 | L6: 45610 | M6: Захаров | P6: 4 | U6: 441.6866 | V6: =N6*U6+O6*U6+P6*U6+Q6*U6+R6*U6+S6*U6+T6*U6 -> 1766.7464
A7: 45616 | E7: 1600 | I7: 2.9 | J7: =B7*I7+C7*I7+D7*I7+E7*I7+F7*I7+G7*I7+H7*I7 -> 4640 | M7: Захаров | O7: 1 | U7: 320 | V7: =N7*U7+O7*U7+P7*U7+Q7*U7+R7*U7+S7*U7+T7*U7 -> 320
F8: 1400 | I8: 2.86 | J8: =B8*I8+C8*I8+D8*I8+E8*I8+F8*I8+G8*I8+H8*I8 -> 4004 | L8: 45614 | M8: Захаров | N8: 8 | U8: 4 | V8: =N8*U8+O8*U8+P8*U8+Q8*U8+R8*U8+S8*U8+T8*U8 -> 32
G9: 6.65 | I9: 499.4 | J9: =B9*I9+C9*I9+D9*I9+E9*I9+F9*I9+G9*I9+H9*I9 -> 3321.01 | L9: 45618 | M9: Захаров | P9: 0.1 | U9: 441.69 | V9: =N9*U9+O9*U9+P9*U9+Q9*U9+R9*U9+S9*U9+T9*U9 -> 44.169
A10: 45639 | H10: 100 | I10: 18 | J10: =B10*I10+C10*I10+D10*I10+E10*I10+F10*I10+G10*I10+H10*I10 -> 1800 | V10: =N10*U10+O10*U10+P10*U10+Q10*U10+R10*U10+S10*U10+T10*U10 -> 0
J11: =B11*I11+C11*I11+D11*I11+E11*I11+F11*I11+G11*I11+H11*I11 -> 0 | L11: 45642 | M11: Захаров | T11: 50 | U11: 18 | V11: =N11*U11+O11*U11+P11*U11+Q11*U11+R11*U11+S11*U11+T11*U11 -> 900
J12: =B12*I12+C12*I12+D12*I12+E12*I12+F12*I12+G12*I12+H12*I12 -> 0 | L12: 2025 год | V12: =N12*U12+O12*U12+P12*U12+Q12*U12+R12*U12+S12*U12+T12*U12 -> 0
J13: =B13*I13+C13*I13+D13*I13+E13*I13+F13*I13+G13*I13+H13*I13 -> 0 | L13: 45672 | M13: Захаров | P13: 4 | U13: 441.69 | V13: =N13*U13+O13*U13+P13*U13+Q13*U13+R13*U13+S13*U13+T13*U13 -> 1766.76
J14: =B14*I14+C14*I14+D14*I14+E14*I14+F14*I14+G14*I14+H14*I14 -> 0 | M14: Захаров | S14: 3 | U14: 499.4 | V14: =N14*U14+O14*U14+P14*U14+Q14*U14+R14*U14+S14*U14+T14*U14 -> 1498.2
A15: 45681 | C15: 60 | I15: 446.12 | J15: =B15*I15+C15*I15+D15*I15+E15*I15+F15*I15+G15*I15+H15*I15 -> 26767.2 | V15: =N15*U15+O15*U15+P15*U15+Q15*U15+R15*U15+S15*U15+T15*U15 -> 0
J16: =B16*I16+C16*I16+D16*I16+E16*I16+F16*I16+G16*I16+H16*I16 -> 0 | L16: 45691 | M16: Захаров | O16: 10.3 | U16: 446.12 | V16: =N16*U16+O16*U16+P16*U16+Q16*U16+R16*U16+S16*U16+T16*U16 -> 4595.036
J17: =B17*I17+C17*I17+D17*I17+E17*I17+F17*I17+G17*I17+H17*I17 -> 0 | L17: 45694 | M17: Захаров | O17: 4 | U17: 446.12 | V17: =N17*U17+O17*U17+P17*U17+Q17*U17+R17*U17+S17*U17+T17*U17 -> 1784.48
J18: =B18*I18+C18*I18+D18*I18+E18*I18+F18*I18+G18*I18+H18*I18 -> 0 | M18: Захаров | R18: 1400 | U18: 2.86 | V18: =N18*U18+O18*U18+P18*U18+Q18*U18+R18*U18+S18*U18+T18*U18 -> 4004
J19: =B19*I19+C19*I19+D19*I19+E19*I19+F19*I19+G19*I19+H19*I19 -> 0 | L19: 45695 | M19: Захаров | O19: 4 | U19: 446.12 | V19: =N19*U19+O19*U19+P19*U19+Q19*U19+R19*U19+S19*U19+T19*U19 -> 1784.48
J20: =B20*I20+C20*I20+D20*I20+E20*I20+F20*I20+G20*I20+H20*I20 -> 0 | L20: 45701 | M20: Захаров | O20: 6.7 | U20: 446.12 | V20: =N20*U20+O20*U20+P20*U20+Q20*U20+R20*U20+S20*U20+T20*U20 -> 2989.004
J21: =B21*I21+C21*I21+D21*I21+E21*I21+F21*I21+G21*I21+H21*I21 -> 0 | L21: 45705 | M21: Захаров | O21: 6 | U21: 446.12 | V21: =N21*U21+O21*U21+P21*U21+Q21*U21+R21*U21+S21*U21+T21*U21 -> 2676.72
J22: =B22*I22+C22*I22+D22*I22+E22*I22+F22*I22+G22*I22+H22*I22 -> 0 | L22: 45706 | M22: Захаров | O22: 3 | U22: 446.12 | V22: =N22*U22+O22*U22+P22*U22+Q22*U22+R22*U22+S22*U22+T22*U22 -> 1338.36
J23: =B23*I23+C23*I23+D23*I23+E23*I23+F23*I23+G23*I23+H23*I23 -> 0 | L23: 45707 | M23: Захаров | O23: 5 | U23: 446.12 | V23: =N23*U23+O23*U23+P23*U23+Q23*U23+R23*U23+S23*U23+T23*U23 -> 2230.6
J24: =B24*I24+C24*I24+D24*I24+E24*I24+F24*I24+G24*I24+H24*I24 -> 0 | L24: 45709 | M24: Захаров | O24: 2 | U24: 446.12 | V24: =N24*U24+O24*U24+P24*U24+Q24*U24+R24*U24+S24*U24+T24*U24 -> 892.24
J25: =B25*I25+C25*I25+D25*I25+E25*I25+F25*I25+G25*I25+H25*I25 -> 0 | L25: 45713 | M25: Захаров | O25: 2 | U25: 446.12 | V25: =N25*U25+O25*U25+P25*U25+Q25*U25+R25*U25+S25*U25+T25*U25 -> 892.24
J26: =B26*I26+C26*I26+D26*I26+E26*I26+F26*I26+G26*I26+H26*I26 -> 0 | L26: 45714 | M26: Захаров | O26: 2 | U26: 446.12 | V26: =N26*U26+O26*U26+P26*U26+Q26*U26+R26*U26+S26*U26+T26*U26 -> 892.24
J27: =B27*I27+C27*I27+D27*I27+E27*I27+F27*I27+G27*I27+H27*I27 -> 0 | L27: март | M27: Захаров | V27: =N27*U27+O27*U27+P27*U27+Q27*U27+R27*U27+S27*U27+T27*U27 -> 0
J28: =B28*I28+C28*I28+D28*I28+E28*I28+F28*I28+G28*I28+H28*I28 -> 0 | L28: 45720 | M28: Захаров | O28: 3 | U28: 446.12 | V28: =N28*U28+O28*U28+P28*U28+Q28*U28+R28*U28+S28*U28+T28*U28 -> 1338.36
J29: =B29*I29+C29*I29+D29*I29+E29*I29+F29*I29+G29*I29+H29*I29 -> 0 | L29: 45722 | M29: Захаров | V29: =N29*U29+O29*U29+P29*U29+Q29*U29+R29*U29+S29*U29+T29*U29 -> 0
J30: =B30*I30+C30*I30+D30*I30+E30*I30+F30*I30+G30*I30+H30*I30 -> 0 | M30: Захаров | Q30: 20 | U30: 2.9 | V30: =N30*U30+O30*U30+P30*U30+Q30*U30+R30*U30+S30*U30+T30*U30 -> 58
J31: =B31*I31+C31*I31+D31*I31+E31*I31+F31*I31+G31*I31+H31*I31 -> 0 | L31: 45728 | M31: Захаров | O31: 3 | U31: 446.12 | V31: =N31*U31+O31*U31+P31*U31+Q31*U31+R31*U31+S31*U31+T31*U31 -> 1338.36
J32: =B32*I32+C32*I32+D32*I32+E32*I32+F32*I32+G32*I32+H32*I32 -> 0 | L32: 45730 | M32: Захаров | O32: 2 | U32: 446.12 | V32: =N32*U32+O32*U32+P32*U32+Q32*U32+R32*U32+S32*U32+T32*U32 -> 892.24
J33: =B33*I33+C33*I33+D33*I33+E33*I33+F33*I33+G33*I33+H33*I33 -> 0 | L33: 45734 | M33: Захаров | O33: 1 | U33: 446.12 | V33: =N33*U33+O33*U33+P33*U33+Q33*U33+R33*U33+S33*U33+T33*U33 -> 446.12
J34: =B34*I34+C34*I34+D34*I34+E34*I34+F34*I34+G34*I34+H34*I34 -> 0 | L34: 45740 | M34: Захаров | O34: 1 | U34: 446.12 | V34: =N34*U34+O34*U34+P34*U34+Q34*U34+R34*U34+S34*U34+T34*U34 -> 446.12
J35: =B35*I35+C35*I35+D35*I35+E35*I35+F35*I35+G35*I35+H35*I35 -> 0 | M35: Захаров | P35: 3.9 | U35: 441.69 | V35: =N35*U35+O35*U35+P35*U35+Q35*U35+R35*U35+S35*U35+T35*U35 -> 1722.591
J36: =B36*I36+C36*I36+D36*I36+E36*I36+F36*I36+G36*I36+H36*I36 -> 0 | L36: 45742 | M36: Захаров | O36: 5 | U36: 446.12 | V36: =N36*U36+O36*U36+P36*U36+Q36*U36+R36*U36+S36*U36+T36*U36 -> 2230.6
J37: =B37*I37+C37*I37+D37*I37+E37*I37+F37*I37+G37*I37+H37*I37 -> 0 | L37: 45744 | M37: Захаров | T37: 50 | U37: 18 | V37: =N37*U37+O37*U37+P37*U37+Q37*U37+R37*U37+S37*U37+T37*U37 -> 900
A38: май | L38: май
A39: 14 мая | D39: 60 | I39: 432.82 | J39: =B39*I39+C39*I39+D39*I39+E39*I39+F39*I39+G39*I39+H39*I39 -> 25969.2 | L39: 06 мая | M39: Захаров | P39: 5 | U39: 432.82 | V39: =N39*U39+O39*U39+P39*U39+Q39*U39+R39*U39+S39*U39+T39*U39 -> 2164.1
L40: 15 мая | P40: 6 | U40: 432.82 | V40: =N40*U40+O40*U40+P40*U40+Q40*U40+R40*U40+S40*U40+T40*U40 -> 2596.92
...

Sheet Полимаркет
A1: дата поставки | B1: Этикетка 57*40 мм Лицо | C1: Этикетка 57*40 мм Оборот | E1: цена | F1: на сумму | H1: дата выдачи на пр-во | I1: в чей подотчет | J1: Этикетка 57*40 мм Лицо | K1: Этикетка 57*40 мм Оборот | M1: цена | N1: на сумму | Q1: Этикетка 57*40 мм Лицо | R1: Этикетка 57*40 мм Оборот
A2: 2025 год | H2: 2025 год | Q2: =0+B52-J52 -> 0 | R2: =0+C52-K52 -> 0
A3: 45684 | B3: 50000 | C3: 50000 | E3: 0.85 | F3: =B3*E3+C3*E3+D3*E3 -> 85000 | Q3: 0.54 | R3: 0.54
F4: =B4*E4+C4*E4+D4*E4 -> 0 | H4: 45687 | I4: Захаров | J4: 50000 | K4: 50000 | M4: 0.85 | N4: =J4*M4+K4*M4+L4*M4 -> 85000 | Q4: =Q2*Q3 -> 0 | R4: =R2*R3 -> 0
A5: 45698 | B5: 120000 | C5: 120000 | E5: 0.54 | F5: =B5*E5+C5*E5+D5*E5 -> 129600 | H5: 45699 | I5: Захаров | J5: 120000 | K5: 120000 | M5: 0.54 | N5: =J5*M5+K5*M5+L5*M5 -> 129600
A6: 45716 | B6: 120000 | C6: 120000 | E6: 0.54 | F6: =B6*E6+C6*E6+D6*E6 -> 129600 | N6: =J6*M6+K6*M6+L6*M6 -> 0
F7: =B7*E7+C7*E7+D7*E7 -> 0 | H7: 45722 | I7: Захаров | J7: 120000 | K7: 120000 | M7: 0.54 | N7: =J7*M7+K7*M7+L7*M7 -> 129600
F8: =B8*E8+C8*E8+D8*E8 -> 0 | N8: =J8*M8+K8*M8+L8*M8 -> 0
F9: =B9*E9+C9*E9+D9*E9 -> 0 | N9: =J9*M9+K9*M9+L9*M9 -> 0
F10: =B10*E10+C10*E10+D10*E10 -> 0 | N10: =J10*M10+K10*M10+L10*M10 -> 0
F11: =B11*E11+C11*E11+D11*E11 -> 0 | N11: =J11*M11+K11*M11+L11*M11 -> 0
F12: =B12*E12+C12*E12+D12*E12 -> 0 | N12: =J12*M12+K12*M12+L12*M12 -> 0
F13: =B13*E13+C13*E13+D13*E13 -> 0 | N13: =J13*M13+K13*M13+L13*M13 -> 0
F14: =B14*E14+C14*E14+D14*E14 -> 0 | N14: =J14*M14+K14*M14+L14*M14 -> 0
F15: =B15*E15+C15*E15+D15*E15 -> 0 | N15: =J15*M15+K15*M15+L15*M15 -> 0
F16: =B16*E16+C16*E16+D16*E16 -> 0 | N16: =J16*M16+K16*M16+L16*M16 -> 0
F17: =B17*E17+C17*E17+D17*E17 -> 0 | N17: =J17*M17+K17*M17+L17*M17 -> 0
N18: =J18*M18+K18*M18+L18*M18 -> 0
N19: =J19*M19+K19*M19+L19*M19 -> 0
N20: =J20*M20+K20*M20+L20*M20 -> 0
N21: =J21*M21+K21*M21+L21*M21 -> 0
N22: =J22*M22+K22*M22+L22*M22 -> 0
N23: =J23*M23+K23*M23+L23*M23 -> 0
N24: =J24*M24+K24*M24+L24*M24 -> 0
N25: =J25*M25+K25*M25+L25*M25 -> 0
N26: =J26*M26+K26*M26+L26*M26 -> 0
N27: =J27*M27+K27*M27+L27*M27 -> 0
N28: =J28*M28+K28*M28+L28*M28 -> 0
N29: =J29*M29+K29*M29+L29*M29 -> 0
... N51: =J51*M51+K51*M51+L51*M51 -> 0
B52: =SUM(B3:B51) -> 290000 | C52: =SUM(C3:C51) -> 290000 | D52: =SUM(D3:D51) -> 0 | J52: =SUM(J3:J51) -> 290000 | K52: =SUM(K3:K51) -> 290000 | L52: =SUM(L3:L51) -> 0

Sheet Ф-Граф
A1: дата поставки | B1: пленки сметана-лук | C1: пленки васаби | D1: пленки барбекю | E1: пленки сыр | F1: Пленка арахис КВАДРО МИКС "Тарелка" БОПП 20 мкм проз.,240*310 мм | G1: пленки фисташки | H1: ПЛЕНКА БОПП 40*310 | I1: ПЛЕНКА БОПП 40*420 | J1: Пленка КВАДРО МИКС "Тарелка" БОПП 20 мкм проз.,240*310 мм | K1: цена, кг | L1: на сумму | N1: дата выдачи на пр-во | O1: пленки сметана-лук | P1: пленки васаби | Q1: пленки барбекю | R1: пленки сыр-лук | S1: Пленка арахис КВАДРО МИКС "Тарелка" БОПП 20 мкм проз.,240*310 мм | T1: пленки фисташки | U1: ПЛЕНКА БОПП 40*310 | V1: ПЛЕНКА БОПП 40*420 | W1: Пленка КВАДРО МИКС "Тарелка" БОПП 20 мкм проз.,240*310 мм | X1: цена | Y1: на сумму | AA1: пленки сметана-лук | AB1: пленки васаби | AC1: пленки барбекю | AD1: пленки сыр | AE1: Пленка арахис КВАДРО МИКС "Тарелка" БОПП 20 мкм проз.,240*310 мм | AF1: пленки фисташки | AG1: ПЛЕНКА БОПП 40*310 | AH1: ПЛЕНКА БОПП 40*420 | AI1: Пленка КВАДРО МИКС "Тарелка" БОПП 20 мкм проз.,240*310 мм
A2: 2024 год | N2: 2024 год | AA2: =0+B61-O61 -> 210.2 | AB2: =0+C61-P61 -> 204.85 | AC2: =0+D61-Q61 -> 222.25 | AD2: =0+E61-R61 -> 222.9 | AE2: =0+F61-S61 -> -181.86 | AF2: =0+G61-T61 -> 266 | AG2: =0+H61-U61 -> 0 | AH2: =0+I61-V61 -> 25.45 | AI2: =0+J61-W61 -> 434.12
A3: 45551 | B3: 224.7 | C3: 228.35 | D3: 224.75 | E3: 225.4 | K3: 605 | L3: =B3*K3+C3*K3+D3*K3+E3*K3+F3*K3+G3*K3+H3*K3+I3*K3+J3*K3 -> 546436 | N3: настройка станка | P3: 1.5 | Q3: 1.5 | R3: 1.5 | X3: 605 | Y3: =O3*X3+P3*X3+Q3*X3+R3*X3+S3*X3+T3*T3+U3*X3+V3*X3+W3*X3 -> 2722.5 | AA3: 605 | AB3: 605 | AC3: 605 | AD3: 605 | AE3: 682 | AF3: 692 | AG3: 414 | AH3: 414 | AI3: 625
A4: 45645 | F4: 229.2 | K4: 682 | L4: =B4*K4+C4*K4+D4*K4+E4*K4+F4*K4+G4*K4+H4*K4+I4*K4+J4*K4 -> 156314.4 | N4: на тестир Воронеж | P4: 15 | X4: 605 | Y4: =O4*X4+P4*X4+Q4*X4+R4*X4+S4*X4+T4*T4+U4*X4+V4*X4+W4*X4 -> 9075 | AA4: =AA2*AA3 -> 127171 | AB4: =AB2*AB3 -> 123934.25 | AC4: =AC2*AC3 -> 134461.25 | AD4: =AD2*AD3 -> 134854.5 | AE4: =AE2*AE3 -> -124028.52 | AF4: =AF2*AF3 -> 184072 | AG4: =AG2*AG3 -> 0 | AH4: =AH2*AH3 -> 10536.3 | AI4: =AI2*AI3 -> 271325
G5: 266 | K5: 692 | L5: =B5*K5+C5*K5+D5*K5+E5*K5+F5*K5+G5*K5+H5*K5+I5*K5+J5*K5 -> 184072 | N5: 45651 | S5: 0.2 | X5: 682 | Y5: =O5*X5+P5*X5+Q5*X5+R5*X5+S5*X5+T5*T5+U5*X5+V5*X5+W5*X5 -> 136.4
L6: =B6*K6+C6*K6+D6*K6+E6*K6+F6*K6+G6*K6+H6*K6+I6*K6+J6*K6 -> 0 | N6: 45652 | S6: 0.2 | X6: 682 | Y6: =O6*X6+P6*X6+Q6*X6+R6*X6+S6*X6+T6*T6+U6*X6+V6*X6+W6*X6 -> 136.4
L7: =B7*K7+C7*K7+D7*K7+E7*K7+F7*K7+G7*K7+H7*K7+I7*K7+J7*K7 -> 0 | N7: 45653 | S7: 0.2 | X7: 682 | Y7: =O7*X7+P7*X7+Q7*X7+R7*X7+S7*X7+T7*T7+U7*X7+V7*X7+W7*X7 -> 136.4
L8: =B8*K8+C8*K8+D8*K8+E8*K8+F8*K8+G8*K8+H8*K8+I8*K8+J8*K8 -> 0 | Y8: =O8*X8+P8*X8+Q8*X8+R8*X8+S8*X8+T8*T8+U8*X8+V8*X8+W8*X8 -> 0
L9: =B9*K9+C9*K9+D9*K9+E9*K9+F9*K9+G9*K9+H9*K9+I9*K9+J9*K9 -> 0 | N9: 45666 | P9: 3 | X9: 605 | Y9: =O9*X9+P9*X9+Q9*X9+R9*X9+S9*X9+T9*T9+U9*X9+V9*X9+W9*X9 -> 1815
L10: =B10*K10+C10*K10+D10*K10+E10*K10+F10*K10+G10*K10+H10*K10+I10*K10+J10*K10 -> 0 | S10: 0.2 | X10: 682 | Y10: =O10*X10+P10*X10+Q10*X10+R10*X10+S10*X10+T10*T10+U10*X10+V10*X10+W10*X10 -> 136.4
L11: =B11*K11+C11*K11+D11*K11+E11*K11+F11*K11+G11*K11+H11*K11+I11*K11+J11*K11 -> 0 | N11: 45667 | P11: 3 | X11: 605 | Y11: =O11*X11+P11*X11+Q11*X11+R11*X11+S11*X11+T11*T11+U11*X11+V11*X11+W11*X11 -> 1815
L12: =B12*K12+C12*K12+D12*K12+E12*K12+F12*K12+G12*K12+H12*K12+I12*K12+J12*K12 -> 0 | N12: 45681 | O12: 1 | P12: 1 | Q12: 1 | R12: 1 | X12: 605 | Y12: =O12*X12+P12*X12+Q12*X12+R12*X12+S12*X12+T12*T12+U12*X12+V12*X12+W12*X12 -> 2420
L13: =B13*K13+C13*K13+D13*K13+E13*K13+F13*K13+G13*K13+H13*K13+I13*K13+J13*K13 -> 0 | N13: 45684 | S13: 0.2 | X13: 682 | Y13: =O13*X13+P13*X13+Q13*X13+R13*X13+S13*X13+T13*T13+U13*X13+V13*X13+W13*X13 -> 136.4
A14: 45687 | H14: 314.8 | K14: 414 | L14: =B14*K14+C14*K14+D14*K14+E14*K14+F14*K14+G14*K14+H14*K14+I14*K14+J14*K14 -> 130327.2 | N14: 45687 | U14: 14.1 | X14: 414 | Y14: =O14*X14+P14*X14+Q14*X14+R14*X14+S14*X14+T14*T14+U14*X14+V14*X14+W14*X14 -> 5837.4
I15: 170.3 | K15: 414 | L15: =B15*K15+C15*K15+D15*K15+E15*K15+F15*K15+G15*K15+H15*K15+I15*K15+J15*K15 -> 70504.2 | N15: 45688 | U15: 14.1 | X15: 414 | Y15: =O15*X15+P15*X15+Q15*X15+R15*X15+S15*X15+T15*T15+U15*X15+V15*X15+W15*X15 -> 5837.4
L16: =B16*K16+C16*K16+D16*K16+E16*K16+F16*K16+G16*K16+H16*K16+I16*K16+J16*K16 -> 0 | N16: 45691 | U16: 14.1 | X16: 414 | Y16: =O16*X16+P16*X16+Q16*X16+R16*X16+S16*X16+T16*T16+U16*X16+V16*X16+W16*X16 -> 5837.4
L17: =B17*K17+C17*K17+D17*K17+E17*K17+F17*K17+G17*K17+H17*K17+I17*K17+J17*K17 -> 0 | U17: 31 | V17: 22.45 | X17: 414 | Y17: =O17*X17+P17*X17+Q17*X17+R17*X17+S17*X17+T17*T17+U17*X17+V17*X17+W17*X17 -> 22128.3
L18: =B18*K18+C18*K18+D18*K18+E18*K18+F18*K18+G18*K18+H18*K18+I18*K18+J18*K18 -> 0 | N18: 45695 | U18: 15 | X18: 414 | Y18: =O18*X18+P18*X18+Q18*X18+R18*X18+S18*X18+T18*T18+U18*X18+V18*X18+W18*X18 -> 6210
L19: =B19*K19+C19*K19+D19*K19+E19*K19+F19*K19+G19*K19+H19*K19+I19*K19+J19*K19 -> 0 | N19: 45698 | U19: 22.4 | V19: 15 | X19: 414 | Y19: =O19*X19+P19*X19+Q19*X19+R19*X19+S19*X19+T19*T19+U19*X19+V19*X19+W19*X19 -> 15483.6
L20: =B20*K20+C20*K20+D20*K20+E20*K20+F20*K20+G20*K20+H20*K20+I20*K20+J20*K20 -> 0 | N20: 45700 | U20: 15.32 | X20: 414 | Y20: =O20*X20+P20*X20+Q20*X20+R20*X20+S20*X20+T20*T20+U20*X20+V20*X20+W20*X20 -> 6342.48
L21: =B21*K21+C21*K21+D21*K21+E21*K21+F21*K21+G21*K21+H21*K21+I21*K21+J21*K21 -> 0 | N21: 45701 | U21: 15.7 | X21: 414 | Y21: =O21*X21+P21*X21+Q21*X21+R21*X21+S21*X21+T21*T21+U21*X21+V21*X21+W21*X21 -> 6499.8
L22: =B22*K22+C22*K22+D22*K22+E22*K22+F22*K22+G22*K22+H22*K22+I22*K22+J22*K22 -> 0 | N22: 45702 | U22: 23.48 | X22: 414 | Y22: =O22*X22+P22*X22+Q22*X22+R22*X22+S22*X22+T22*T22+U22*X22+V22*X22+W22*X22 -> 9720.72
L23: =B23*K23+C23*K23+D23*K23+E23*K23+F23*K23+G23*K23+H23*K23+I23*K23+J23*K23 -> 0 | N23: 45705 | U23: 15.22 | X23: 414 | Y23: =O23*X23+P23*X23+Q23*X23+R23*X23+S23*X23+T23*T23+U23*X23+V23*X23+W23*X23 -> 6301.08
L24: =B24*K24+C24*K24+D24*K24+E24*K24+F24*K24+G24*K24+H24*K24+I24*K24+J24*K24 -> 0 | N24: 45707 | U24: 14.1 | V24: 22.45 | X24: 414 | Y24: =O24*X24+P24*X24+Q24*X24+R24*X24+S24*X24+T24*T24+U24*X24+V24*X24+W24*X24 -> 15131.7
L25: =B25*K25+C25*K25+D25*K25+E25*K25+F25*K25+G25*K25+H25*K25+I25*K25+J25*K25 -> 0 | N25: 45708 | U25: 15.98 | X25: 414 | Y25: =O25*X25+P25*X25+Q25*X25+R25*X25+S25*X25+T25*T25+U25*X25+V25*X25+W25*X25 -> 6615.72
L26: =B26*K26+C26*K26+D26*K26+E26*K26+F26*K26+G26*K26+H26*K26+I26*K26+J26*K26 -> 0 | N26: 45712 | U26: 15.94 | X26: 414 | Y26: =O26*X26+P26*X26+Q26*X26+R26*X26+S26*X26+T26*T26+U26*X26+V26*X26+W26*X26 -> 6599.16
L27: =B27*K27+C27*K27+D27*K27+E27*K27+F27*K27+G27*K27+H27*K27+I27*K27+J27*K27 -> 0 | N27: 45713 | U27: 15.16 | X27: 414 | Y27: =O27*X27+P27*X27+Q27*X27+R27*X27+S27*X27+T27*T27+U27*X27+V27*X27+W27*X27 -> 6276.24
L28: =B28*K28+C28*K28+D28*K28+E28*K28+F28*K28+G28*K28+H28*K28+I28*K28+J28*K28 -> 0 | N28: 45714 | U28: 15.3 | X28: 414 | Y28: =O28*X28+P28*X28+Q28*X28+R28*X28+S28*X28+T28*T28+U28*X28+V28*X28+W28*X28 -> 6334.2
L29: =B29*K29+C29*K29+D29*K29+E29*K29+F29*K29+G29*K29+H29*K29+I29*K29+J29*K29 -> 0 | O29: 13.5 | X29: 605 | Y29: =O29*X29+P29*X29+Q29*X29+R29*X29+S29*X29+T29*T29+U29*X29+V29*X29+W29*X29 -> 8167.5
L30: =B30*K30+C30*K30+D30*K30+E30*K30+F30*K30+G30*K30+H30*K30+I30*K30+J30*K30 -> 0 | N30: 45715 | S30: 30.82 | X30: 682 | Y30: =O30*X30+P30*X30+Q30*X30+R30*X30+S30*X30+T30*T30+U30*X30+V30*X30+W30*X30 -> 21019.24
L31: =B31*K31+C31*K31+D31*K31+E31*K31+F31*K31+G31*K31+H31*K31+I31*K31+J31*K31 -> 0 | U31: 15.22 | X31: 414 | Y31: =O31*X31+P31*X31+Q31*X31+R31*X31+S31*X31+T31*T31+U31*X31+V31*X31+W31*X31 -> 6301.08
L32: =B32*K32+C32*K32+D32*K32+E32*K32+F32*K32+G32*K32+H32*K32+I32*K32+J32*K32 -> 0 | N32: 45716 | V32: 41.9 | X32: 414 | Y32: =O32*X32+P32*X32+Q32*X32+R32*X32+S32*X32+T32*T32+U32*X32+V32*X32+W32*X32 -> 17346.6
L33: =B33*K33+C33*K33+D33*K33+E33*K33+F33*K33+G33*K33+H33*K33+I33*K33+J33*K33 -> 0 | N33: март | Y33: =O33*X33+P33*X33+Q33*X33+R33*X33+S33*X33+T33*T33+U33*X33+V33*X33+W33*X33 -> 0
L34: =B34*K34+C34*K34+D34*K34+E34*K34+F34*K34+G34*K34+H34*K34+I34*K34+J34*K34 -> 0 | N34: 45720 | U34: 30.52 | X34: 414 | Y34: =O34*X34+P34*X34+Q34*X34+R34*X34+S34*X34+T34*T34+U34*X34+V34*X34+W34*X34 -> 12635.28
L35: =B35*K35+C35*K35+D35*K35+E35*K35+F35*K35+G35*K35+H35*K35+I35*K35+J35*K35 -> 0 | N35: 45722 | U35: 12.16 | X35: 414 | Y35: =O35*X35+P35*X35+Q35*X35+R35*X35+S35*X35+T35*T35+U35*X35+V35*X35+W35*X35 -> 5034.24
L36: =B36*K36+C36*K36+D36*K36+E36*K36+F36*K36+G36*K36+H36*K36+I36*K36+J36*K36 -> 0 | N36: 45726 | S36: 15.4 | X36: 682 | Y36: =O36*X36+P36*X36+Q36*X36+R36*X36+S36*X36+T36*T36+U36*X36+V36*X36+W36*X36 -> 10502.8
L37: =B37*K37+C37*K37+D37*K37+E37*K37+F37*K37+G37*K37+H37*K37+I37*K37+J37*K37 -> 0 | N37: 45727 | S37: 15.6 | X37: 682 | Y37: =O37*X37+P37*X37+Q37*X37+R37*X37+S37*X37+T37*T37+U37*X37+V37*X37+W37*X37 -> 10639.2
